<?xml version="1.0"?>
<robot name="robotiq_140_gripper" xmlns:xacro="http://ros.org/wiki/xacro">

    <xacro:macro name="contact_parameters" params="name">
        <gazebo reference="${name}">
            <dampingFactor>0.001</dampingFactor>
            <mu1 value="1.0" />
            <mu2 value="1.0" />
            <kp  value="1e5" />
            <kd  value="1e2" />
            <maxVel  value="1.0" />
            <minDepth  value="0.0" />
        </gazebo>
    </xacro:macro>

    <xacro:macro name="robotiq_box_inertia_def" params="x y z mass">
        <inertia iyy="${mass*(z*z+x*x)/12.0}" ixx="${mass*(y*y+z*z)/12.0}" izz="${mass*(x*x+y*y)/12.0}" ixy="0.0" iyz="0.0" ixz="0.0"/>
    </xacro:macro>

    <xacro:macro name="robotiq_140_gripper_joint_gazebo" params="name">

        <transmission name="${name}_trans">
            <type>transmission_interface/SimpleTransmission</type>
            <joint name="${name}">
                <hardwareInterface>hardware_interface/PositionJointInterface</hardwareInterface>
            </joint>
            <actuator name="${name}_motor">
                <mechanicalReduction>1</mechanicalReduction>
            </actuator>
        </transmission>

        <gazebo reference="${name}">
            <implicitSpringDamper>1</implicitSpringDamper>
        </gazebo>

    </xacro:macro>

    <xacro:macro name="outer_knuckle" params="prefix fingerprefix stroke">
    <link name="${prefix}${fingerprefix}_outer_knuckle">
      <inertial>
        <origin xyz="-0.000200000000003065 0.0199435877845359 0.0292245259211331" rpy="0 0 0" />
        <mass value="0.00853198276973456" />
        <inertia
            ixx="2.89328108496468E-06"
            ixy="-1.57935047237397E-19"
            ixz="-1.93980378593255E-19"
            iyy="1.86719750325683E-06"
            iyz="-1.21858577871576E-06"
            izz="1.21905238907251E-06" />
      </inertial>
      <visual>
        <origin xyz="0 0 0" rpy="0 0 0" />
        <geometry>
          <mesh filename="package://robotiq_140_description/meshes/robotiq_arg2f_${stroke}_outer_knuckle.stl" />
        </geometry>
        <material name="GripperBlue">
          <color rgba="0.792156862745098 0.819607843137255 0.933333333333333 1" />
        </material>
      </visual>
    </link>
    <xacro:contact_parameters name="${prefix}${fingerprefix}_outer_knuckle"/>
  </xacro:macro>

  <xacro:macro name="outer_finger" params="prefix fingerprefix stroke">
    <link name="${prefix}${fingerprefix}_outer_finger">
      <inertial>
        <origin xyz="0.00030115855001899 0.0373907951953854 -0.0208027427000385" rpy="0 0 0" />
        <mass value="0.022614240507152" />
        <inertia
            ixx="1.52518312458174E-05"
            ixy="9.76583423954399E-10"
            ixz="-5.43838577022588E-10"
            iyy="6.17694243867776E-06"
            iyz="6.78636130740228E-06"
            izz="1.16494917907219E-05" />
      </inertial>
      <visual>
        <origin xyz="0 0 0" rpy="0 0 0" />
        <geometry>
          <mesh filename="package://robotiq_140_description/meshes/robotiq_arg2f_${stroke}_outer_finger.stl" />
        </geometry>
        <material name="GripperBlack">
          <color rgba="0.1 0.1 0.1 1" />
        </material>
      </visual>
      <collision>
        <origin rpy="-0.3 0 0" xyz="0 0.04 -0.02"/>
        <geometry>
          <box size="0.028 0.1 0.03"/>
        </geometry>
      </collision>
    </link>
    <xacro:contact_parameters name="${prefix}${fingerprefix}_outer_finger"/>
  </xacro:macro>

  <xacro:macro name="inner_knuckle" params="prefix fingerprefix stroke">
    <link name="${prefix}${fingerprefix}_inner_knuckle">
      <inertial>
        <origin xyz="0.000123011831763771 0.0507850843201817 0.00103968640075166" rpy="0 0 0" />
        <mass value="0.0271177346495152" />
        <inertia
            ixx="2.61910379223783E-05"
            ixy="-2.43616858946494E-07"
            ixz="-6.37789906117123E-09"
            iyy="2.8270243746167E-06"
            iyz="-5.37200748039765E-07"
            izz="2.83695868220296E-05" />
      </inertial>
      <visual>
        <origin xyz="0 0 0" rpy="0 0 0" />
        <geometry>
          <mesh filename="package://robotiq_140_description/meshes/robotiq_arg2f_${stroke}_inner_knuckle.stl" />
        </geometry>
        <material name="GripperBlack">
        </material>
      </visual>
      <collision>
        <origin rpy="-0.02 0 0" xyz="0 0.05 -0.002"/>
        <geometry>
          <box size="0.038 0.12 0.015"/>
        </geometry>
      </collision>
    </link>
    <xacro:contact_parameters name="${prefix}${fingerprefix}_inner_knuckle"/>
  </xacro:macro>

  <xacro:macro name="inner_finger" params="prefix fingerprefix stroke">
    <link name="${prefix}${fingerprefix}_inner_finger">
      <inertial>
        <origin xyz="0.000299999999999317 0.0160078233491243 -0.0136945669206257" rpy="0 0 0" />
        <mass value="0.0104003125914103" />
        <inertia
            ixx="2.71909453810972E-06"
            ixy="1.35402465472579E-21"
            ixz="-7.1817349065269E-22"
            iyy="7.69100314106116E-07"
            iyz="6.74715432769696E-07"
            izz="2.30315190420171E-06" />
      </inertial>
      <visual>
        <origin xyz="0 0 0" rpy="0 0 0" />
        <geometry>
          <mesh filename="package://robotiq_140_description/meshes/robotiq_arg2f_${stroke}_inner_finger.stl" />
        </geometry>
        <material name="GripperBlack">
        </material>
      </visual>
      <visual>
        <origin rpy="0 0 0" xyz="0 0.048 -0.025"/>
        <geometry>
          <box size="0.024 0.06 0.01"/>
        </geometry>
        <material name="GripperBlack">
        </material>
      </visual>
      <collision>
        <origin rpy="0 0 0" xyz="0 0.039 -0.02"/>
        <geometry>
          <box size="0.024 0.078 0.02"/>
        </geometry>
      </collision>
    </link>
    <xacro:contact_parameters name="${prefix}${fingerprefix}_inner_finger"/>
  </xacro:macro>

  <xacro:macro name="outer_finger_joint" params="prefix fingerprefix">
    <joint name="${prefix}${fingerprefix}_outer_finger_joint" type="fixed">
      <origin xyz="0 0.01821998610742 0.0260018192872234" rpy="0 0 0" />
      <parent link="${prefix}${fingerprefix}_outer_knuckle" />
      <child link="${prefix}${fingerprefix}_outer_finger" />
      <axis xyz="1 0 0" />
    </joint>
  </xacro:macro>

  <xacro:macro name="inner_knuckle_joint" params="prefix fingerprefix reflect">
    <joint name="${prefix}${fingerprefix}_inner_knuckle_joint" type="revolute">
      <origin xyz="0 ${reflect * -0.0127} 0.06142" rpy="${pi / 2 + .725} 0 ${(reflect - 1) * pi / 2}" />
      <parent link="${prefix}robotiq_arg2f_link" />
      <child link="${prefix}${fingerprefix}_inner_knuckle" />
      <axis xyz="1 0 0" />
      <limit lower="-1" upper="1" velocity="2.0" effort="1000" />
      <dynamics damping="0.5" friction="0.5"/>
    </joint>
    <xacro:robotiq_140_gripper_joint_gazebo name="${prefix}${fingerprefix}_inner_knuckle_joint"/>
  </xacro:macro>

  <xacro:macro name="inner_finger_joint" params="prefix fingerprefix">
    <joint name="${prefix}${fingerprefix}_inner_finger_joint" type="revolute">
      <origin xyz="0 0.0817554015893473 -0.0282203446692936" rpy="-.725 0 0" />
      <parent link="${prefix}${fingerprefix}_outer_finger" />
      <child link="${prefix}${fingerprefix}_inner_finger" />
      <axis xyz="1 0 0" />
      <limit lower="0" upper="0.8757" velocity="2.0" effort="1000" />
      <dynamics damping="0.5" friction="0.5"/>
    </joint>
    <xacro:robotiq_140_gripper_joint_gazebo name="${prefix}${fingerprefix}_inner_finger_joint"/>
  </xacro:macro>

  <xacro:macro name="robotiq_arg2f_link" params="prefix">
    <link name="${prefix}robotiq_arg2f_link">
      <inertial>
        <origin xyz="8.625E-08 -4.6583E-06 0.03145" rpy="0 0 0" />
        <mass value="0.22652" />
        <inertia ixx="0.00020005" ixy="-4.2442E-10" ixz="-2.9069E-10" iyy="0.00017832" iyz="-3.4402E-08" izz="0.00013478" />
      </inertial>
      <visual>
        <origin xyz="0 0 0" rpy="0 0 0" />
        <geometry>
          <mesh filename="package://robotiq_140_description/meshes/robotiq_arg2f_base_link_fine.stl" />
        </geometry>
        <material name="GripperGrey">
          <color rgba="0.5 0.5 0.5 1" />
        </material>
      </visual>
        <collision>
          <origin rpy="0 0 0" xyz="0 0 0.03"/>
          <geometry>
            <cylinder length="0.06" radius="0.04"/>
          </geometry>
        </collision>
        <collision>
          <origin rpy="0 0 0" xyz="0 0 0.075"/>
          <geometry>
            <box size="0.025 0.08 0.03"/>
          </geometry>
        </collision>
    </link>
    <xacro:contact_parameters name="${prefix}robotiq_arg2f_link"/>
  </xacro:macro>

  <xacro:macro name="finger_joints" params="prefix fingerprefix reflect">
    <xacro:outer_finger_joint prefix="${prefix}" fingerprefix="${fingerprefix}"/>
    <xacro:inner_knuckle_joint prefix="${prefix}" fingerprefix="${fingerprefix}" reflect="${reflect}"/>
    <xacro:inner_finger_joint prefix="${prefix}" fingerprefix="${fingerprefix}"/>
  </xacro:macro>

  <xacro:macro name="finger_links" params="prefix fingerprefix stroke">
    <xacro:outer_knuckle prefix="${prefix}" fingerprefix="${fingerprefix}" stroke="${stroke}"/>
    <xacro:outer_finger prefix="${prefix}" fingerprefix="${fingerprefix}" stroke="${stroke}"/>
    <xacro:inner_finger prefix="${prefix}" fingerprefix="${fingerprefix}" stroke="${stroke}"/>
    <xacro:inner_knuckle prefix="${prefix}" fingerprefix="${fingerprefix}" stroke="${stroke}"/>
  </xacro:macro>

  <xacro:macro name="finger_joint" params="prefix">
    <joint name="${prefix}finger_joint" type="revolute">
      <origin xyz="0 -0.030601 0.054905" rpy="${pi / 2 + .725} 0 0" />
      <parent link="${prefix}robotiq_arg2f_link" />
      <child link="${prefix}left_outer_knuckle" />
      <axis xyz="-1 0 0" />
      <limit lower="0" upper="0.775" velocity="2.0" effort="1000" />
      <dynamics damping="0.5" friction="0.5"/>
    </joint>
    <xacro:robotiq_140_gripper_joint_gazebo name="${prefix}finger_joint"/>
    <xacro:finger_joints prefix="${prefix}" fingerprefix="left" reflect="1.0"/>
  </xacro:macro>

  <xacro:macro name="right_outer_knuckle_joint" params="prefix">
    <joint name="${prefix}right_outer_knuckle_joint" type="revolute">
      <origin xyz="0 0.030601 0.054905" rpy="${pi / 2 + .725} 0 ${pi}" />
      <parent link="${prefix}robotiq_arg2f_link" />
      <child link="${prefix}right_outer_knuckle" />
      <axis xyz="-1 0 0" />
      <limit lower="0" upper="0.725" velocity="2.0" effort="1000" />
      <dynamics damping="0.5" friction="0.5"/>
    </joint>
    <xacro:robotiq_140_gripper_joint_gazebo name="${prefix}right_outer_knuckle_joint"/>
    <xacro:finger_joints prefix="${prefix}" fingerprefix="right" reflect="-1.0"/>
  </xacro:macro>

  <xacro:macro name="robotiq_arg2f_140" params="prefix">
    <xacro:robotiq_arg2f_link prefix="${prefix}"/>
    <xacro:finger_links prefix="${prefix}" fingerprefix="left" stroke="140"/>
    <xacro:finger_links prefix="${prefix}" fingerprefix="right" stroke="140"/>
    <xacro:finger_joint prefix="${prefix}"/>
    <xacro:right_outer_knuckle_joint prefix="${prefix}"/>
  </xacro:macro>

  <!-- Define the gripper -->
  <xacro:macro name="robotiq_140_gripper" params="prefix parent *origin">

    <joint name="${prefix}gripper_base_joint" type="fixed">
      <parent link="${parent}"/>
      <child link="${prefix}robotiq_arg2f_link"/>
      <xacro:insert_block name="origin"/>
    </joint>

    <xacro:robotiq_arg2f_140 prefix="${prefix}"/>

    <joint name="${prefix}gripper_open_joint" type="revolute">
      <parent link="${prefix}robotiq_arg2f_link"/>
      <child link="${prefix}gripper_dummy_link"/>
      <axis xyz="1 0 0"/>
      <origin rpy="0.0 0.0 0.0" xyz="0 0 0"/>
      <limit lower="0" upper="0.140" velocity="1.0" effort="100"/>
      <dynamics damping="0.5" friction="0.5"/>
    </joint>

    <xacro:robotiq_140_gripper_joint_gazebo name="${prefix}gripper_open_joint"/>

    <link name="${prefix}gripper_dummy_link">
      <inertial>
          <mass value="0.0001" />
          <origin rpy="0 0 0" xyz="0 0 0" />
          <xacro:robotiq_box_inertia_def x="0.05" y="0.015" z="0.024" mass="0.0001"/>
      </inertial>
    </link>

  </xacro:macro>

</robot>
