<?xml version="1.0" ?>
<!-- =================================================================================== -->
<!-- |    This document was autogenerated by xacro from /home/keyhan/uoe_slmc_software_platform/src/packages/nextage_pushing/urdf/pushing_box.urdf.xacro | -->
<!-- |    EDITING THIS FILE BY HAND IS NOT RECOMMENDED                                 | -->
<!-- =================================================================================== -->
<!--|
    Copyright (C) 2022 Satistical Learning and Motor Control Group, University of Edinburgh, UK
    Author:  Joao Moura (maintainer)
    email:    Joao.Moura@ed.ac.uk
    website:  web.inf.ed.ac.uk/slmc

    This file is part of iiwa_pushing.

    iiwa_pushing is free software: you can redistribute it and/or modify
    it under the terms of the GNU General Public License as published by
    the Free Software Foundation, either version 3 of the License, or
    (at your option) any later version.

    iiwa_pushing is distributed in the hope that it will be useful,
    but WITHOUT ANY WARRANTY; without even the implied warranty of
    MERCHANTABILITY or FITNESS FOR A PARTICULAR PURPOSE.  See the
    GNU General Public License for more details.

|-->
<robot name="pushing_box">
  <!-- Fix to world just for testing -->
  <link name="world"/>
  <link name="base_link_pushing_box">
    <visual>
      <geometry>
        <box size="0.101 0.119 0.0705"/>
      </geometry>
      <material name="green">
        <color rgba="1.0 1.0 0.0 1"/>
      </material>
    </visual>
  </link>
  <joint name="base_link_joint" type="floating">
    <parent link="world"/>
    <child link="base_link_pushing_box"/>
    <origin rpy="0 0 0" xyz="0 0 0"/>
  </joint>
</robot>
