<?xml version="1.0" ?>
<!-- =================================================================================== -->
<!-- |    This document was autogenerated by xacro from /home/dwq/chonk/src/donkey_description/urdf/donkey.urdf.xacro | -->
<!-- |    EDITING THIS FILE BY HAND IS NOT RECOMMENDED                                 | -->
<!-- =================================================================================== -->
<robot name="DonkeyRobot">
  <!-- Base link-->
  <link name="base_link"/>
  <link name="donkey_base">
    <inertial>
      <mass value="200.0"/>
      <origin rpy="0 0 0" xyz="0.0 0.0 0.4485"/>
      <inertia ixx="21.14963333333333" ixy="0.0" ixz="0.0" iyy="29.71963333333333" iyz="0.0" izz="25.23163333333333"/>
    </inertial>
    <visual>
      <origin rpy="0 0 0" xyz="0.0 0.0 0.0"/>
      <geometry>
        <mesh filename="package://donkey_description/meshes/donkey_colourised_decimated.dae"/>
      </geometry>
    </visual>
    <collision>
      <origin rpy="0 0 0" xyz="0.0 0.0 0.4885"/>
      <geometry>
        <box size="1.007 0.707 0.727"/>
      </geometry>
    </collision>
  </link>
  <gazebo reference="donkey_base">
    <dampingFactor>0.001</dampingFactor>
  </gazebo>
  <joint name="donkey_base_link_joint" type="fixed">
    <child link="donkey_base"/>
    <parent link="base_link"/>
    <origin rpy="0 0 0" xyz="0 0 0"/>
  </joint>
  <link name="fl_wheel_link">
    <inertial>
      <mass value="8.0"/>
      <origin rpy="1.5707963267948966 0 0" xyz="0 0 0"/>
      <inertia ixx="0.024716666666666668" ixy="0" ixz="0" iyy="0.024716666666666668" iyz="0" izz="0.0361"/>
    </inertial>
    <visual>
      <origin rpy="1.5707963267948966 0 0" xyz="0 0 0"/>
      <geometry>
        <cylinder length="0.1" radius="0.095"/>
      </geometry>
    </visual>
  </link>
  <joint name="fl_wheel_joint" type="continuous">
    <axis xyz="0 1 0"/>
    <limit effort="100" velocity="100"/>
    <dynamics damping="0.0" friction="0.0"/>
    <safety_controller k_velocity="10.0"/>
    <origin rpy="0 0 0" xyz="0.36 0.25 0.095"/>
    <parent link="donkey_base"/>
    <child link="fl_wheel_link"/>
  </joint>
  <link name="fl_wheel_link_passive">
    <inertial>
      <mass value="1.0"/>
      <origin rpy="0 0 0" xyz="0 0 0"/>
      <inertia ixx="0.003610000000000001" ixy="0" ixz="0" iyy="0.003610000000000001" iyz="0" izz="0.003610000000000001"/>
    </inertial>
    <collision>
      <origin rpy="0 0 0" xyz="0 0 0"/>
      <geometry>
        <sphere radius="0.095"/>
      </geometry>
    </collision>
  </link>
  <joint name="fl_wheel_link_passive_joint" type="continuous">
    <axis xyz="0 1 0"/>
    <limit effort="100" velocity="100.0"/>
    <dynamics damping="0.0" friction="0.0"/>
    <safety_controller k_velocity="10.0"/>
    <origin rpy="0 0 0" xyz="0 0 0"/>
    <parent link="fl_wheel_link"/>
    <child link="fl_wheel_link_passive"/>
  </joint>
  <gazebo reference="fl_wheel_link_passive_joint">
    <implicitSpringDamper>1</implicitSpringDamper>
  </gazebo>
  <!-- Passive joint transmission with effort interface.
             Workaround to get all joints to publish a state.
             Do NOT use these joints for control! -->
  <transmission name="fl_wheel_link_passive_joint_trans">
    <type>transmission_interface/SimpleTransmission</type>
    <joint name="fl_wheel_link_passive_joint">
      <hardwareInterface>hardware_interface/EffortJointInterface</hardwareInterface>
    </joint>
    <actuator name="fl_wheel_link_passive_joint_motor">
      <mechanicalReduction>1</mechanicalReduction>
    </actuator>
  </transmission>
  <!-- Contact properties -->
  <gazebo reference="fl_wheel_link_passive">
    <mu>5</mu>
    <mu2>5</mu2>
    <dampingFactor>0.00001</dampingFactor>
    <selfCollide>0</selfCollide>
    <kp>1e6</kp>
    <kd>1e2</kd>
    <maxVel>2.0</maxVel>
    <minDepth>0.001</minDepth>
  </gazebo>
  <gazebo>
    <!-- Mecanum plugin -->
    <plugin filename="libmecanum_gazebo_plugin.so" name="fl_wheel_controller">
      <wheelLinkName>fl_wheel_link</wheelLinkName>
      <baseLinkName>base_link</baseLinkName>
      <axis>-1 1 0</axis>
    </plugin>
  </gazebo>
  <gazebo reference="fl_wheel_joint">
    <implicitSpringDamper>1</implicitSpringDamper>
  </gazebo>
  <gazebo reference="fl_wheel_link">
    <dampingFactor>0.001</dampingFactor>
  </gazebo>
  <transmission name="fl_wheel_joint_trans">
    <type>transmission_interface/SimpleTransmission</type>
    <joint name="fl_wheel_joint">
      <hardwareInterface>hardware_interface/VelocityJointInterface</hardwareInterface>
    </joint>
    <actuator name="fl_wheel_joint_motor">
      <mechanicalReduction>1</mechanicalReduction>
    </actuator>
  </transmission>
  <link name="fr_wheel_link">
    <inertial>
      <mass value="8.0"/>
      <origin rpy="1.5707963267948966 0 0" xyz="0 0 0"/>
      <inertia ixx="0.024716666666666668" ixy="0" ixz="0" iyy="0.024716666666666668" iyz="0" izz="0.0361"/>
    </inertial>
    <visual>
      <origin rpy="1.5707963267948966 0 0" xyz="0 0 0"/>
      <geometry>
        <cylinder length="0.1" radius="0.095"/>
      </geometry>
    </visual>
  </link>
  <joint name="fr_wheel_joint" type="continuous">
    <axis xyz="0 1 0"/>
    <limit effort="100" velocity="100"/>
    <dynamics damping="0.0" friction="0.0"/>
    <safety_controller k_velocity="10.0"/>
    <origin rpy="0 0 0" xyz="0.36 -0.25 0.095"/>
    <parent link="donkey_base"/>
    <child link="fr_wheel_link"/>
  </joint>
  <link name="fr_wheel_link_passive">
    <inertial>
      <mass value="1.0"/>
      <origin rpy="0 0 0" xyz="0 0 0"/>
      <inertia ixx="0.003610000000000001" ixy="0" ixz="0" iyy="0.003610000000000001" iyz="0" izz="0.003610000000000001"/>
    </inertial>
    <collision>
      <origin rpy="0 0 0" xyz="0 0 0"/>
      <geometry>
        <sphere radius="0.095"/>
      </geometry>
    </collision>
  </link>
  <joint name="fr_wheel_link_passive_joint" type="continuous">
    <axis xyz="0 1 0"/>
    <limit effort="100" velocity="100.0"/>
    <dynamics damping="0.0" friction="0.0"/>
    <safety_controller k_velocity="10.0"/>
    <origin rpy="0 0 0" xyz="0 0 0"/>
    <parent link="fr_wheel_link"/>
    <child link="fr_wheel_link_passive"/>
  </joint>
  <gazebo reference="fr_wheel_link_passive_joint">
    <implicitSpringDamper>1</implicitSpringDamper>
  </gazebo>
  <!-- Passive joint transmission with effort interface.
             Workaround to get all joints to publish a state.
             Do NOT use these joints for control! -->
  <transmission name="fr_wheel_link_passive_joint_trans">
    <type>transmission_interface/SimpleTransmission</type>
    <joint name="fr_wheel_link_passive_joint">
      <hardwareInterface>hardware_interface/EffortJointInterface</hardwareInterface>
    </joint>
    <actuator name="fr_wheel_link_passive_joint_motor">
      <mechanicalReduction>1</mechanicalReduction>
    </actuator>
  </transmission>
  <!-- Contact properties -->
  <gazebo reference="fr_wheel_link_passive">
    <mu>5</mu>
    <mu2>5</mu2>
    <dampingFactor>0.00001</dampingFactor>
    <selfCollide>0</selfCollide>
    <kp>1e6</kp>
    <kd>1e2</kd>
    <maxVel>2.0</maxVel>
    <minDepth>0.001</minDepth>
  </gazebo>
  <gazebo>
    <!-- Mecanum plugin -->
    <plugin filename="libmecanum_gazebo_plugin.so" name="fr_wheel_controller">
      <wheelLinkName>fr_wheel_link</wheelLinkName>
      <baseLinkName>base_link</baseLinkName>
      <axis>-1 -1 0</axis>
    </plugin>
  </gazebo>
  <gazebo reference="fr_wheel_joint">
    <implicitSpringDamper>1</implicitSpringDamper>
  </gazebo>
  <gazebo reference="fr_wheel_link">
    <dampingFactor>0.001</dampingFactor>
  </gazebo>
  <transmission name="fr_wheel_joint_trans">
    <type>transmission_interface/SimpleTransmission</type>
    <joint name="fr_wheel_joint">
      <hardwareInterface>hardware_interface/VelocityJointInterface</hardwareInterface>
    </joint>
    <actuator name="fr_wheel_joint_motor">
      <mechanicalReduction>1</mechanicalReduction>
    </actuator>
  </transmission>
  <link name="rl_wheel_link">
    <inertial>
      <mass value="8.0"/>
      <origin rpy="1.5707963267948966 0 0" xyz="0 0 0"/>
      <inertia ixx="0.024716666666666668" ixy="0" ixz="0" iyy="0.024716666666666668" iyz="0" izz="0.0361"/>
    </inertial>
    <visual>
      <origin rpy="1.5707963267948966 0 0" xyz="0 0 0"/>
      <geometry>
        <cylinder length="0.1" radius="0.095"/>
      </geometry>
    </visual>
  </link>
  <joint name="rl_wheel_joint" type="continuous">
    <axis xyz="0 1 0"/>
    <limit effort="100" velocity="100"/>
    <dynamics damping="0.0" friction="0.0"/>
    <safety_controller k_velocity="10.0"/>
    <origin rpy="0 0 0" xyz="-0.36 0.25 0.095"/>
    <parent link="donkey_base"/>
    <child link="rl_wheel_link"/>
  </joint>
  <link name="rl_wheel_link_passive">
    <inertial>
      <mass value="1.0"/>
      <origin rpy="0 0 0" xyz="0 0 0"/>
      <inertia ixx="0.003610000000000001" ixy="0" ixz="0" iyy="0.003610000000000001" iyz="0" izz="0.003610000000000001"/>
    </inertial>
    <collision>
      <origin rpy="0 0 0" xyz="0 0 0"/>
      <geometry>
        <sphere radius="0.095"/>
      </geometry>
    </collision>
  </link>
  <joint name="rl_wheel_link_passive_joint" type="continuous">
    <axis xyz="0 1 0"/>
    <limit effort="100" velocity="100.0"/>
    <dynamics damping="0.0" friction="0.0"/>
    <safety_controller k_velocity="10.0"/>
    <origin rpy="0 0 0" xyz="0 0 0"/>
    <parent link="rl_wheel_link"/>
    <child link="rl_wheel_link_passive"/>
  </joint>
  <gazebo reference="rl_wheel_link_passive_joint">
    <implicitSpringDamper>1</implicitSpringDamper>
  </gazebo>
  <!-- Passive joint transmission with effort interface.
             Workaround to get all joints to publish a state.
             Do NOT use these joints for control! -->
  <transmission name="rl_wheel_link_passive_joint_trans">
    <type>transmission_interface/SimpleTransmission</type>
    <joint name="rl_wheel_link_passive_joint">
      <hardwareInterface>hardware_interface/EffortJointInterface</hardwareInterface>
    </joint>
    <actuator name="rl_wheel_link_passive_joint_motor">
      <mechanicalReduction>1</mechanicalReduction>
    </actuator>
  </transmission>
  <!-- Contact properties -->
  <gazebo reference="rl_wheel_link_passive">
    <mu>5</mu>
    <mu2>5</mu2>
    <dampingFactor>0.00001</dampingFactor>
    <selfCollide>0</selfCollide>
    <kp>1e6</kp>
    <kd>1e2</kd>
    <maxVel>2.0</maxVel>
    <minDepth>0.001</minDepth>
  </gazebo>
  <gazebo>
    <!-- Mecanum plugin -->
    <plugin filename="libmecanum_gazebo_plugin.so" name="rl_wheel_controller">
      <wheelLinkName>rl_wheel_link</wheelLinkName>
      <baseLinkName>base_link</baseLinkName>
      <axis>1 1 0</axis>
    </plugin>
  </gazebo>
  <gazebo reference="rl_wheel_joint">
    <implicitSpringDamper>1</implicitSpringDamper>
  </gazebo>
  <gazebo reference="rl_wheel_link">
    <dampingFactor>0.001</dampingFactor>
  </gazebo>
  <transmission name="rl_wheel_joint_trans">
    <type>transmission_interface/SimpleTransmission</type>
    <joint name="rl_wheel_joint">
      <hardwareInterface>hardware_interface/VelocityJointInterface</hardwareInterface>
    </joint>
    <actuator name="rl_wheel_joint_motor">
      <mechanicalReduction>1</mechanicalReduction>
    </actuator>
  </transmission>
  <link name="rr_wheel_link">
    <inertial>
      <mass value="8.0"/>
      <origin rpy="1.5707963267948966 0 0" xyz="0 0 0"/>
      <inertia ixx="0.024716666666666668" ixy="0" ixz="0" iyy="0.024716666666666668" iyz="0" izz="0.0361"/>
    </inertial>
    <visual>
      <origin rpy="1.5707963267948966 0 0" xyz="0 0 0"/>
      <geometry>
        <cylinder length="0.1" radius="0.095"/>
      </geometry>
    </visual>
  </link>
  <joint name="rr_wheel_joint" type="continuous">
    <axis xyz="0 1 0"/>
    <limit effort="100" velocity="100"/>
    <dynamics damping="0.0" friction="0.0"/>
    <safety_controller k_velocity="10.0"/>
    <origin rpy="0 0 0" xyz="-0.36 -0.25 0.095"/>
    <parent link="donkey_base"/>
    <child link="rr_wheel_link"/>
  </joint>
  <link name="rr_wheel_link_passive">
    <inertial>
      <mass value="1.0"/>
      <origin rpy="0 0 0" xyz="0 0 0"/>
      <inertia ixx="0.003610000000000001" ixy="0" ixz="0" iyy="0.003610000000000001" iyz="0" izz="0.003610000000000001"/>
    </inertial>
    <collision>
      <origin rpy="0 0 0" xyz="0 0 0"/>
      <geometry>
        <sphere radius="0.095"/>
      </geometry>
    </collision>
  </link>
  <joint name="rr_wheel_link_passive_joint" type="continuous">
    <axis xyz="0 1 0"/>
    <limit effort="100" velocity="100.0"/>
    <dynamics damping="0.0" friction="0.0"/>
    <safety_controller k_velocity="10.0"/>
    <origin rpy="0 0 0" xyz="0 0 0"/>
    <parent link="rr_wheel_link"/>
    <child link="rr_wheel_link_passive"/>
  </joint>
  <gazebo reference="rr_wheel_link_passive_joint">
    <implicitSpringDamper>1</implicitSpringDamper>
  </gazebo>
  <!-- Passive joint transmission with effort interface.
             Workaround to get all joints to publish a state.
             Do NOT use these joints for control! -->
  <transmission name="rr_wheel_link_passive_joint_trans">
    <type>transmission_interface/SimpleTransmission</type>
    <joint name="rr_wheel_link_passive_joint">
      <hardwareInterface>hardware_interface/EffortJointInterface</hardwareInterface>
    </joint>
    <actuator name="rr_wheel_link_passive_joint_motor">
      <mechanicalReduction>1</mechanicalReduction>
    </actuator>
  </transmission>
  <!-- Contact properties -->
  <gazebo reference="rr_wheel_link_passive">
    <mu>5</mu>
    <mu2>5</mu2>
    <dampingFactor>0.00001</dampingFactor>
    <selfCollide>0</selfCollide>
    <kp>1e6</kp>
    <kd>1e2</kd>
    <maxVel>2.0</maxVel>
    <minDepth>0.001</minDepth>
  </gazebo>
  <gazebo>
    <!-- Mecanum plugin -->
    <plugin filename="libmecanum_gazebo_plugin.so" name="rr_wheel_controller">
      <wheelLinkName>rr_wheel_link</wheelLinkName>
      <baseLinkName>base_link</baseLinkName>
      <axis>1 -1 0</axis>
    </plugin>
  </gazebo>
  <gazebo reference="rr_wheel_joint">
    <implicitSpringDamper>1</implicitSpringDamper>
  </gazebo>
  <gazebo reference="rr_wheel_link">
    <dampingFactor>0.001</dampingFactor>
  </gazebo>
  <transmission name="rr_wheel_joint_trans">
    <type>transmission_interface/SimpleTransmission</type>
    <joint name="rr_wheel_joint">
      <hardwareInterface>hardware_interface/VelocityJointInterface</hardwareInterface>
    </joint>
    <actuator name="rr_wheel_joint_motor">
      <mechanicalReduction>1</mechanicalReduction>
    </actuator>
  </transmission>
  <gazebo>
    <plugin filename="libgazebo_ros_control.so" name="gazebo_ros_control">
      <robotNamespace>/donkey</robotNamespace>
    </plugin>
  </gazebo>
  <link name="dummy_link"/>
  <joint name="donkey_base_mount_joint" type="fixed">
    <child link="dummy_link"/>
    <parent link="base_link"/>
    <origin rpy="0 0 0" xyz="0.0 0.0 0.0"/>
  </joint>
</robot>
