<?xml version="1.0" ?>
<!-- =================================================================================== -->
<!-- |    This document was autogenerated by xacro from myumi_v2.xacro                 | -->
<!-- |    EDITING THIS FILE BY HAND IS NOT RECOMMENDED                                 | -->
<!-- =================================================================================== -->
<robot name="abb_myumi_v2">
  <!-- ============================================== Include Macros =============================================== -->
  <!-- ================================================ Main Macros ================================================ -->
  <!-- ============================================== Support Macros =============================================== -->
  <!-- ================================================ Main Macros ================================================ -->
  <!-- ============================================== Support Macros =============================================== -->
  <!-- ================================================ Main Macros ================================================ -->
  <!-- ================================================ Main Macros ================================================ -->
  <!-- ============================================== Support Macros =============================================== -->
  <!-- ================================================ Main Macros ================================================ -->
  <!-- ================================================ Main Macros ================================================ -->
  <!-- ================================================ Main Macros ================================================ -->
  <!-- ============================================== Support Macros =============================================== -->
  <link name="base_link">
    <inertial>
      <!-- Mass -->
      <mass value="1.0e-5"/>
      <!-- Inertia -->
      <inertia ixx="1.0e-6" ixy="0.0" ixz="0.0" iyy="1.0e-6" iyz="0.0" izz="1.0e-6"/>
    </inertial>
  </link>
  <link name="chassis_link">
    <visual>
      <!-- Origin -->
      <origin rpy="0.0 0.0 0.0" xyz="0.0 0.0 0.0"/>
      <geometry>
        <mesh filename="package://abb_mp_myumi_description/meshes/myumi_v2/visual/chassis_link.stl"/>
      </geometry>
      <material name="light_grey">
        <color rgba="0.6 0.6 0.6 1.0"/>
      </material>
    </visual>
    <collision>
      <!-- Origin -->
      <origin rpy="0.0 0.0 0.0" xyz="0.0 0.0 0.0"/>
      <geometry>
        <mesh filename="package://abb_mp_myumi_description/meshes/myumi_v2/collision/chassis_link.stl"/>
      </geometry>
    </collision>
    <inertial>
      <!-- Origin -->
      <origin rpy="0.0 0.0 0.0" xyz="0.0 0.0 0.125"/>
      <!-- Mass -->
      <mass value="46.23"/>
      <inertia ixx="0.44" ixy="0.0" ixz="0.0" iyy="0.45" iyz="0.0" izz="0.66"/>
    </inertial>
  </link>
  <link name="front_radar_link">
    <inertial>
      <!-- Mass -->
      <mass value="1.0e-5"/>
      <!-- Inertia -->
      <inertia ixx="1.0e-6" ixy="0.0" ixz="0.0" iyy="1.0e-6" iyz="0.0" izz="1.0e-6"/>
    </inertial>
  </link>
  <link name="front_laser_scanner_link">
    <inertial>
      <!-- Mass -->
      <mass value="1.0e-5"/>
      <!-- Inertia -->
      <inertia ixx="1.0e-6" ixy="0.0" ixz="0.0" iyy="1.0e-6" iyz="0.0" izz="1.0e-6"/>
    </inertial>
  </link>
  <link name="rear_laser_scanner_link">
    <inertial>
      <!-- Mass -->
      <mass value="1.0e-5"/>
      <!-- Inertia -->
      <inertia ixx="1.0e-6" ixy="0.0" ixz="0.0" iyy="1.0e-6" iyz="0.0" izz="1.0e-6"/>
    </inertial>
  </link>
  <joint name="chassis_joint" type="fixed">
    <!-- Parent and child -->
    <parent link="base_link"/>
    <child link="chassis_link"/>
    <!-- Origin -->
    <origin rpy="0.0 0.0 0.0" xyz="0.0 0.0 0.0292"/>
  </joint>
  <joint name="front_radar_joint" type="fixed">
    <!-- Parent and child -->
    <parent link="chassis_link"/>
    <child link="front_radar_link"/>
    <!-- Origin -->
    <origin rpy="0.0 0.0 0.0" xyz="0.35116 0.0 0.07192"/>
  </joint>
  <joint name="front_laser_scanner_joint" type="fixed">
    <!-- Parent and child -->
    <parent link="chassis_link"/>
    <child link="front_laser_scanner_link"/>
    <!-- Origin -->
    <origin rpy="0.0 0.0 0.0" xyz="0.16789 0.0 0.2837"/>
  </joint>
  <joint name="rear_laser_scanner_joint" type="fixed">
    <!-- Parent and child -->
    <parent link="chassis_link"/>
    <child link="rear_laser_scanner_link"/>
    <!-- Origin -->
    <origin rpy="0.0 0.0 3.141592653589793" xyz="-0.17921 0.0 0.2837"/>
  </joint>
  <!--link name="world"/>

  <joint name="fixed" type="fixed">
    <parent link="world"/>
    <child link="base_link"/>
  </joint-->
  <gazebo reference="chassis_link">
    <material>Gazebo/White</material>
  </gazebo>
  <!-- ================ Subcomponents ================ -->
  <!-- ============================================== Include Macros =============================================== -->
  <!-- ================================================ Main Macros ================================================ -->
  <!-- ============================================== Support Macros =============================================== -->
  <!-- ================================================ Main Macros ================================================ -->
  <!-- ============================================== Support Macros =============================================== -->
  <!-- ================================================ Main Macros ================================================ -->
  <!-- ================================================ Main Macros ================================================ -->
  <!-- ============================================== Support Macros =============================================== -->
  <!-- ================================================ Main Macros ================================================ -->
  <!-- ================================================ Main Macros ================================================ -->
  <!-- ================================================ Main Macros ================================================ -->
  <!-- ============================================== Support Macros =============================================== -->
  <link name="front_left_base_link">
    <inertial>
      <!-- Mass -->
      <mass value="1.0e-5"/>
      <!-- Inertia -->
      <inertia ixx="1.0e-6" ixy="0.0" ixz="0.0" iyy="1.0e-6" iyz="0.0" izz="1.0e-6"/>
    </inertial>
  </link>
  <link name="front_left_steering_link">
    <visual>
      <!-- Origin -->
      <origin rpy="0.0 0.0 0.0" xyz="0.0 0.0 0.0"/>
      <geometry>
        <mesh filename="package://abb_mp_steerable_wheel_description/meshes/sw_v3/visual/steering_link.stl"/>
      </geometry>
      <material name="light_grey">
        <color rgba="0.6 0.6 0.6 1.0"/>
      </material>
    </visual>
    <collision>
      <!-- Origin -->
      <origin rpy="0.0 0.0 0.0" xyz="0.0 0.0 0.0"/>
      <geometry>
        <mesh filename="package://abb_mp_steerable_wheel_description/meshes/sw_v3/collision/steering_link.stl"/>
      </geometry>
    </collision>
    <inertial>
      <!-- Origin -->
      <origin rpy="0.0 1.0000736613927508 0.0" xyz="0.0 0.0 0.0"/>
      <!-- Mass -->
      <mass value="2.6"/>
      <inertia ixx="0.0018" ixy="0.0" ixz="0.0" iyy="0.0017" iyz="-0.0004" izz="0.0013"/>
    </inertial>
  </link>
  <link name="front_left_drive_wheel_link">
    <visual>
      <!-- Origin -->
      <origin rpy="0.0 0.0 0.0" xyz="0.0 0.0 0.0"/>
      <geometry>
        <mesh filename="package://abb_mp_steerable_wheel_description/meshes/sw_v3/visual/drive_wheel_link.stl"/>
      </geometry>
      <material name="dark_grey">
        <color rgba="0.3 0.3 0.3 1.0"/>
      </material>
    </visual>
    <collision>
      <!-- Origin -->
      <origin rpy="1.5707963267948966 0.0 0.0" xyz="0.0 0.0 0.0"/>
      <geometry>
        <cylinder length="0.047" radius="0.0865"/>
      </geometry>
    </collision>
    <inertial>
      <!-- Origin -->
      <origin rpy="0.0 0.0 0.0" xyz="0.0 0.0 0.0"/>
      <!-- Mass -->
      <mass value="1.31"/>
      <inertia ixx="0.0018" ixy="0.0" ixz="0.0" iyy="0.0017" iyz="0.0" izz="0.0013"/>
    </inertial>
  </link>
  <joint name="front_left_steering_joint" type="revolute">
    <!-- Parent and child -->
    <parent link="front_left_base_link"/>
    <child link="front_left_steering_link"/>
    <!-- Origin -->
    <origin rpy="0.0 0.0 0.0" xyz="0.0 0.0 0.0"/>
    <axis xyz="0.0 0.0 1.0"/>
    <limit effort="1000.0" lower="-3.141592653589793" upper="3.141592653589793" velocity="62.83185307179586"/>
    <dynamics damping="0.0" friction="0.0"/>
  </joint>
  <joint name="front_left_drive_wheel_joint" type="continuous">
    <!-- Parent and child -->
    <parent link="front_left_steering_link"/>
    <child link="front_left_drive_wheel_link"/>
    <!-- Origin -->
    <origin rpy="0.0 0.0 0.0" xyz="0.0 0.0 -0.0925"/>
    <axis xyz="0.0 1.0 0.0"/>
  </joint>
  <transmission name="front_left_steering_transmission">
    <type>transmission_interface/SimpleTransmission</type>
    <joint name="front_left_steering_joint">
      <hardwareInterface>hardware_interface/PositionJointInterface</hardwareInterface>
    </joint>
    <actuator name="front_left_steering_joint_motor">
      <mechanicalReduction>1.0</mechanicalReduction>
    </actuator>
  </transmission>
  <transmission name="front_left_drive_wheel_transmission">
    <type>transmission_interface/SimpleTransmission</type>
    <joint name="front_left_drive_wheel_joint">
      <hardwareInterface>hardware_interface/VelocityJointInterface</hardwareInterface>
    </joint>
    <actuator name="front_left_drive_wheel_joint_motor">
      <mechanicalReduction>1.0</mechanicalReduction>
    </actuator>
  </transmission>
  <gazebo reference="front_left_steering_link">
    <material>Gazebo/White</material>
  </gazebo>
  <gazebo reference="front_left_drive_wheel_link">
    <material>Gazebo/Grey</material>
    <mu1 value="1.0"/>
    <mu2 value="1.0"/>
    <kp value="1000000.0"/>
    <kd value="1000.0"/>
    <fdir1 value="1.0 0.0 0.0"/>
  </gazebo>
  <!-- ============================================== Include Macros =============================================== -->
  <!-- ================================================ Main Macros ================================================ -->
  <!-- ============================================== Support Macros =============================================== -->
  <!-- ================================================ Main Macros ================================================ -->
  <!-- ============================================== Support Macros =============================================== -->
  <!-- ================================================ Main Macros ================================================ -->
  <!-- ================================================ Main Macros ================================================ -->
  <!-- ============================================== Support Macros =============================================== -->
  <!-- ================================================ Main Macros ================================================ -->
  <!-- ================================================ Main Macros ================================================ -->
  <!-- ================================================ Main Macros ================================================ -->
  <!-- ============================================== Support Macros =============================================== -->
  <link name="front_right_base_link">
    <inertial>
      <!-- Mass -->
      <mass value="1.0e-5"/>
      <!-- Inertia -->
      <inertia ixx="1.0e-6" ixy="0.0" ixz="0.0" iyy="1.0e-6" iyz="0.0" izz="1.0e-6"/>
    </inertial>
  </link>
  <link name="front_right_steering_link">
    <visual>
      <!-- Origin -->
      <origin rpy="0.0 0.0 0.0" xyz="0.0 0.0 0.0"/>
      <geometry>
        <mesh filename="package://abb_mp_steerable_wheel_description/meshes/sw_v3/visual/steering_link.stl"/>
      </geometry>
      <material name="light_grey">
        <color rgba="0.6 0.6 0.6 1.0"/>
      </material>
    </visual>
    <collision>
      <!-- Origin -->
      <origin rpy="0.0 0.0 0.0" xyz="0.0 0.0 0.0"/>
      <geometry>
        <mesh filename="package://abb_mp_steerable_wheel_description/meshes/sw_v3/collision/steering_link.stl"/>
      </geometry>
    </collision>
    <inertial>
      <!-- Origin -->
      <origin rpy="0.0 1.0000736613927508 0.0" xyz="0.0 0.0 0.0"/>
      <!-- Mass -->
      <mass value="2.6"/>
      <inertia ixx="0.0018" ixy="0.0" ixz="0.0" iyy="0.0017" iyz="-0.0004" izz="0.0013"/>
    </inertial>
  </link>
  <link name="front_right_drive_wheel_link">
    <visual>
      <!-- Origin -->
      <origin rpy="0.0 0.0 0.0" xyz="0.0 0.0 0.0"/>
      <geometry>
        <mesh filename="package://abb_mp_steerable_wheel_description/meshes/sw_v3/visual/drive_wheel_link.stl"/>
      </geometry>
      <material name="dark_grey">
        <color rgba="0.3 0.3 0.3 1.0"/>
      </material>
    </visual>
    <collision>
      <!-- Origin -->
      <origin rpy="1.5707963267948966 0.0 0.0" xyz="0.0 0.0 0.0"/>
      <geometry>
        <cylinder length="0.047" radius="0.0865"/>
      </geometry>
    </collision>
    <inertial>
      <!-- Origin -->
      <origin rpy="0.0 0.0 0.0" xyz="0.0 0.0 0.0"/>
      <!-- Mass -->
      <mass value="1.31"/>
      <inertia ixx="0.0018" ixy="0.0" ixz="0.0" iyy="0.0017" iyz="0.0" izz="0.0013"/>
    </inertial>
  </link>
  <joint name="front_right_steering_joint" type="revolute">
    <!-- Parent and child -->
    <parent link="front_right_base_link"/>
    <child link="front_right_steering_link"/>
    <!-- Origin -->
    <origin rpy="0.0 0.0 0.0" xyz="0.0 0.0 0.0"/>
    <axis xyz="0.0 0.0 1.0"/>
    <limit effort="1000.0" lower="-3.141592653589793" upper="3.141592653589793" velocity="62.83185307179586"/>
    <dynamics damping="0.0" friction="0.0"/>
  </joint>
  <joint name="front_right_drive_wheel_joint" type="continuous">
    <!-- Parent and child -->
    <parent link="front_right_steering_link"/>
    <child link="front_right_drive_wheel_link"/>
    <!-- Origin -->
    <origin rpy="0.0 0.0 0.0" xyz="0.0 0.0 -0.0925"/>
    <axis xyz="0.0 1.0 0.0"/>
  </joint>
  <transmission name="front_right_steering_transmission">
    <type>transmission_interface/SimpleTransmission</type>
    <joint name="front_right_steering_joint">
      <hardwareInterface>hardware_interface/PositionJointInterface</hardwareInterface>
    </joint>
    <actuator name="front_right_steering_joint_motor">
      <mechanicalReduction>1.0</mechanicalReduction>
    </actuator>
  </transmission>
  <transmission name="front_right_drive_wheel_transmission">
    <type>transmission_interface/SimpleTransmission</type>
    <joint name="front_right_drive_wheel_joint">
      <hardwareInterface>hardware_interface/VelocityJointInterface</hardwareInterface>
    </joint>
    <actuator name="front_right_drive_wheel_joint_motor">
      <mechanicalReduction>1.0</mechanicalReduction>
    </actuator>
  </transmission>
  <gazebo reference="front_right_steering_link">
    <material>Gazebo/White</material>
  </gazebo>
  <gazebo reference="front_right_drive_wheel_link">
    <material>Gazebo/Grey</material>
    <mu1 value="1.0"/>
    <mu2 value="1.0"/>
    <kp value="1000000.0"/>
    <kd value="1000.0"/>
    <fdir1 value="1.0 0.0 0.0"/>
  </gazebo>
  <!-- ============================================== Include Macros =============================================== -->
  <!-- ================================================ Main Macros ================================================ -->
  <!-- ============================================== Support Macros =============================================== -->
  <!-- ================================================ Main Macros ================================================ -->
  <!-- ============================================== Support Macros =============================================== -->
  <!-- ================================================ Main Macros ================================================ -->
  <!-- ================================================ Main Macros ================================================ -->
  <!-- ============================================== Support Macros =============================================== -->
  <!-- ================================================ Main Macros ================================================ -->
  <!-- ================================================ Main Macros ================================================ -->
  <!-- ================================================ Main Macros ================================================ -->
  <!-- ============================================== Support Macros =============================================== -->
  <link name="rear_right_base_link">
    <inertial>
      <!-- Mass -->
      <mass value="1.0e-5"/>
      <!-- Inertia -->
      <inertia ixx="1.0e-6" ixy="0.0" ixz="0.0" iyy="1.0e-6" iyz="0.0" izz="1.0e-6"/>
    </inertial>
  </link>
  <link name="rear_right_steering_link">
    <visual>
      <!-- Origin -->
      <origin rpy="0.0 0.0 0.0" xyz="0.0 0.0 0.0"/>
      <geometry>
        <mesh filename="package://abb_mp_steerable_wheel_description/meshes/sw_v3/visual/steering_link.stl"/>
      </geometry>
      <material name="light_grey">
        <color rgba="0.6 0.6 0.6 1.0"/>
      </material>
    </visual>
    <collision>
      <!-- Origin -->
      <origin rpy="0.0 0.0 0.0" xyz="0.0 0.0 0.0"/>
      <geometry>
        <mesh filename="package://abb_mp_steerable_wheel_description/meshes/sw_v3/collision/steering_link.stl"/>
      </geometry>
    </collision>
    <inertial>
      <!-- Origin -->
      <origin rpy="0.0 1.0000736613927508 0.0" xyz="0.0 0.0 0.0"/>
      <!-- Mass -->
      <mass value="2.6"/>
      <inertia ixx="0.0018" ixy="0.0" ixz="0.0" iyy="0.0017" iyz="-0.0004" izz="0.0013"/>
    </inertial>
  </link>
  <link name="rear_right_drive_wheel_link">
    <visual>
      <!-- Origin -->
      <origin rpy="0.0 0.0 0.0" xyz="0.0 0.0 0.0"/>
      <geometry>
        <mesh filename="package://abb_mp_steerable_wheel_description/meshes/sw_v3/visual/drive_wheel_link.stl"/>
      </geometry>
      <material name="dark_grey">
        <color rgba="0.3 0.3 0.3 1.0"/>
      </material>
    </visual>
    <collision>
      <!-- Origin -->
      <origin rpy="1.5707963267948966 0.0 0.0" xyz="0.0 0.0 0.0"/>
      <geometry>
        <cylinder length="0.047" radius="0.0865"/>
      </geometry>
    </collision>
    <inertial>
      <!-- Origin -->
      <origin rpy="0.0 0.0 0.0" xyz="0.0 0.0 0.0"/>
      <!-- Mass -->
      <mass value="1.31"/>
      <inertia ixx="0.0018" ixy="0.0" ixz="0.0" iyy="0.0017" iyz="0.0" izz="0.0013"/>
    </inertial>
  </link>
  <joint name="rear_right_steering_joint" type="revolute">
    <!-- Parent and child -->
    <parent link="rear_right_base_link"/>
    <child link="rear_right_steering_link"/>
    <!-- Origin -->
    <origin rpy="0.0 0.0 0.0" xyz="0.0 0.0 0.0"/>
    <axis xyz="0.0 0.0 1.0"/>
    <limit effort="1000.0" lower="-3.141592653589793" upper="3.141592653589793" velocity="62.83185307179586"/>
    <dynamics damping="0.0" friction="0.0"/>
  </joint>
  <joint name="rear_right_drive_wheel_joint" type="continuous">
    <!-- Parent and child -->
    <parent link="rear_right_steering_link"/>
    <child link="rear_right_drive_wheel_link"/>
    <!-- Origin -->
    <origin rpy="0.0 0.0 0.0" xyz="0.0 0.0 -0.0925"/>
    <axis xyz="0.0 1.0 0.0"/>
  </joint>
  <transmission name="rear_right_steering_transmission">
    <type>transmission_interface/SimpleTransmission</type>
    <joint name="rear_right_steering_joint">
      <hardwareInterface>hardware_interface/PositionJointInterface</hardwareInterface>
    </joint>
    <actuator name="rear_right_steering_joint_motor">
      <mechanicalReduction>1.0</mechanicalReduction>
    </actuator>
  </transmission>
  <transmission name="rear_right_drive_wheel_transmission">
    <type>transmission_interface/SimpleTransmission</type>
    <joint name="rear_right_drive_wheel_joint">
      <hardwareInterface>hardware_interface/VelocityJointInterface</hardwareInterface>
    </joint>
    <actuator name="rear_right_drive_wheel_joint_motor">
      <mechanicalReduction>1.0</mechanicalReduction>
    </actuator>
  </transmission>
  <gazebo reference="rear_right_steering_link">
    <material>Gazebo/White</material>
  </gazebo>
  <gazebo reference="rear_right_drive_wheel_link">
    <material>Gazebo/Grey</material>
    <mu1 value="1.0"/>
    <mu2 value="1.0"/>
    <kp value="1000000.0"/>
    <kd value="1000.0"/>
    <fdir1 value="1.0 0.0 0.0"/>
  </gazebo>
  <!-- ============================================== Include Macros =============================================== -->
  <!-- ================================================ Main Macros ================================================ -->
  <!-- ============================================== Support Macros =============================================== -->
  <!-- ================================================ Main Macros ================================================ -->
  <!-- ============================================== Support Macros =============================================== -->
  <!-- ================================================ Main Macros ================================================ -->
  <!-- ================================================ Main Macros ================================================ -->
  <!-- ============================================== Support Macros =============================================== -->
  <!-- ================================================ Main Macros ================================================ -->
  <!-- ================================================ Main Macros ================================================ -->
  <!-- ================================================ Main Macros ================================================ -->
  <!-- ============================================== Support Macros =============================================== -->
  <link name="rear_left_base_link">
    <inertial>
      <!-- Mass -->
      <mass value="1.0e-5"/>
      <!-- Inertia -->
      <inertia ixx="1.0e-6" ixy="0.0" ixz="0.0" iyy="1.0e-6" iyz="0.0" izz="1.0e-6"/>
    </inertial>
  </link>
  <link name="rear_left_steering_link">
    <visual>
      <!-- Origin -->
      <origin rpy="0.0 0.0 0.0" xyz="0.0 0.0 0.0"/>
      <geometry>
        <mesh filename="package://abb_mp_steerable_wheel_description/meshes/sw_v3/visual/steering_link.stl"/>
      </geometry>
      <material name="light_grey">
        <color rgba="0.6 0.6 0.6 1.0"/>
      </material>
    </visual>
    <collision>
      <!-- Origin -->
      <origin rpy="0.0 0.0 0.0" xyz="0.0 0.0 0.0"/>
      <geometry>
        <mesh filename="package://abb_mp_steerable_wheel_description/meshes/sw_v3/collision/steering_link.stl"/>
      </geometry>
    </collision>
    <inertial>
      <!-- Origin -->
      <origin rpy="0.0 1.0000736613927508 0.0" xyz="0.0 0.0 0.0"/>
      <!-- Mass -->
      <mass value="2.6"/>
      <inertia ixx="0.0018" ixy="0.0" ixz="0.0" iyy="0.0017" iyz="-0.0004" izz="0.0013"/>
    </inertial>
  </link>
  <link name="rear_left_drive_wheel_link">
    <visual>
      <!-- Origin -->
      <origin rpy="0.0 0.0 0.0" xyz="0.0 0.0 0.0"/>
      <geometry>
        <mesh filename="package://abb_mp_steerable_wheel_description/meshes/sw_v3/visual/drive_wheel_link.stl"/>
      </geometry>
      <material name="dark_grey">
        <color rgba="0.3 0.3 0.3 1.0"/>
      </material>
    </visual>
    <collision>
      <!-- Origin -->
      <origin rpy="1.5707963267948966 0.0 0.0" xyz="0.0 0.0 0.0"/>
      <geometry>
        <cylinder length="0.047" radius="0.0865"/>
      </geometry>
    </collision>
    <inertial>
      <!-- Origin -->
      <origin rpy="0.0 0.0 0.0" xyz="0.0 0.0 0.0"/>
      <!-- Mass -->
      <mass value="1.31"/>
      <inertia ixx="0.0018" ixy="0.0" ixz="0.0" iyy="0.0017" iyz="0.0" izz="0.0013"/>
    </inertial>
  </link>
  <joint name="rear_left_steering_joint" type="revolute">
    <!-- Parent and child -->
    <parent link="rear_left_base_link"/>
    <child link="rear_left_steering_link"/>
    <!-- Origin -->
    <origin rpy="0.0 0.0 0.0" xyz="0.0 0.0 0.0"/>
    <axis xyz="0.0 0.0 1.0"/>
    <limit effort="1000.0" lower="-3.141592653589793" upper="3.141592653589793" velocity="62.83185307179586"/>
    <dynamics damping="0.0" friction="0.0"/>
  </joint>
  <joint name="rear_left_drive_wheel_joint" type="continuous">
    <!-- Parent and child -->
    <parent link="rear_left_steering_link"/>
    <child link="rear_left_drive_wheel_link"/>
    <!-- Origin -->
    <origin rpy="0.0 0.0 0.0" xyz="0.0 0.0 -0.0925"/>
    <axis xyz="0.0 1.0 0.0"/>
  </joint>
  <transmission name="rear_left_steering_transmission">
    <type>transmission_interface/SimpleTransmission</type>
    <joint name="rear_left_steering_joint">
      <hardwareInterface>hardware_interface/PositionJointInterface</hardwareInterface>
    </joint>
    <actuator name="rear_left_steering_joint_motor">
      <mechanicalReduction>1.0</mechanicalReduction>
    </actuator>
  </transmission>
  <transmission name="rear_left_drive_wheel_transmission">
    <type>transmission_interface/SimpleTransmission</type>
    <joint name="rear_left_drive_wheel_joint">
      <hardwareInterface>hardware_interface/VelocityJointInterface</hardwareInterface>
    </joint>
    <actuator name="rear_left_drive_wheel_joint_motor">
      <mechanicalReduction>1.0</mechanicalReduction>
    </actuator>
  </transmission>
  <gazebo reference="rear_left_steering_link">
    <material>Gazebo/White</material>
  </gazebo>
  <gazebo reference="rear_left_drive_wheel_link">
    <material>Gazebo/Grey</material>
    <mu1 value="1.0"/>
    <mu2 value="1.0"/>
    <kp value="1000000.0"/>
    <kd value="1000.0"/>
    <fdir1 value="1.0 0.0 0.0"/>
  </gazebo>
  <joint name="front_left_joint" type="fixed">
    <!-- Parent and child -->
    <parent link="chassis_link"/>
    <child link="front_left_base_link"/>
    <!-- Origin -->
    <origin rpy="0.0 0.0 0.0" xyz="0.285 0.2002 0.1498"/>
  </joint>
  <joint name="front_right_joint" type="fixed">
    <!-- Parent and child -->
    <parent link="chassis_link"/>
    <child link="front_right_base_link"/>
    <!-- Origin -->
    <origin rpy="0.0 0.0 0.0" xyz="0.285 -0.2002 0.1498"/>
  </joint>
  <joint name="rear_right_joint" type="fixed">
    <!-- Parent and child -->
    <parent link="chassis_link"/>
    <child link="rear_right_base_link"/>
    <!-- Origin -->
    <origin rpy="0.0 0.0 0.0" xyz="-0.165 -0.2002 0.1498"/>
  </joint>
  <joint name="rear_left_joint" type="fixed">
    <!-- Parent and child -->
    <parent link="chassis_link"/>
    <child link="rear_left_base_link"/>
    <!-- Origin -->
    <origin rpy="0.0 0.0 0.0" xyz="-0.165 0.2002 0.1498"/>
  </joint>
  <!-- ============================================== Include Macros =============================================== -->
  <!-- ================================================ Main Macros ================================================ -->
  <!-- ============================================== Support Macros =============================================== -->
  <!-- ================================================ Main Macros ================================================ -->
  <!-- ============================================== Support Macros =============================================== -->
  <!-- ================================================ Main Macros ================================================ -->
  <!-- ================================================ Main Macros ================================================ -->
  <!-- ============================================== Support Macros =============================================== -->
  <!-- ================================================ Main Macros ================================================ -->
  <!-- ================================================ Main Macros ================================================ -->
  <!-- ================================================ Main Macros ================================================ -->
  <!-- ============================================== Support Macros =============================================== -->
  <link name="pillar_base_link">
    <visual>
      <!-- Origin -->
      <origin rpy="0.0 0.0 0.0" xyz="0.0 0.0 0.241"/>
      <geometry>
        <mesh filename="package://abb_mp_telescopic_pillar_description/meshes/tp_v2/visual/base_link.stl"/>
      </geometry>
      <material name="dark_grey">
        <color rgba="0.3 0.3 0.3 1.0"/>
      </material>
    </visual>
    <collision>
      <!-- Origin -->
      <origin rpy="0.0 0.0 0.0" xyz="0.0 0.0 0.241"/>
      <geometry>
        <mesh filename="package://abb_mp_telescopic_pillar_description/meshes/tp_v2/collision/base_link.stl"/>
      </geometry>
    </collision>
    <inertial>
      <!-- Origin -->
      <origin rpy="0.0 0.0 0.0" xyz="0.0 0.0 0.36"/>
      <!-- Mass -->
      <mass value="5.5"/>
      <inertia ixx="0.001422" ixy="0.0" ixz="0.0" iyy="0.001422" iyz="0.0" izz="0.000366"/>
    </inertial>
  </link>
  <link name="pillar_body_link">
    <visual>
      <!-- Origin -->
      <origin rpy="0.0 0.0 0.0" xyz="0.0 0.0 0.1"/>
      <geometry>
        <mesh filename="package://abb_mp_telescopic_pillar_description/meshes/tp_v2/visual/body_link.stl"/>
      </geometry>
      <material name="light_grey">
        <color rgba="0.6 0.6 0.6 1.0"/>
      </material>
    </visual>
    <collision>
      <!-- Origin -->
      <origin rpy="0.0 0.0 0.0" xyz="0.0 0.0 0.1"/>
      <geometry>
        <mesh filename="package://abb_mp_telescopic_pillar_description/meshes/tp_v2/collision/body_link.stl"/>
      </geometry>
    </collision>
    <inertial>
      <!-- Origin -->
      <origin rpy="0.0 0.0 0.0" xyz="0.0 0.0 0.36"/>
      <!-- Mass -->
      <mass value="5.5"/>
      <inertia ixx="0.001422" ixy="0.0" ixz="0.0" iyy="0.001422" iyz="0.0" izz="0.000366"/>
    </inertial>
  </link>
  <link name="pillar_top_link">
    <inertial>
      <!-- Mass -->
      <mass value="1.0e-5"/>
      <!-- Inertia -->
      <inertia ixx="1.0e-6" ixy="0.0" ixz="0.0" iyy="1.0e-6" iyz="0.0" izz="1.0e-6"/>
    </inertial>
  </link>
  <joint name="pillar_body_joint" type="prismatic">
    <!-- Parent and child -->
    <parent link="pillar_base_link"/>
    <child link="pillar_body_link"/>
    <!-- Origin -->
    <origin rpy="0.0 0.0 0.0" xyz="0.0 0.0 0.241"/>
    <axis xyz="0 0 1"/>
    <limit effort="1000.0" lower="0.0" upper="0.45" velocity="1.0"/>
    <dynamics damping="0.0" friction="0.0"/>
  </joint>
  <joint name="pillar_top_joint" type="fixed">
    <!-- Parent and child -->
    <parent link="pillar_body_link"/>
    <child link="pillar_top_link"/>
    <!-- Origin -->
    <origin rpy="0.0 0.0 0.0" xyz="0.0 0.0 0.5125"/>
  </joint>
  <transmission name="pillar_body_transmission">
    <type>transmission_interface/SimpleTransmission</type>
    <joint name="pillar_body_joint">
      <hardwareInterface>hardware_interface/EffortJointInterface</hardwareInterface>
    </joint>
    <actuator name="pillar_body_joint_motor">
      <mechanicalReduction>1.0</mechanicalReduction>
    </actuator>
  </transmission>
  <gazebo reference="pillar_base_link">
    <material>Gazebo/Grey</material>
    <mu1 value="0.8"/>
    <mu2 value="0.8"/>
    <kp value="1000000.0"/>
    <kd value="1000.0"/>
    <fdir1 value="0 0 1"/>
    <maxVel value="0.0"/>
    <minDepth value="0.001"/>
  </gazebo>
  <gazebo reference="pillar_body_link">
    <material>Gazebo/White</material>
    <mu1 value="0.8"/>
    <mu2 value="0.8"/>
    <kp value="1000000.0"/>
    <kd value="1000.0"/>
    <fdir1 value="0 0 1"/>
    <maxVel value="0.0"/>
    <minDepth value="0.001"/>
  </gazebo>
  <!--xacro:include filename="$(find abb_mp_telescopic_pillar_description)/urdf/gazebo.urdf.xacro"/-->
  <joint name="chassi_pillar_joint" type="fixed">
    <!-- Parent and child -->
    <parent link="chassis_link"/>
    <child link="pillar_base_link"/>
    <!-- Origin -->
    <origin rpy="0.0 0.0 0.0" xyz="0.0 0.0 0.0"/>
  </joint>
  <!-- ============================================== Include Macros =============================================== -->
  <!-- ================================================ Main Macros ================================================ -->
  <!-- ============================================== Support Macros =============================================== -->
  <!-- ================================================ Main Macros ================================================ -->
  <!-- ============================================== Support Macros =============================================== -->
  <!-- ================================================ Main Macros ================================================ -->
  <!-- ================================================ Main Macros ================================================ -->
  <!-- ============================================== Support Macros =============================================== -->
  <!-- ================================================ Main Macros ================================================ -->
  <!-- ================================================ Main Macros ================================================ -->
  <!-- ================================================ Main Macros ================================================ -->
  <!-- ============================================== Support Macros =============================================== -->
  <link name="yumi_base_link">
    <visual>
      <!-- Origin -->
      <origin rpy="0.0 0.0 0.0" xyz="0.0 0.0 0.0"/>
      <geometry>
        <mesh filename="package://abb_mp_irb14000_description/meshes/irb14000_05_50/visual/base_link.stl"/>
      </geometry>
      <material name="light_grey">
        <color rgba="0.6 0.6 0.6 1.0"/>
      </material>
    </visual>
    <collision>
      <!-- Origin -->
      <origin rpy="0.0 0.0 0.0" xyz="0.0 0.0 0.0"/>
      <geometry>
        <mesh filename="package://abb_mp_irb14000_description/meshes/irb14000_05_50/collision/base_link.stl"/>
      </geometry>
    </collision>
    <inertial>
      <!-- Origin -->
      <origin rpy="0.0 0.0 0.0" xyz="0.0 0.0 0.0"/>
      <!-- Mass -->
      <mass value="1.095"/>
      <inertia ixx="0.00088" ixy="0.0" ixz="0.0" iyy="0.00177" iyz="0.0" izz="0.00177"/>
    </inertial>
  </link>
  <link name="yumi_base">
    <inertial>
      <!-- Mass -->
      <mass value="1.0e-5"/>
      <!-- Inertia -->
      <inertia ixx="1.0e-6" ixy="0.0" ixz="0.0" iyy="1.0e-6" iyz="0.0" izz="1.0e-6"/>
    </inertial>
  </link>
  <link name="yumi_robl_base_link">
    <inertial>
      <!-- Mass -->
      <mass value="1.0e-5"/>
      <!-- Inertia -->
      <inertia ixx="1.0e-6" ixy="0.0" ixz="0.0" iyy="1.0e-6" iyz="0.0" izz="1.0e-6"/>
    </inertial>
  </link>
  <link name="yumi_robl_link_1">
    <visual>
      <!-- Origin -->
      <origin rpy="0.0 0.0 0.0" xyz="0.0 0.0 0.0"/>
      <geometry>
        <mesh filename="package://abb_mp_irb14000_description/meshes/irb14000_05_50/visual/robl_link_1.stl"/>
      </geometry>
      <material name="light_grey">
        <color rgba="0.6 0.6 0.6 1.0"/>
      </material>
    </visual>
    <collision>
      <!-- Origin -->
      <origin rpy="0.0 0.0 0.0" xyz="0.0 0.0 0.0"/>
      <geometry>
        <mesh filename="package://abb_mp_irb14000_description/meshes/irb14000_05_50/collision/robl_link_1.stl"/>
      </geometry>
    </collision>
    <inertial>
      <!-- Origin -->
      <origin rpy="0.0 0.0 0.0" xyz="-0.01468 -0.00021 0.06646"/>
      <!-- Mass -->
      <mass value="1.753"/>
      <inertia ixx="-0.002132958402100001" ixy="0.0001064041484" ixz="-0.0028402842984" iyy="-0.002670656802000002" iyz="-0.0002044659198" izz="0.0025121469855"/>
    </inertial>
  </link>
  <link name="yumi_robl_link_2">
    <visual>
      <!-- Origin -->
      <origin rpy="0.0 0.0 0.0" xyz="0.0 0.0 0.0"/>
      <geometry>
        <mesh filename="package://abb_mp_irb14000_description/meshes/irb14000_05_50/visual/robl_link_2.stl"/>
      </geometry>
      <material name="light_grey">
        <color rgba="0.6 0.6 0.6 1.0"/>
      </material>
    </visual>
    <collision>
      <!-- Origin -->
      <origin rpy="0.0 0.0 0.0" xyz="0.0 0.0 0.0"/>
      <geometry>
        <mesh filename="package://abb_mp_irb14000_description/meshes/irb14000_05_50/collision/robl_link_2.stl"/>
      </geometry>
    </collision>
    <inertial>
      <!-- Origin -->
      <origin rpy="0.0 0.0 0.0" xyz="0.01828 -0.0177 0.06202"/>
      <!-- Mass -->
      <mass value="1.444"/>
      <inertia ixx="0.001423291542400001" ixy="-0.000108214864" ixz="0.0026970997664" iyy="0.001143157572800001" iyz="-0.000155156776" izz="0.0013150845104"/>
    </inertial>
  </link>
  <!--xacro:link_tag name="robl_link_3"/>
	  <xacro:link_tag name="robl_link_4"/>
	  <xacro:link_tag name="robl_link_5"/>
	  <xacro:link_tag name="robl_link_6"/>
	  <xacro:link_tag name="robl_link_7"/>
	  <xacro:link_tag name="robl_flange"/>
	  <xacro:link_tag name="robl_tool0"/-->
  <link name="yumi_robr_base_link">
    <inertial>
      <!-- Mass -->
      <mass value="1.0e-5"/>
      <!-- Inertia -->
      <inertia ixx="1.0e-6" ixy="0.0" ixz="0.0" iyy="1.0e-6" iyz="0.0" izz="1.0e-6"/>
    </inertial>
  </link>
  <link name="yumi_robr_link_1">
    <visual>
      <!-- Origin -->
      <origin rpy="0.0 0.0 0.0" xyz="0.0 0.0 0.0"/>
      <geometry>
        <mesh filename="package://abb_mp_irb14000_description/meshes/irb14000_05_50/visual/robr_link_1.stl"/>
      </geometry>
      <material name="light_grey">
        <color rgba="0.6 0.6 0.6 1.0"/>
      </material>
    </visual>
    <collision>
      <!-- Origin -->
      <origin rpy="0.0 0.0 0.0" xyz="0.0 0.0 0.0"/>
      <geometry>
        <mesh filename="package://abb_mp_irb14000_description/meshes/irb14000_05_50/collision/robr_link_1.stl"/>
      </geometry>
    </collision>
    <inertial>
      <!-- Origin -->
      <origin rpy="0.0 0.0 0.0" xyz="-0.01468 -0.00021 0.06646"/>
      <!-- Mass -->
      <mass value="1.753"/>
      <inertia ixx="-0.002133" ixy="0.0001064" ixz="-0.0028403" iyy="-0.0026707" iyz="-0.00020447" izz="0.0025121"/>
    </inertial>
  </link>
  <link name="yumi_robr_link_2">
    <visual>
      <!-- Origin -->
      <origin rpy="0.0 0.0 0.0" xyz="0.0 0.0 0.0"/>
      <geometry>
        <mesh filename="package://abb_mp_irb14000_description/meshes/irb14000_05_50/visual/robr_link_2.stl"/>
      </geometry>
      <material name="light_grey">
        <color rgba="0.6 0.6 0.6 1.0"/>
      </material>
    </visual>
    <collision>
      <!-- Origin -->
      <origin rpy="0.0 0.0 0.0" xyz="0.0 0.0 0.0"/>
      <geometry>
        <mesh filename="package://abb_mp_irb14000_description/meshes/irb14000_05_50/collision/robr_link_2.stl"/>
      </geometry>
    </collision>
    <inertial>
      <!-- Origin -->
      <origin rpy="0.0 0.0 0.0" xyz="0.01828 -0.0177 0.06202"/>
      <!-- Mass -->
      <mass value="1.444"/>
      <inertia ixx="0.0014233" ixy="-0.00010821" ixz="0.0026971" iyy="0.0011432" iyz="-0.00015516" izz="0.0013151"/>
    </inertial>
  </link>
  <link name="yumi_robr_link_3">
    <visual>
      <!-- Origin -->
      <origin rpy="0.0 0.0 0.0" xyz="0.0 0.0 0.0"/>
      <geometry>
        <mesh filename="package://abb_mp_irb14000_description/meshes/irb14000_05_50/visual/robr_link_3.stl"/>
      </geometry>
      <material name="light_grey">
        <color rgba="0.6 0.6 0.6 1.0"/>
      </material>
    </visual>
    <collision>
      <!-- Origin -->
      <origin rpy="0.0 0.0 0.0" xyz="0.0 0.0 0.0"/>
      <geometry>
        <mesh filename="package://abb_mp_irb14000_description/meshes/irb14000_05_50/collision/robr_link_3.stl"/>
      </geometry>
    </collision>
    <inertial>
      <!-- Origin -->
      <origin rpy="0.0 0.0 0.0" xyz="0.02349 0.00556 0.05944"/>
      <!-- Mass -->
      <mass value="0.936"/>
      <inertia ixx="-0.00082593e2" ixy="0.00012488" ixz="0.0019949" iyy="-0.0014135e2" iyz="0.00039834" izz="0.0008846e2"/>
    </inertial>
  </link>
  <!--xacro:link_tag name="robr_link_4"/>
	  <xacro:link_tag name="robr_link_5"/>
	  <xacro:link_tag name="robr_link_6"/>
	  <xacro:link_tag name="robr_link_7"/>
	  <xacro:link_tag name="robr_flange"/>
	  <xacro:link_tag name="robr_tool0"/-->
  <joint name="yumi_base_joint" type="fixed">
    <!-- Parent and child -->
    <parent link="yumi_base_link"/>
    <child link="yumi_base"/>
    <!-- Origin -->
    <origin rpy="0.0 0.0 0.0" xyz="0.0 0.0 0.0"/>
  </joint>
  <joint name="yumi_robl_base_joint" type="fixed">
    <!-- Parent and child -->
    <parent link="yumi_base_link"/>
    <child link="yumi_robl_base_link"/>
    <!-- Origin -->
    <origin rpy="-0.979574289414893 0.569499575052463 -0.8258330548971096" xyz="0.047607 0.070008 0.411486"/>
  </joint>
  <joint name="yumi_robl_joint_1" type="revolute">
    <!-- Parent and child -->
    <parent link="yumi_robl_base_link"/>
    <child link="yumi_robl_link_1"/>
    <!-- Origin -->
    <origin rpy="0.0 0.0 0.0" xyz="0.0 0.0 0.0"/>
    <axis xyz="0 0 1"/>
    <limit effort="100.0" lower="-2.9408797896104453" upper="2.9408797896104453" velocity="3.141592653589793"/>
    <dynamics damping="0.0" friction="0.0"/>
  </joint>
  <joint name="yumi_robl_joint_2" type="revolute">
    <!-- Parent and child -->
    <parent link="yumi_robl_link_1"/>
    <child link="yumi_robl_link_2"/>
    <!-- Origin -->
    <origin rpy="0.0 0.0 0.0" xyz="-0.03 0.0 0.1075"/>
    <axis xyz="0 1 0"/>
    <limit effort="100.0" lower="-2.504547476611863" upper="0.7592182246175333" velocity="3.141592653589793"/>
    <dynamics damping="0.0" friction="0.0"/>
  </joint>
  <!--xacro:joint_tag name="robl_joint_3"        parent="robl_link_2"    child="robl_link_3"/>
    <xacro:joint_tag name="robl_joint_4"        parent="robl_link_3"    child="robl_link_4"/>
    <xacro:joint_tag name="robl_joint_5"        parent="robl_link_4"    child="robl_link_5"/>
    <xacro:joint_tag name="robl_joint_6"        parent="robl_link_5"    child="robl_link_6"/>
    <xacro:joint_tag name="robl_joint_7"        parent="robl_link_6"    child="robl_link_7"/>
    <xacro:joint_tag name="robl_joint_7_flange" parent="robl_link_7"    child="robl_flange"/>
    <xacro:joint_tag name="robl_flange_tool0"   parent="robl_flange"    child="robl_tool0"/-->
  <joint name="yumi_robr_base_joint" type="fixed">
    <!-- Parent and child -->
    <parent link="yumi_base_link"/>
    <child link="yumi_robr_base_link"/>
    <!-- Origin -->
    <origin rpy="0.979574289414893 0.569499575052463 0.8258330548971096" xyz="0.047607 -0.070008 0.411486"/>
  </joint>
  <joint name="yumi_robr_joint_1" type="revolute">
    <!-- Parent and child -->
    <parent link="yumi_robr_base_link"/>
    <child link="yumi_robr_link_1"/>
    <!-- Origin -->
    <origin rpy="0.0 0.0 0.0" xyz="0.0 0.0 0.0"/>
    <axis xyz="0 0 1"/>
    <limit effort="100.0" lower="-2.9408797896104453" upper="2.9408797896104453" velocity="3.141592653589793"/>
    <dynamics damping="0.0" friction="0.0"/>
  </joint>
  <joint name="yumi_robr_joint_2" type="revolute">
    <!-- Parent and child -->
    <parent link="yumi_robr_link_1"/>
    <child link="yumi_robr_link_2"/>
    <!-- Origin -->
    <origin rpy="0.0 0.0 0.0" xyz="-0.03 0.0 0.1075"/>
    <axis xyz="0 1 0"/>
    <limit effort="100.0" lower="-2.504547476611863" upper="0.7592182246175333" velocity="3.141592653589793"/>
    <dynamics damping="0.0" friction="0.0"/>
  </joint>
  <joint name="yumi_robr_joint_3" type="revolute">
    <!-- Parent and child -->
    <parent link="yumi_robr_link_2"/>
    <child link="yumi_robr_link_3"/>
    <!-- Origin -->
    <origin rpy="0.0 0.0 0.0" xyz="0.03 0.0 0.1603"/>
    <axis xyz="0 0 1"/>
    <limit effort="100.0" lower="-2.9408797896104453" upper="2.9408797896104453" velocity="3.141592653589793"/>
    <dynamics damping="1.0" friction="0.0"/>
  </joint>
  <!--xacro:joint_tag name="robr_joint_4"        parent="robr_link_3"    child="robr_link_4"/>
    <xacro:joint_tag name="robr_joint_5"        parent="robr_link_4"    child="robr_link_5"/>
    <xacro:joint_tag name="robr_joint_6"        parent="robr_link_5"    child="robr_link_6"/>
    <xacro:joint_tag name="robr_joint_7"        parent="robr_link_6"    child="robr_link_7"/>
    <xacro:joint_tag name="robr_joint_7_flange" parent="robr_link_7"    child="robr_flange"/>
    <xacro:joint_tag name="robr_flange_tool0"   parent="robr_flange"    child="robr_tool0"/-->
  <transmission name="yumi_robl_transmission_1">
    <type>transmission_interface/SimpleTransmission</type>
    <joint name="yumi_robl_joint_1">
      <hardwareInterface>hardware_interface/EffortJointInterface</hardwareInterface>
    </joint>
    <actuator name="yumi_robl_joint_1_motor">
      <mechanicalReduction>1.0</mechanicalReduction>
    </actuator>
  </transmission>
  <transmission name="yumi_robl_transmission_2">
    <type>transmission_interface/SimpleTransmission</type>
    <joint name="yumi_robl_joint_2">
      <hardwareInterface>hardware_interface/EffortJointInterface</hardwareInterface>
    </joint>
    <actuator name="yumi_robl_joint_2_motor">
      <mechanicalReduction>1.0</mechanicalReduction>
    </actuator>
  </transmission>
  <!--xacro:transmission_tag name="robl_transmission_3" joint="robl_joint_3"/>
    <xacro:transmission_tag name="robl_transmission_4" joint="robl_joint_4"/>
    <xacro:transmission_tag name="robl_transmission_5" joint="robl_joint_5"/>
    <xacro:transmission_tag name="robl_transmission_6" joint="robl_joint_6"/>
    <xacro:transmission_tag name="robl_transmission_7" joint="robl_joint_7"/-->
  <transmission name="yumi_robr_transmission_1">
    <type>transmission_interface/SimpleTransmission</type>
    <joint name="yumi_robr_joint_1">
      <hardwareInterface>hardware_interface/EffortJointInterface</hardwareInterface>
    </joint>
    <actuator name="yumi_robr_joint_1_motor">
      <mechanicalReduction>1.0</mechanicalReduction>
    </actuator>
  </transmission>
  <transmission name="yumi_robr_transmission_2">
    <type>transmission_interface/SimpleTransmission</type>
    <joint name="yumi_robr_joint_2">
      <hardwareInterface>hardware_interface/EffortJointInterface</hardwareInterface>
    </joint>
    <actuator name="yumi_robr_joint_2_motor">
      <mechanicalReduction>1.0</mechanicalReduction>
    </actuator>
  </transmission>
  <transmission name="yumi_robr_transmission_3">
    <type>transmission_interface/SimpleTransmission</type>
    <joint name="yumi_robr_joint_3">
      <hardwareInterface>hardware_interface/EffortJointInterface</hardwareInterface>
    </joint>
    <actuator name="yumi_robr_joint_3_motor">
      <mechanicalReduction>1.0</mechanicalReduction>
    </actuator>
  </transmission>
  <!--xacro:transmission_tag name="robr_transmission_4" joint="robr_joint_4"/>
    <xacro:transmission_tag name="robr_transmission_5" joint="robr_joint_5"/>
    <xacro:transmission_tag name="robr_transmission_6" joint="robr_joint_6"/>
    <xacro:transmission_tag name="robr_transmission_7" joint="robr_joint_7"/-->
  <gazebo reference="yumi_base_link">
    <material>Gazebo/White</material>
    <turnGravityOff>False</turnGravityOff>
  </gazebo>
  <gazebo reference="yumi_robl_link_1">
    <mu1 value="1.0"/>
    <mu2 value="1"/>
    <kp value="10000000.0"/>
    <kd value="1000.0"/>
    <fdir1 value="1 0 0"/>
    <turnGravityOff>False</turnGravityOff>
  </gazebo>
  <gazebo reference="yumi_robl_link_2">
    <mu1 value="1.0"/>
    <mu2 value="1"/>
    <kp value="10000000.0"/>
    <kd value="1000.0"/>
    <fdir1 value="1 0 0"/>
    <turnGravityOff>False</turnGravityOff>
  </gazebo>
  <!--xacro:gazebo_link_tag link="robl_link_3"/>
    <xacro:gazebo_link_tag link="robl_link_4"/>
    <xacro:gazebo_link_tag link="robl_link_5"/>
    <xacro:gazebo_link_tag link="robl_link_6"/>
    <xacro:gazebo_link_tag link="robl_link_7"/-->
  <gazebo reference="yumi_robr_link_1">
    <mu1 value="1.0"/>
    <mu2 value="1"/>
    <kp value="10000000.0"/>
    <kd value="1000.0"/>
    <fdir1 value="1 0 0"/>
    <turnGravityOff>False</turnGravityOff>
  </gazebo>
  <gazebo reference="yumi_robr_link_2">
    <mu1 value="1.0"/>
    <mu2 value="1"/>
    <kp value="10000000.0"/>
    <kd value="1000.0"/>
    <fdir1 value="1 0 0"/>
    <turnGravityOff>False</turnGravityOff>
  </gazebo>
  <gazebo reference="yumi_robr_link_3">
    <mu1 value="1.0"/>
    <mu2 value="1"/>
    <kp value="10000000.0"/>
    <kd value="1000.0"/>
    <fdir1 value="1 0 0"/>
    <turnGravityOff>False</turnGravityOff>
  </gazebo>
  <!--xacro:gazebo_link_tag link="robr_link_4"/>
    <xacro:gazebo_link_tag link="robr_link_5"/>
    <xacro:gazebo_link_tag link="robr_link_6"/>
    <xacro:gazebo_link_tag link="robr_link_7"/-->
  <joint name="pillar_yumi_joint" type="fixed">
    <!-- Parent and child -->
    <parent link="pillar_top_link"/>
    <child link="yumi_base_link"/>
    <!-- Origin -->
    <origin rpy="0.0 0.0 0.0" xyz="0.234995 0.0 -0.108"/>
  </joint>
  <!-- SmartGrippers -->
  <!--xacro:abb_sg prefix="${prefix}yumi_robl_sg_"/>
    <xacro:abb_sg prefix="${prefix}yumi_robr_sg_"/>
    <xacro:joint_tag name="yumi_robl_sg_joint" parent="yumi_robl_tool0" child="yumi_robl_sg_base_link"/>
    <xacro:joint_tag name="yumi_robr_sg_joint" parent="yumi_robr_tool0" child="yumi_robr_sg_base_link"/-->
  <!-- ============================================== Include Macros =============================================== -->
  <!-- ================================================ Main Macros ================================================ -->
  <!-- ============================================== Support Macros =============================================== -->
  <!-- ================================================ Main Macros ================================================ -->
  <!-- ============================================== Support Macros =============================================== -->
  <!-- ================================================ Main Macros ================================================ -->
  <!-- ================================================ Main Macros ================================================ -->
  <!-- ============================================== Support Macros =============================================== -->
  <!-- ================================================ Main Macros ================================================ -->
  <!-- ================================================ Main Macros ================================================ -->
  <!-- ================================================ Main Macros ================================================ -->
  <!-- ============================================== Support Macros =============================================== -->
  <link name="yumi_cs_base_link">
    <visual>
      <!-- Origin -->
      <origin rpy="0.0 0.0 0.0" xyz="0.0 0.0 0.0"/>
      <geometry>
        <mesh filename="package://abb_mp_camera_stand_description/meshes/cs_v2/visual/base_link.stl"/>
      </geometry>
      <material name="light_grey">
        <color rgba="0.6 0.6 0.6 1.0"/>
      </material>
    </visual>
    <collision>
      <!-- Origin -->
      <origin rpy="0.0 0.0 0.0" xyz="0.0 0.0 0.0"/>
      <geometry>
        <mesh filename="package://abb_mp_camera_stand_description/meshes/cs_v2/collision/base_link.stl"/>
      </geometry>
    </collision>
    <inertial>
      <!-- Origin -->
      <origin rpy="0.0 0.0 0.0" xyz="0.0 0.0 0.0"/>
      <!-- Mass -->
      <mass value="1e-05"/>
      <inertia ixx="1e-06" ixy="0.0" ixz="0.0" iyy="1e-06" iyz="0.0" izz="1e-06"/>
    </inertial>
  </link>
  <link name="yumi_cs_plate_link">
    <visual>
      <!-- Origin -->
      <origin rpy="0.0 0.0 0.0" xyz="0.0 0.0 0.0"/>
      <geometry>
        <mesh filename="package://abb_mp_camera_stand_description/meshes/cs_v2/visual/plate_link.stl"/>
      </geometry>
      <material name="dark_grey">
        <color rgba="0.3 0.3 0.3 1.0"/>
      </material>
    </visual>
    <collision>
      <!-- Origin -->
      <origin rpy="0.0 0.0 0.0" xyz="0.0 0.0 0.0"/>
      <geometry>
        <mesh filename="package://abb_mp_camera_stand_description/meshes/cs_v2/collision/plate_link.stl"/>
      </geometry>
    </collision>
    <inertial>
      <!-- Origin -->
      <origin rpy="0.0 0.0 0.0" xyz="0.0 0.0 0.0"/>
      <!-- Mass -->
      <mass value="1e-05"/>
      <inertia ixx="1e-06" ixy="0.0" ixz="0.0" iyy="1e-06" iyz="0.0" izz="1e-06"/>
    </inertial>
  </link>
  <link name="yumi_cs_attachment_link">
    <inertial>
      <!-- Mass -->
      <mass value="1.0e-5"/>
      <!-- Inertia -->
      <inertia ixx="1.0e-6" ixy="0.0" ixz="0.0" iyy="1.0e-6" iyz="0.0" izz="1.0e-6"/>
    </inertial>
  </link>
  <joint name="yumi_cs_plate_joint" type="fixed">
    <!-- Parent and child -->
    <parent link="yumi_cs_base_link"/>
    <child link="yumi_cs_plate_link"/>
    <!-- Origin -->
    <origin rpy="0.0 0.5585053606381855 0.0" xyz="0.14935 0.0 0.17194"/>
  </joint>
  <joint name="yumi_cs_attachment_joint" type="fixed">
    <!-- Parent and child -->
    <parent link="yumi_cs_plate_link"/>
    <child link="yumi_cs_attachment_link"/>
    <!-- Origin -->
    <origin rpy="0.0 0.0 0.0" xyz="0.015 0.0 -0.0125"/>
  </joint>
  <gazebo reference="yumi_cs_base_link">
    <material>Gazebo/White</material>
  </gazebo>
  <gazebo reference="yumi_cs_plate_link">
    <material>Gazebo/Grey</material>
  </gazebo>
  <joint name="yumi_cs_joint" type="fixed">
    <!-- Parent and child -->
    <parent link="yumi_base_link"/>
    <child link="yumi_cs_base_link"/>
    <!-- Origin -->
    <origin rpy="0.0 0.0 0.0" xyz="-0.09 0.0 0.469"/>
  </joint>
  <link name="camera_body">
    <visual>
      <origin xyz="0. 0. 0."/>
      <geometry>
        <box size="0.0994 0.0996 0.023"/>
      </geometry>
      <material name="white">
        <color rgba="0.9 0.9 0.9 1"/>
      </material>
    </visual>
    <collision>
      <origin xyz="0. 0. 0."/>
      <geometry>
        <box size="0.0994 0.0996 0.023"/>
      </geometry>
    </collision>
  </link>
  <link name="camera_base">
    <visual>
      <origin xyz="-0.013 0. 0."/>
      <geometry>
        <box size="0.026 0.103 0.039"/>
      </geometry>
      <material name="grey">
        <color rgba="0.6 0.6 0.6 1"/>
      </material>
    </visual>
    <collision>
      <origin xyz="-0.013 0. 0."/>
      <geometry>
        <box size="0.026 0.103 0.039"/>
      </geometry>
    </collision>
  </link>
  <link name="camera_visor">
    <visual>
      <origin xyz="-0.0128 0. 0."/>
      <geometry>
        <box size="0.026 0.101 0.037"/>
      </geometry>
      <material name="black">
        <color rgba="0. 0. 0. 1"/>
      </material>
    </visual>
    <collision>
      <origin xyz="-0.0128 0. 0."/>
      <geometry>
        <box size="0.026 0.101 0.037"/>
      </geometry>
    </collision>
  </link>
  <joint name="camera_base_to_body" type="fixed">
    <parent link="camera_base"/>
    <child link="camera_body"/>
    <origin rpy="0. 0. 0." xyz="-0.0757 0. 0.008"/>
  </joint>
  <joint name="camera_base_to_visor" type="fixed">
    <parent link="camera_base"/>
    <child link="camera_visor"/>
    <origin rpy="0. 0. 0." xyz="0. 0. 0."/>
  </joint>
  <gazebo reference="camera_visor">
    <material>Gazebo/Black</material>
  </gazebo>
  <joint name="cs_camera_joint" type="fixed">
    <!-- Parent and child -->
    <parent link="yumi_cs_attachment_link"/>
    <child link="camera_base"/>
    <!-- Origin -->
    <origin rpy="0.0 0.0 0.0" xyz="0.03 0.0 0.03"/>
  </joint>
  <!-- Gazebo plugin for ROS Control -->
  <gazebo>
    <plugin filename="libgazebo_ros_control.so" name="gazebo_ros_control">
      <robotSimType>gazebo_ros_control/DefaultRobotHWSim</robotSimType>
      <legacyModeNS>true</legacyModeNS>
    </plugin>
    <plugin filename="libgazebo_ros_p3d.so" name="p3d_base_controller">
      <alwaysOn>true</alwaysOn>
      <updateRate>50.0</updateRate>
      <bodyName>base_link</bodyName>
      <topicName>odom</topicName>
      <gaussianNoise>0.001</gaussianNoise>
      <frameName>world</frameName>
      <xyzOffsets>0 0 0</xyzOffsets>
      <rpyOffsets>0 0 0</rpyOffsets>
      <robotNamespace>/</robotNamespace>
    </plugin>
  </gazebo>
</robot>

