<?xml version="1.0" ?>
<!-- =================================================================================== -->
<!-- |    This document was autogenerated by xacro from myumi_v2.xacro                 | -->
<!-- |    EDITING THIS FILE BY HAND IS NOT RECOMMENDED                                 | -->
<!-- =================================================================================== -->
<robot name="abb_myumi_v2">
  <!-- ============================================== Include Macros =============================================== -->
  <!-- ================================================ Main Macros ================================================ -->
  <!-- ============================================== Support Macros =============================================== -->
  <!-- ================================================ Main Macros ================================================ -->
  <!-- ============================================== Support Macros =============================================== -->
  <!-- ================================================ Main Macros ================================================ -->
  <!-- ================================================ Main Macros ================================================ -->
  <!-- ============================================== Support Macros =============================================== -->
  <!-- ================================================ Main Macros ================================================ -->
  <!-- ================================================ Main Macros ================================================ -->
  <!-- ================================================ Main Macros ================================================ -->
  <!-- ============================================== Support Macros =============================================== -->
  <!--xacro:include filename="$(find abb_mp_irb14000_description)/urdf/irb14000_05_50_macro.xacro"/>
    <xacro:include filename="$(find abb_mp_smart_gripper_description)/urdf/sg_macro.xacro"/>
    <xacro:include filename="$(find abb_mp_camera_stand_description)/urdf/cs_v2_macro.xacro"/>
    <xacro:include filename="$(find abb_mp_camera_description)/urdf/azure_kinect_macro.xacro"/-->
  <link name="base_link">
    <inertial>
      <!-- Mass -->
      <mass value="1.0e-5"/>
      <!-- Inertia -->
      <inertia ixx="1.0e-6" ixy="0.0" ixz="0.0" iyy="1.0e-6" iyz="0.0" izz="1.0e-6"/>
    </inertial>
  </link>
  <link name="chassis_link">
    <visual>
      <!-- Origin -->
      <origin rpy="0.0 0.0 0.0" xyz="0.0 0.0 0.0"/>
      <geometry>
        <mesh filename="package://abb_mp_myumi_description/meshes/myumi_v2/visual/chassis_link.stl"/>
      </geometry>
      <material name="light_grey">
        <color rgba="0.6 0.6 0.6 1.0"/>
      </material>
    </visual>
    <collision>
      <!-- Origin -->
      <origin rpy="0.0 0.0 0.0" xyz="0.0 0.0 0.0"/>
      <geometry>
        <mesh filename="package://abb_mp_myumi_description/meshes/myumi_v2/collision/chassis_link.stl"/>
      </geometry>
    </collision>
    <inertial>
      <!-- Origin -->
      <origin rpy="0.0 0.0 0.0" xyz="0.0 0.0 0.0"/>
      <!-- Mass -->
      <mass value="46.23"/>
      <inertia ixx="0.44" ixy="0.0" ixz="0.0" iyy="0.45" iyz="0.0" izz="0.66"/>
    </inertial>
  </link>
  <!--xacro:link_tag name="front_radar_link"/>
	  <xacro:link_tag name="front_laser_scanner_link"/>
	  <xacro:link_tag name="rear_laser_scanner_link"/-->
  <joint name="chassis_joint" type="fixed">
    <!-- Parent and child -->
    <parent link="base_link"/>
    <child link="chassis_link"/>
    <!-- Origin -->
    <origin rpy="0.0 0.0 0.0" xyz="0.0 0.0 0.0292"/>
  </joint>
  <!--xacro:joint_tag name="front_radar_joint"         parent="chassis_link" child="front_radar_link"/>
    <xacro:joint_tag name="front_laser_scanner_joint" parent="chassis_link" child="front_laser_scanner_link"/>
    <xacro:joint_tag name="rear_laser_scanner_joint"  parent="chassis_link" child="rear_laser_scanner_link"/-->
  <!--link name="world"/>

  <joint name="fixed" type="fixed">
    <parent link="world"/>
    <child link="base_link"/>
  </joint-->
  <gazebo reference="chassis_link">
    <material>Gazebo/White</material>
  </gazebo>
  <!-- ================ Subcomponents ================ -->
  <!-- ============================================== Include Macros =============================================== -->
  <!-- ================================================ Main Macros ================================================ -->
  <!-- ============================================== Support Macros =============================================== -->
  <!-- ================================================ Main Macros ================================================ -->
  <!-- ============================================== Support Macros =============================================== -->
  <!-- ================================================ Main Macros ================================================ -->
  <!-- ================================================ Main Macros ================================================ -->
  <!-- ============================================== Support Macros =============================================== -->
  <!-- ================================================ Main Macros ================================================ -->
  <!-- ================================================ Main Macros ================================================ -->
  <!-- ================================================ Main Macros ================================================ -->
  <!-- ============================================== Support Macros =============================================== -->
  <link name="front_left_base_link">
    <inertial>
      <!-- Mass -->
      <mass value="1.0e-5"/>
      <!-- Inertia -->
      <inertia ixx="1.0e-6" ixy="0.0" ixz="0.0" iyy="1.0e-6" iyz="0.0" izz="1.0e-6"/>
    </inertial>
  </link>
  <link name="front_left_steering_link">
    <visual>
      <!-- Origin -->
      <origin rpy="0.0 0.0 0.0" xyz="0.0 0.0 0.0"/>
      <geometry>
        <mesh filename="package://abb_mp_steerable_wheel_description/meshes/sw_v3/visual/steering_link.stl"/>
      </geometry>
      <material name="light_grey">
        <color rgba="0.6 0.6 0.6 1.0"/>
      </material>
    </visual>
    <collision>
      <!-- Origin -->
      <origin rpy="0.0 0.0 0.0" xyz="0.0 0.0 0.0"/>
      <geometry>
        <mesh filename="package://abb_mp_steerable_wheel_description/meshes/sw_v3/collision/steering_link.stl"/>
      </geometry>
    </collision>
    <inertial>
      <!-- Origin -->
      <origin rpy="0.0 1.0000736613927508 0.0" xyz="0.0 0.0 0.0"/>
      <!-- Mass -->
      <mass value="2.6"/>
      <inertia ixx="0.0018" ixy="0.0" ixz="0.0" iyy="0.0017" iyz="-0.0004" izz="0.0013"/>
    </inertial>
  </link>
  <link name="front_left_drive_wheel_link">
    <visual>
      <!-- Origin -->
      <origin rpy="0.0 0.0 0.0" xyz="0.0 0.0 0.0"/>
      <geometry>
        <mesh filename="package://abb_mp_steerable_wheel_description/meshes/sw_v3/visual/drive_wheel_link.stl"/>
      </geometry>
      <material name="dark_grey">
        <color rgba="0.3 0.3 0.3 1.0"/>
      </material>
    </visual>
    <collision>
      <!-- Origin -->
      <origin rpy="1.5707963267948966 0.0 0.0" xyz="0.0 0.0 0.0"/>
      <geometry>
        <cylinder length="0.047" radius="0.0865"/>
      </geometry>
    </collision>
    <inertial>
      <!-- Origin -->
      <origin rpy="0.0 0.0 0.0" xyz="0.0 0.0 0.0"/>
      <!-- Mass -->
      <mass value="1.31"/>
      <inertia ixx="0.0018" ixy="0.0" ixz="0.0" iyy="0.0017" iyz="0.0" izz="0.0013"/>
    </inertial>
  </link>
  <joint name="front_left_steering_joint" type="revolute">
    <!-- Parent and child -->
    <parent link="front_left_base_link"/>
    <child link="front_left_steering_link"/>
    <!-- Origin -->
    <origin rpy="0.0 0.0 0.0" xyz="0.0 0.0 0.0"/>
    <axis xyz="0.0 0.0 1.0"/>
    <limit effort="1000.0" lower="-3.141592653589793" upper="3.141592653589793" velocity="62.83185307179586"/>
    <dynamics damping="0.0" friction="0.0"/>
  </joint>
  <joint name="front_left_drive_wheel_joint" type="continuous">
    <!-- Parent and child -->
    <parent link="front_left_steering_link"/>
    <child link="front_left_drive_wheel_link"/>
    <!-- Origin -->
    <origin rpy="0.0 0.0 0.0" xyz="0.0 0.0 -0.0925"/>
    <axis xyz="0.0 1.0 0.0"/>
  </joint>
  <transmission name="front_left_steering_transmission">
    <type>transmission_interface/SimpleTransmission</type>
    <joint name="front_left_steering_joint">
      <hardwareInterface>hardware_interface/PositionJointInterface</hardwareInterface>
    </joint>
    <actuator name="front_left_steering_joint_motor">
      <mechanicalReduction>1.0</mechanicalReduction>
    </actuator>
  </transmission>
  <transmission name="front_left_drive_wheel_transmission">
    <type>transmission_interface/SimpleTransmission</type>
    <joint name="front_left_drive_wheel_joint">
      <hardwareInterface>hardware_interface/VelocityJointInterface</hardwareInterface>
    </joint>
    <actuator name="front_left_drive_wheel_joint_motor">
      <mechanicalReduction>1.0</mechanicalReduction>
    </actuator>
  </transmission>
  <gazebo reference="front_left_steering_link">
    <material>Gazebo/White</material>
  </gazebo>
  <gazebo reference="front_left_drive_wheel_link">
    <material>Gazebo/Grey</material>
    <mu1 value="1.0"/>
    <mu2 value="1.0"/>
    <kp value="1000000.0"/>
    <kd value="1000.0"/>
    <fdir1 value="1.0 0.0 0.0"/>
  </gazebo>
  <!-- ============================================== Include Macros =============================================== -->
  <!-- ================================================ Main Macros ================================================ -->
  <!-- ============================================== Support Macros =============================================== -->
  <!-- ================================================ Main Macros ================================================ -->
  <!-- ============================================== Support Macros =============================================== -->
  <!-- ================================================ Main Macros ================================================ -->
  <!-- ================================================ Main Macros ================================================ -->
  <!-- ============================================== Support Macros =============================================== -->
  <!-- ================================================ Main Macros ================================================ -->
  <!-- ================================================ Main Macros ================================================ -->
  <!-- ================================================ Main Macros ================================================ -->
  <!-- ============================================== Support Macros =============================================== -->
  <link name="front_right_base_link">
    <inertial>
      <!-- Mass -->
      <mass value="1.0e-5"/>
      <!-- Inertia -->
      <inertia ixx="1.0e-6" ixy="0.0" ixz="0.0" iyy="1.0e-6" iyz="0.0" izz="1.0e-6"/>
    </inertial>
  </link>
  <link name="front_right_steering_link">
    <visual>
      <!-- Origin -->
      <origin rpy="0.0 0.0 0.0" xyz="0.0 0.0 0.0"/>
      <geometry>
        <mesh filename="package://abb_mp_steerable_wheel_description/meshes/sw_v3/visual/steering_link.stl"/>
      </geometry>
      <material name="light_grey">
        <color rgba="0.6 0.6 0.6 1.0"/>
      </material>
    </visual>
    <collision>
      <!-- Origin -->
      <origin rpy="0.0 0.0 0.0" xyz="0.0 0.0 0.0"/>
      <geometry>
        <mesh filename="package://abb_mp_steerable_wheel_description/meshes/sw_v3/collision/steering_link.stl"/>
      </geometry>
    </collision>
    <inertial>
      <!-- Origin -->
      <origin rpy="0.0 1.0000736613927508 0.0" xyz="0.0 0.0 0.0"/>
      <!-- Mass -->
      <mass value="2.6"/>
      <inertia ixx="0.0018" ixy="0.0" ixz="0.0" iyy="0.0017" iyz="-0.0004" izz="0.0013"/>
    </inertial>
  </link>
  <link name="front_right_drive_wheel_link">
    <visual>
      <!-- Origin -->
      <origin rpy="0.0 0.0 0.0" xyz="0.0 0.0 0.0"/>
      <geometry>
        <mesh filename="package://abb_mp_steerable_wheel_description/meshes/sw_v3/visual/drive_wheel_link.stl"/>
      </geometry>
      <material name="dark_grey">
        <color rgba="0.3 0.3 0.3 1.0"/>
      </material>
    </visual>
    <collision>
      <!-- Origin -->
      <origin rpy="1.5707963267948966 0.0 0.0" xyz="0.0 0.0 0.0"/>
      <geometry>
        <cylinder length="0.047" radius="0.0865"/>
      </geometry>
    </collision>
    <inertial>
      <!-- Origin -->
      <origin rpy="0.0 0.0 0.0" xyz="0.0 0.0 0.0"/>
      <!-- Mass -->
      <mass value="1.31"/>
      <inertia ixx="0.0018" ixy="0.0" ixz="0.0" iyy="0.0017" iyz="0.0" izz="0.0013"/>
    </inertial>
  </link>
  <joint name="front_right_steering_joint" type="revolute">
    <!-- Parent and child -->
    <parent link="front_right_base_link"/>
    <child link="front_right_steering_link"/>
    <!-- Origin -->
    <origin rpy="0.0 0.0 0.0" xyz="0.0 0.0 0.0"/>
    <axis xyz="0.0 0.0 1.0"/>
    <limit effort="1000.0" lower="-3.141592653589793" upper="3.141592653589793" velocity="62.83185307179586"/>
    <dynamics damping="0.0" friction="0.0"/>
  </joint>
  <joint name="front_right_drive_wheel_joint" type="continuous">
    <!-- Parent and child -->
    <parent link="front_right_steering_link"/>
    <child link="front_right_drive_wheel_link"/>
    <!-- Origin -->
    <origin rpy="0.0 0.0 0.0" xyz="0.0 0.0 -0.0925"/>
    <axis xyz="0.0 1.0 0.0"/>
  </joint>
  <transmission name="front_right_steering_transmission">
    <type>transmission_interface/SimpleTransmission</type>
    <joint name="front_right_steering_joint">
      <hardwareInterface>hardware_interface/PositionJointInterface</hardwareInterface>
    </joint>
    <actuator name="front_right_steering_joint_motor">
      <mechanicalReduction>1.0</mechanicalReduction>
    </actuator>
  </transmission>
  <transmission name="front_right_drive_wheel_transmission">
    <type>transmission_interface/SimpleTransmission</type>
    <joint name="front_right_drive_wheel_joint">
      <hardwareInterface>hardware_interface/VelocityJointInterface</hardwareInterface>
    </joint>
    <actuator name="front_right_drive_wheel_joint_motor">
      <mechanicalReduction>1.0</mechanicalReduction>
    </actuator>
  </transmission>
  <gazebo reference="front_right_steering_link">
    <material>Gazebo/White</material>
  </gazebo>
  <gazebo reference="front_right_drive_wheel_link">
    <material>Gazebo/Grey</material>
    <mu1 value="1.0"/>
    <mu2 value="1.0"/>
    <kp value="1000000.0"/>
    <kd value="1000.0"/>
    <fdir1 value="1.0 0.0 0.0"/>
  </gazebo>
  <!-- ============================================== Include Macros =============================================== -->
  <!-- ================================================ Main Macros ================================================ -->
  <!-- ============================================== Support Macros =============================================== -->
  <!-- ================================================ Main Macros ================================================ -->
  <!-- ============================================== Support Macros =============================================== -->
  <!-- ================================================ Main Macros ================================================ -->
  <!-- ================================================ Main Macros ================================================ -->
  <!-- ============================================== Support Macros =============================================== -->
  <!-- ================================================ Main Macros ================================================ -->
  <!-- ================================================ Main Macros ================================================ -->
  <!-- ================================================ Main Macros ================================================ -->
  <!-- ============================================== Support Macros =============================================== -->
  <link name="rear_right_base_link">
    <inertial>
      <!-- Mass -->
      <mass value="1.0e-5"/>
      <!-- Inertia -->
      <inertia ixx="1.0e-6" ixy="0.0" ixz="0.0" iyy="1.0e-6" iyz="0.0" izz="1.0e-6"/>
    </inertial>
  </link>
  <link name="rear_right_steering_link">
    <visual>
      <!-- Origin -->
      <origin rpy="0.0 0.0 0.0" xyz="0.0 0.0 0.0"/>
      <geometry>
        <mesh filename="package://abb_mp_steerable_wheel_description/meshes/sw_v3/visual/steering_link.stl"/>
      </geometry>
      <material name="light_grey">
        <color rgba="0.6 0.6 0.6 1.0"/>
      </material>
    </visual>
    <collision>
      <!-- Origin -->
      <origin rpy="0.0 0.0 0.0" xyz="0.0 0.0 0.0"/>
      <geometry>
        <mesh filename="package://abb_mp_steerable_wheel_description/meshes/sw_v3/collision/steering_link.stl"/>
      </geometry>
    </collision>
    <inertial>
      <!-- Origin -->
      <origin rpy="0.0 1.0000736613927508 0.0" xyz="0.0 0.0 0.0"/>
      <!-- Mass -->
      <mass value="2.6"/>
      <inertia ixx="0.0018" ixy="0.0" ixz="0.0" iyy="0.0017" iyz="-0.0004" izz="0.0013"/>
    </inertial>
  </link>
  <link name="rear_right_drive_wheel_link">
    <visual>
      <!-- Origin -->
      <origin rpy="0.0 0.0 0.0" xyz="0.0 0.0 0.0"/>
      <geometry>
        <mesh filename="package://abb_mp_steerable_wheel_description/meshes/sw_v3/visual/drive_wheel_link.stl"/>
      </geometry>
      <material name="dark_grey">
        <color rgba="0.3 0.3 0.3 1.0"/>
      </material>
    </visual>
    <collision>
      <!-- Origin -->
      <origin rpy="1.5707963267948966 0.0 0.0" xyz="0.0 0.0 0.0"/>
      <geometry>
        <cylinder length="0.047" radius="0.0865"/>
      </geometry>
    </collision>
    <inertial>
      <!-- Origin -->
      <origin rpy="0.0 0.0 0.0" xyz="0.0 0.0 0.0"/>
      <!-- Mass -->
      <mass value="1.31"/>
      <inertia ixx="0.0018" ixy="0.0" ixz="0.0" iyy="0.0017" iyz="0.0" izz="0.0013"/>
    </inertial>
  </link>
  <joint name="rear_right_steering_joint" type="revolute">
    <!-- Parent and child -->
    <parent link="rear_right_base_link"/>
    <child link="rear_right_steering_link"/>
    <!-- Origin -->
    <origin rpy="0.0 0.0 0.0" xyz="0.0 0.0 0.0"/>
    <axis xyz="0.0 0.0 1.0"/>
    <limit effort="1000.0" lower="-3.141592653589793" upper="3.141592653589793" velocity="62.83185307179586"/>
    <dynamics damping="0.0" friction="0.0"/>
  </joint>
  <joint name="rear_right_drive_wheel_joint" type="continuous">
    <!-- Parent and child -->
    <parent link="rear_right_steering_link"/>
    <child link="rear_right_drive_wheel_link"/>
    <!-- Origin -->
    <origin rpy="0.0 0.0 0.0" xyz="0.0 0.0 -0.0925"/>
    <axis xyz="0.0 1.0 0.0"/>
  </joint>
  <transmission name="rear_right_steering_transmission">
    <type>transmission_interface/SimpleTransmission</type>
    <joint name="rear_right_steering_joint">
      <hardwareInterface>hardware_interface/PositionJointInterface</hardwareInterface>
    </joint>
    <actuator name="rear_right_steering_joint_motor">
      <mechanicalReduction>1.0</mechanicalReduction>
    </actuator>
  </transmission>
  <transmission name="rear_right_drive_wheel_transmission">
    <type>transmission_interface/SimpleTransmission</type>
    <joint name="rear_right_drive_wheel_joint">
      <hardwareInterface>hardware_interface/VelocityJointInterface</hardwareInterface>
    </joint>
    <actuator name="rear_right_drive_wheel_joint_motor">
      <mechanicalReduction>1.0</mechanicalReduction>
    </actuator>
  </transmission>
  <gazebo reference="rear_right_steering_link">
    <material>Gazebo/White</material>
  </gazebo>
  <gazebo reference="rear_right_drive_wheel_link">
    <material>Gazebo/Grey</material>
    <mu1 value="1.0"/>
    <mu2 value="1.0"/>
    <kp value="1000000.0"/>
    <kd value="1000.0"/>
    <fdir1 value="1.0 0.0 0.0"/>
  </gazebo>
  <!-- ============================================== Include Macros =============================================== -->
  <!-- ================================================ Main Macros ================================================ -->
  <!-- ============================================== Support Macros =============================================== -->
  <!-- ================================================ Main Macros ================================================ -->
  <!-- ============================================== Support Macros =============================================== -->
  <!-- ================================================ Main Macros ================================================ -->
  <!-- ================================================ Main Macros ================================================ -->
  <!-- ============================================== Support Macros =============================================== -->
  <!-- ================================================ Main Macros ================================================ -->
  <!-- ================================================ Main Macros ================================================ -->
  <!-- ================================================ Main Macros ================================================ -->
  <!-- ============================================== Support Macros =============================================== -->
  <link name="rear_left_base_link">
    <inertial>
      <!-- Mass -->
      <mass value="1.0e-5"/>
      <!-- Inertia -->
      <inertia ixx="1.0e-6" ixy="0.0" ixz="0.0" iyy="1.0e-6" iyz="0.0" izz="1.0e-6"/>
    </inertial>
  </link>
  <link name="rear_left_steering_link">
    <visual>
      <!-- Origin -->
      <origin rpy="0.0 0.0 0.0" xyz="0.0 0.0 0.0"/>
      <geometry>
        <mesh filename="package://abb_mp_steerable_wheel_description/meshes/sw_v3/visual/steering_link.stl"/>
      </geometry>
      <material name="light_grey">
        <color rgba="0.6 0.6 0.6 1.0"/>
      </material>
    </visual>
    <collision>
      <!-- Origin -->
      <origin rpy="0.0 0.0 0.0" xyz="0.0 0.0 0.0"/>
      <geometry>
        <mesh filename="package://abb_mp_steerable_wheel_description/meshes/sw_v3/collision/steering_link.stl"/>
      </geometry>
    </collision>
    <inertial>
      <!-- Origin -->
      <origin rpy="0.0 1.0000736613927508 0.0" xyz="0.0 0.0 0.0"/>
      <!-- Mass -->
      <mass value="2.6"/>
      <inertia ixx="0.0018" ixy="0.0" ixz="0.0" iyy="0.0017" iyz="-0.0004" izz="0.0013"/>
    </inertial>
  </link>
  <link name="rear_left_drive_wheel_link">
    <visual>
      <!-- Origin -->
      <origin rpy="0.0 0.0 0.0" xyz="0.0 0.0 0.0"/>
      <geometry>
        <mesh filename="package://abb_mp_steerable_wheel_description/meshes/sw_v3/visual/drive_wheel_link.stl"/>
      </geometry>
      <material name="dark_grey">
        <color rgba="0.3 0.3 0.3 1.0"/>
      </material>
    </visual>
    <collision>
      <!-- Origin -->
      <origin rpy="1.5707963267948966 0.0 0.0" xyz="0.0 0.0 0.0"/>
      <geometry>
        <cylinder length="0.047" radius="0.0865"/>
      </geometry>
    </collision>
    <inertial>
      <!-- Origin -->
      <origin rpy="0.0 0.0 0.0" xyz="0.0 0.0 0.0"/>
      <!-- Mass -->
      <mass value="1.31"/>
      <inertia ixx="0.0018" ixy="0.0" ixz="0.0" iyy="0.0017" iyz="0.0" izz="0.0013"/>
    </inertial>
  </link>
  <joint name="rear_left_steering_joint" type="revolute">
    <!-- Parent and child -->
    <parent link="rear_left_base_link"/>
    <child link="rear_left_steering_link"/>
    <!-- Origin -->
    <origin rpy="0.0 0.0 0.0" xyz="0.0 0.0 0.0"/>
    <axis xyz="0.0 0.0 1.0"/>
    <limit effort="1000.0" lower="-3.141592653589793" upper="3.141592653589793" velocity="62.83185307179586"/>
    <dynamics damping="0.0" friction="0.0"/>
  </joint>
  <joint name="rear_left_drive_wheel_joint" type="continuous">
    <!-- Parent and child -->
    <parent link="rear_left_steering_link"/>
    <child link="rear_left_drive_wheel_link"/>
    <!-- Origin -->
    <origin rpy="0.0 0.0 0.0" xyz="0.0 0.0 -0.0925"/>
    <axis xyz="0.0 1.0 0.0"/>
  </joint>
  <transmission name="rear_left_steering_transmission">
    <type>transmission_interface/SimpleTransmission</type>
    <joint name="rear_left_steering_joint">
      <hardwareInterface>hardware_interface/PositionJointInterface</hardwareInterface>
    </joint>
    <actuator name="rear_left_steering_joint_motor">
      <mechanicalReduction>1.0</mechanicalReduction>
    </actuator>
  </transmission>
  <transmission name="rear_left_drive_wheel_transmission">
    <type>transmission_interface/SimpleTransmission</type>
    <joint name="rear_left_drive_wheel_joint">
      <hardwareInterface>hardware_interface/VelocityJointInterface</hardwareInterface>
    </joint>
    <actuator name="rear_left_drive_wheel_joint_motor">
      <mechanicalReduction>1.0</mechanicalReduction>
    </actuator>
  </transmission>
  <gazebo reference="rear_left_steering_link">
    <material>Gazebo/White</material>
  </gazebo>
  <gazebo reference="rear_left_drive_wheel_link">
    <material>Gazebo/Grey</material>
    <mu1 value="1.0"/>
    <mu2 value="1.0"/>
    <kp value="1000000.0"/>
    <kd value="1000.0"/>
    <fdir1 value="1.0 0.0 0.0"/>
  </gazebo>
  <joint name="front_left_joint" type="fixed">
    <!-- Parent and child -->
    <parent link="chassis_link"/>
    <child link="front_left_base_link"/>
    <!-- Origin -->
    <origin rpy="0.0 0.0 0.0" xyz="0.285 0.2002 0.1498"/>
  </joint>
  <joint name="front_right_joint" type="fixed">
    <!-- Parent and child -->
    <parent link="chassis_link"/>
    <child link="front_right_base_link"/>
    <!-- Origin -->
    <origin rpy="0.0 0.0 0.0" xyz="0.285 -0.2002 0.1498"/>
  </joint>
  <joint name="rear_right_joint" type="fixed">
    <!-- Parent and child -->
    <parent link="chassis_link"/>
    <child link="rear_right_base_link"/>
    <!-- Origin -->
    <origin rpy="0.0 0.0 0.0" xyz="-0.165 -0.2002 0.1498"/>
  </joint>
  <joint name="rear_left_joint" type="fixed">
    <!-- Parent and child -->
    <parent link="chassis_link"/>
    <child link="rear_left_base_link"/>
    <!-- Origin -->
    <origin rpy="0.0 0.0 0.0" xyz="-0.165 0.2002 0.1498"/>
  </joint>
  <!-- ============================================== Include Macros =============================================== -->
  <!-- ================================================ Main Macros ================================================ -->
  <!-- ============================================== Support Macros =============================================== -->
  <!-- ================================================ Main Macros ================================================ -->
  <!-- ============================================== Support Macros =============================================== -->
  <!-- ================================================ Main Macros ================================================ -->
  <!-- ================================================ Main Macros ================================================ -->
  <!-- ============================================== Support Macros =============================================== -->
  <!-- ================================================ Main Macros ================================================ -->
  <!-- ================================================ Main Macros ================================================ -->
  <!-- ================================================ Main Macros ================================================ -->
  <!-- ============================================== Support Macros =============================================== -->
  <link name="pillar_base_link">
    <visual>
      <!-- Origin -->
      <origin rpy="0.0 0.0 0.0" xyz="0.0 0.0 0.241"/>
      <geometry>
        <mesh filename="package://abb_mp_telescopic_pillar_description/meshes/tp_v2/visual/base_link.stl"/>
      </geometry>
      <material name="dark_grey">
        <color rgba="0.3 0.3 0.3 1.0"/>
      </material>
    </visual>
    <collision>
      <!-- Origin -->
      <origin rpy="0.0 0.0 0.0" xyz="0.0 0.0 0.241"/>
      <geometry>
        <mesh filename="package://abb_mp_telescopic_pillar_description/meshes/tp_v2/collision/base_link.stl"/>
      </geometry>
    </collision>
    <inertial>
      <!-- Origin -->
      <origin rpy="0.0 0.0 0.0" xyz="0.0 0.0 0.241"/>
      <!-- Mass -->
      <mass value="5.5"/>
      <inertia ixx="1e-06" ixy="0.0" ixz="0.0" iyy="1e-06" iyz="0.0" izz="1e-06"/>
    </inertial>
  </link>
  <link name="pillar_body_link">
    <visual>
      <!-- Origin -->
      <origin rpy="0.0 0.0 0.0" xyz="0.0 0.0 0.1"/>
      <geometry>
        <mesh filename="package://abb_mp_telescopic_pillar_description/meshes/tp_v2/visual/body_link.stl"/>
      </geometry>
      <material name="light_grey">
        <color rgba="0.6 0.6 0.6 1.0"/>
      </material>
    </visual>
    <collision>
      <!-- Origin -->
      <origin rpy="0.0 0.0 0.0" xyz="0.0 0.0 0.15"/>
      <geometry>
        <mesh filename="package://abb_mp_telescopic_pillar_description/meshes/tp_v2/collision/body_link.stl"/>
      </geometry>
    </collision>
    <inertial>
      <!-- Origin -->
      <origin rpy="0.0 0.0 0.0" xyz="0.0 0.0 0.0097"/>
      <!-- Mass -->
      <mass value="5.5"/>
      <inertia ixx="1e-06" ixy="0.0" ixz="0.0" iyy="1e-06" iyz="0.0" izz="1e-06"/>
    </inertial>
  </link>
  <link name="pillar_top_link">
    <inertial>
      <!-- Mass -->
      <mass value="1.0e-5"/>
      <!-- Inertia -->
      <inertia ixx="1.0e-6" ixy="0.0" ixz="0.0" iyy="1.0e-6" iyz="0.0" izz="1.0e-6"/>
    </inertial>
  </link>
  <joint name="pillar_body_joint" type="prismatic">
    <!-- Parent and child -->
    <parent link="pillar_base_link"/>
    <child link="pillar_body_link"/>
    <!-- Origin -->
    <origin rpy="0.0 0.0 0.0" xyz="0.0 0.0 0.241"/>
    <axis xyz="0 0 1"/>
    <limit effort="100.0" lower="0.0" upper="0.45" velocity="0.5"/>
    <dynamics damping="10.0" friction="0.1"/>
  </joint>
  <joint name="pillar_top_joint" type="fixed">
    <!-- Parent and child -->
    <parent link="pillar_body_link"/>
    <child link="pillar_top_link"/>
    <!-- Origin -->
    <origin rpy="0.0 0.0 0.0" xyz="0.0 0.0 0.5125"/>
  </joint>
  <transmission name="pillar_body_transmission">
    <type>transmission_interface/SimpleTransmission</type>
    <joint name="pillar_body_joint">
      <hardwareInterface>hardware_interface/EffortJointInterface</hardwareInterface>
    </joint>
    <actuator name="pillar_body_joint_motor">
      <mechanicalReduction>1.0</mechanicalReduction>
    </actuator>
  </transmission>
  <gazebo reference="pillar_base_link">
    <material>Gazebo/Grey</material>
    <mu1 value="0.8"/>
    <mu2 value="0.8"/>
    <kp value="1000000.0"/>
    <kd value="1000.0"/>
    <fdir1 value="0 0 1"/>
    <minDepth value="0.0"/>
    <minDepth value="0.001"/>
  </gazebo>
  <gazebo reference="pillar_body_link">
    <material>Gazebo/White</material>
    <mu1 value="0.8"/>
    <mu2 value="0.8"/>
    <kp value="1000000.0"/>
    <kd value="1000.0"/>
    <fdir1 value="0 0 1"/>
    <minDepth value="0.0"/>
    <minDepth value="0.001"/>
  </gazebo>
  <gazebo>
    <plugin filename="libgazebo_ros_control.so" name="gazebo_ros_controller">
      <robotNamespace>/abb_myumi_v2</robotNamespace>
    </plugin>
  </gazebo>
  <joint name="chassi_pillar_joint" type="fixed">
    <!-- Parent and child -->
    <parent link="chassis_link"/>
    <child link="pillar_base_link"/>
    <!-- Origin -->
    <origin rpy="0.0 0.0 0.0" xyz="0.0 0.0 0.0"/>
  </joint>
  <!-- YuMi robot -->
  <!--xacro:abb_irb14000_05_50 prefix="${prefix}yumi_"/>
    <xacro:joint_tag name="pillar_yumi_joint"  parent="pillar_top_link" child="yumi_base_link"/-->
  <!-- SmartGrippers -->
  <!--xacro:abb_sg prefix="${prefix}yumi_robl_sg_"/>
    <xacro:abb_sg prefix="${prefix}yumi_robr_sg_"/>
    <xacro:joint_tag name="yumi_robl_sg_joint" parent="yumi_robl_tool0" child="yumi_robl_sg_base_link"/>
    <xacro:joint_tag name="yumi_robr_sg_joint" parent="yumi_robr_tool0" child="yumi_robr_sg_base_link"/-->
  <!-- Camera stand -->
  <!--xacro:abb_cs_v2 prefix="${prefix}yumi_cs_"/>
    <xacro:joint_tag name="yumi_cs_joint" parent="yumi_base_link" child="yumi_cs_base_link"/-->
  <!-- Camera -->
  <!--xacro:ms_azure_kinect prefix="${prefix}"/>
    <xacro:joint_tag name="cs_camera_joint" parent="yumi_cs_attachment_link" child="camera_base"/-->
  <!-- Gazebo plugin for ROS Control -->
  <gazebo>
    <plugin filename="libgazebo_ros_control.so" name="gazebo_ros_control">
      <robotSimType>gazebo_ros_control/DefaultRobotHWSim</robotSimType>
      <legacyModeNS>true</legacyModeNS>
    </plugin>
    <plugin filename="libgazebo_ros_p3d.so" name="p3d_base_controller">
      <alwaysOn>true</alwaysOn>
      <updateRate>50.0</updateRate>
      <bodyName>base_link</bodyName>
      <topicName>odom</topicName>
      <gaussianNoise>0.001</gaussianNoise>
      <frameName>world</frameName>
      <xyzOffsets>0 0 0</xyzOffsets>
      <rpyOffsets>0 0 0</rpyOffsets>
      <robotNamespace>/</robotNamespace>
    </plugin>
  </gazebo>
</robot>

