<?xml version="1.0" ?>
<!-- =================================================================================== -->
<!-- |    This document was autogenerated by xacro from myumi_v2.xacro                 | -->
<!-- |    EDITING THIS FILE BY HAND IS NOT RECOMMENDED                                 | -->
<!-- =================================================================================== -->
<robot name="abb_myumi_v2">
  <!-- ============================================== Include Macros =============================================== -->
  <!-- ================================================ Main Macros ================================================ -->
  <!-- ============================================== Support Macros =============================================== -->
  <!-- ================================================ Main Macros ================================================ -->
  <!-- ============================================== Support Macros =============================================== -->
  <!-- ================================================ Main Macros ================================================ -->
  <!-- ================================================ Main Macros ================================================ -->
  <!-- ============================================== Support Macros =============================================== -->
  <!-- ================================================ Main Macros ================================================ -->
  <!-- ================================================ Main Macros ================================================ -->
  <!-- ================================================ Main Macros ================================================ -->
  <!-- ============================================== Support Macros =============================================== -->
  <link name="base_link">
    <inertial>
      <!-- Mass -->
      <mass value="1.0e-5"/>
      <!-- Inertia -->
      <inertia ixx="1.0e-6" ixy="0.0" ixz="0.0" iyy="1.0e-6" iyz="0.0" izz="1.0e-6"/>
    </inertial>
  </link>
  <link name="chassis_link">
    <visual>
      <!-- Origin -->
      <origin rpy="0.0 0.0 0.0" xyz="0.0 0.0 0.0"/>
      <geometry>
        <mesh filename="package://abb_mp_myumi_description/meshes/myumi_v2/visual/chassis_link.stl"/>
      </geometry>
      <material name="light_grey">
        <color rgba="0.6 0.6 0.6 1.0"/>
      </material>
    </visual>
    <collision>
      <!-- Origin -->
      <origin rpy="0.0 0.0 0.0" xyz="0.0 0.0 0.0"/>
      <geometry>
        <mesh filename="package://abb_mp_myumi_description/meshes/myumi_v2/collision/chassis_link.stl"/>
      </geometry>
    </collision>
    <inertial>
      <!-- Origin -->
      <origin rpy="0.0 0.0 0.0" xyz="0.0 0.0 0.0"/>
      <!-- Mass -->
      <mass value="12.67"/>
      <inertia ixx="0.44" ixy="0.0" ixz="0.0" iyy="0.45" iyz="0.0" izz="0.66"/>
    </inertial>
  </link>
  <link name="front_radar_link">
    <inertial>
      <!-- Mass -->
      <mass value="1.0e-5"/>
      <!-- Inertia -->
      <inertia ixx="1.0e-6" ixy="0.0" ixz="0.0" iyy="1.0e-6" iyz="0.0" izz="1.0e-6"/>
    </inertial>
  </link>
  <link name="front_laser_scanner_link">
    <inertial>
      <!-- Mass -->
      <mass value="1.0e-5"/>
      <!-- Inertia -->
      <inertia ixx="1.0e-6" ixy="0.0" ixz="0.0" iyy="1.0e-6" iyz="0.0" izz="1.0e-6"/>
    </inertial>
  </link>
  <link name="rear_laser_scanner_link">
    <inertial>
      <!-- Mass -->
      <mass value="1.0e-5"/>
      <!-- Inertia -->
      <inertia ixx="1.0e-6" ixy="0.0" ixz="0.0" iyy="1.0e-6" iyz="0.0" izz="1.0e-6"/>
    </inertial>
  </link>
  <joint name="chassis_joint" type="fixed">
    <!-- Parent and child -->
    <parent link="base_link"/>
    <child link="chassis_link"/>
    <!-- Origin -->
    <origin rpy="0.0 0.0 0.0" xyz="-0.06 0.0 0.0292"/>
  </joint>
  <joint name="front_radar_joint" type="fixed">
    <!-- Parent and child -->
    <parent link="chassis_link"/>
    <child link="front_radar_link"/>
    <!-- Origin -->
    <origin rpy="-1.5707963267948966 0.0 0.0" xyz="0.35116 0.0 0.08892"/>
  </joint>
  <joint name="front_laser_scanner_joint" type="fixed">
    <!-- Parent and child -->
    <parent link="chassis_link"/>
    <child link="front_laser_scanner_link"/>
    <!-- Origin -->
    <origin rpy="0.0 0.0 0.0" xyz="0.16789 0.0 0.2837"/>
  </joint>
  <joint name="rear_laser_scanner_joint" type="fixed">
    <!-- Parent and child -->
    <parent link="chassis_link"/>
    <child link="rear_laser_scanner_link"/>
    <!-- Origin -->
    <origin rpy="0.0 0.0 3.141592653589793" xyz="-0.17921 0.0 0.2837"/>
  </joint>
  <gazebo reference="chassis_link">
    <material>Gazebo/White</material>
  </gazebo>
  <!-- ================ Subcomponents ================ -->
  <!-- ============================================== Include Macros =============================================== -->
  <!-- ================================================ Main Macros ================================================ -->
  <!-- ============================================== Support Macros =============================================== -->
  <!-- ================================================ Main Macros ================================================ -->
  <!-- ============================================== Support Macros =============================================== -->
  <!-- ================================================ Main Macros ================================================ -->
  <!-- ================================================ Main Macros ================================================ -->
  <!-- ============================================== Support Macros =============================================== -->
  <!-- ================================================ Main Macros ================================================ -->
  <!-- ================================================ Main Macros ================================================ -->
  <!-- ================================================ Main Macros ================================================ -->
  <!-- ============================================== Support Macros =============================================== -->
  <link name="front_left_base_link">
    <inertial>
      <!-- Mass -->
      <mass value="1.0e-5"/>
      <!-- Inertia -->
      <inertia ixx="1.0e-6" ixy="0.0" ixz="0.0" iyy="1.0e-6" iyz="0.0" izz="1.0e-6"/>
    </inertial>
  </link>
  <link name="front_left_steering_link">
    <visual>
      <!-- Origin -->
      <origin rpy="0.0 0.0 0.0" xyz="0.0 0.0 0.0"/>
      <geometry>
        <mesh filename="package://abb_mp_steerable_wheel_description/meshes/sw_v3/visual/steering_link.stl"/>
      </geometry>
      <material name="light_grey">
        <color rgba="0.6 0.6 0.6 1.0"/>
      </material>
    </visual>
    <collision>
      <!-- Origin -->
      <origin rpy="0.0 0.0 0.0" xyz="0.0 0.0 0.0"/>
      <geometry>
        <mesh filename="package://abb_mp_steerable_wheel_description/meshes/sw_v3/collision/steering_link.stl"/>
      </geometry>
    </collision>
    <inertial>
      <!-- Origin -->
      <origin rpy="0.0 1.0000736613927508 0.0" xyz="0.0 0.0 0.0"/>
      <!-- Mass -->
      <mass value="0.6242"/>
      <inertia ixx="0.0018" ixy="0.0" ixz="0.0" iyy="0.0017" iyz="-0.0004" izz="0.0013"/>
    </inertial>
  </link>
  <link name="front_left_drive_wheel_link">
    <visual>
      <!-- Origin -->
      <origin rpy="0.0 0.0 0.0" xyz="0.0 0.0 0.0"/>
      <geometry>
        <mesh filename="package://abb_mp_steerable_wheel_description/meshes/sw_v3/visual/drive_wheel_link.stl"/>
      </geometry>
      <material name="dark_grey">
        <color rgba="0.3 0.3 0.3 1.0"/>
      </material>
    </visual>
    <collision>
      <!-- Origin -->
      <origin rpy="1.5707963267948966 0.0 0.0" xyz="0.0 0.0 0.0"/>
      <geometry>
        <cylinder length="0.047" radius="0.0865"/>
      </geometry>
    </collision>
    <inertial>
      <!-- Origin -->
      <origin rpy="0.0 0.0 0.0" xyz="0.0 0.0 0.0"/>
      <!-- Mass -->
      <mass value="0.6242"/>
      <inertia ixx="0.0018" ixy="0.0" ixz="0.0" iyy="0.0017" iyz="0.0" izz="0.0013"/>
    </inertial>
  </link>
  <joint name="front_left_steering_joint" type="revolute">
    <!-- Parent and child -->
    <parent link="front_left_base_link"/>
    <child link="front_left_steering_link"/>
    <!-- Origin -->
    <origin rpy="0.0 0.0 0.0" xyz="0.0 0.0 0.0"/>
    <axis xyz="0.0 0.0 1.0"/>
    <limit effort="1000.0" lower="-62.83185307179586" upper="62.83185307179586" velocity="62.83185307179586"/>
    <dynamics damping="0.7" friction="0.0"/>
  </joint>
  <joint name="front_left_drive_wheel_joint" type="continuous">
    <!-- Parent and child -->
    <parent link="front_left_steering_link"/>
    <child link="front_left_drive_wheel_link"/>
    <!-- Origin -->
    <origin rpy="0.0 0.0 0.0" xyz="0.0 0.0 -0.0925"/>
    <axis xyz="0.0 1.0 0.0"/>
  </joint>
  <transmission name="front_left_steering_transmission">
    <type>transmission_interface/SimpleTransmission</type>
    <joint name="front_left_steering_joint">
      <hardwareInterface>hardware_interface/PositionJointInterface</hardwareInterface>
    </joint>
    <actuator name="front_left_steering_joint_motor">
      <mechanicalReduction>1.0</mechanicalReduction>
    </actuator>
  </transmission>
  <transmission name="front_left_drive_wheel_transmission">
    <type>transmission_interface/SimpleTransmission</type>
    <joint name="front_left_drive_wheel_joint">
      <hardwareInterface>hardware_interface/VelocityJointInterface</hardwareInterface>
    </joint>
    <actuator name="front_left_drive_wheel_joint_motor">
      <mechanicalReduction>1.0</mechanicalReduction>
    </actuator>
  </transmission>
  <gazebo reference="front_left_steering_link">
    <material>Gazebo/White</material>
  </gazebo>
  <gazebo reference="front_left_drive_wheel_link">
    <material>Gazebo/Grey</material>
    <mu1 value="1.0"/>
    <mu2 value="1.0"/>
    <kp value="10000000.0"/>
    <kd value="1.0"/>
    <fdir1 value="1.0 0.0 0.0"/>
  </gazebo>
  <!-- ============================================== Include Macros =============================================== -->
  <!-- ================================================ Main Macros ================================================ -->
  <!-- ============================================== Support Macros =============================================== -->
  <!-- ================================================ Main Macros ================================================ -->
  <!-- ============================================== Support Macros =============================================== -->
  <!-- ================================================ Main Macros ================================================ -->
  <!-- ================================================ Main Macros ================================================ -->
  <!-- ============================================== Support Macros =============================================== -->
  <!-- ================================================ Main Macros ================================================ -->
  <!-- ================================================ Main Macros ================================================ -->
  <!-- ================================================ Main Macros ================================================ -->
  <!-- ============================================== Support Macros =============================================== -->
  <link name="front_right_base_link">
    <inertial>
      <!-- Mass -->
      <mass value="1.0e-5"/>
      <!-- Inertia -->
      <inertia ixx="1.0e-6" ixy="0.0" ixz="0.0" iyy="1.0e-6" iyz="0.0" izz="1.0e-6"/>
    </inertial>
  </link>
  <link name="front_right_steering_link">
    <visual>
      <!-- Origin -->
      <origin rpy="0.0 0.0 0.0" xyz="0.0 0.0 0.0"/>
      <geometry>
        <mesh filename="package://abb_mp_steerable_wheel_description/meshes/sw_v3/visual/steering_link.stl"/>
      </geometry>
      <material name="light_grey">
        <color rgba="0.6 0.6 0.6 1.0"/>
      </material>
    </visual>
    <collision>
      <!-- Origin -->
      <origin rpy="0.0 0.0 0.0" xyz="0.0 0.0 0.0"/>
      <geometry>
        <mesh filename="package://abb_mp_steerable_wheel_description/meshes/sw_v3/collision/steering_link.stl"/>
      </geometry>
    </collision>
    <inertial>
      <!-- Origin -->
      <origin rpy="0.0 1.0000736613927508 0.0" xyz="0.0 0.0 0.0"/>
      <!-- Mass -->
      <mass value="0.6242"/>
      <inertia ixx="0.0018" ixy="0.0" ixz="0.0" iyy="0.0017" iyz="-0.0004" izz="0.0013"/>
    </inertial>
  </link>
  <link name="front_right_drive_wheel_link">
    <visual>
      <!-- Origin -->
      <origin rpy="0.0 0.0 0.0" xyz="0.0 0.0 0.0"/>
      <geometry>
        <mesh filename="package://abb_mp_steerable_wheel_description/meshes/sw_v3/visual/drive_wheel_link.stl"/>
      </geometry>
      <material name="dark_grey">
        <color rgba="0.3 0.3 0.3 1.0"/>
      </material>
    </visual>
    <collision>
      <!-- Origin -->
      <origin rpy="1.5707963267948966 0.0 0.0" xyz="0.0 0.0 0.0"/>
      <geometry>
        <cylinder length="0.047" radius="0.0865"/>
      </geometry>
    </collision>
    <inertial>
      <!-- Origin -->
      <origin rpy="0.0 0.0 0.0" xyz="0.0 0.0 0.0"/>
      <!-- Mass -->
      <mass value="0.6242"/>
      <inertia ixx="0.0018" ixy="0.0" ixz="0.0" iyy="0.0017" iyz="0.0" izz="0.0013"/>
    </inertial>
  </link>
  <joint name="front_right_steering_joint" type="revolute">
    <!-- Parent and child -->
    <parent link="front_right_base_link"/>
    <child link="front_right_steering_link"/>
    <!-- Origin -->
    <origin rpy="0.0 0.0 0.0" xyz="0.0 0.0 0.0"/>
    <axis xyz="0.0 0.0 1.0"/>
    <limit effort="1000.0" lower="-62.83185307179586" upper="62.83185307179586" velocity="62.83185307179586"/>
    <dynamics damping="0.7" friction="0.0"/>
  </joint>
  <joint name="front_right_drive_wheel_joint" type="continuous">
    <!-- Parent and child -->
    <parent link="front_right_steering_link"/>
    <child link="front_right_drive_wheel_link"/>
    <!-- Origin -->
    <origin rpy="0.0 0.0 0.0" xyz="0.0 0.0 -0.0925"/>
    <axis xyz="0.0 1.0 0.0"/>
  </joint>
  <transmission name="front_right_steering_transmission">
    <type>transmission_interface/SimpleTransmission</type>
    <joint name="front_right_steering_joint">
      <hardwareInterface>hardware_interface/PositionJointInterface</hardwareInterface>
    </joint>
    <actuator name="front_right_steering_joint_motor">
      <mechanicalReduction>1.0</mechanicalReduction>
    </actuator>
  </transmission>
  <transmission name="front_right_drive_wheel_transmission">
    <type>transmission_interface/SimpleTransmission</type>
    <joint name="front_right_drive_wheel_joint">
      <hardwareInterface>hardware_interface/VelocityJointInterface</hardwareInterface>
    </joint>
    <actuator name="front_right_drive_wheel_joint_motor">
      <mechanicalReduction>1.0</mechanicalReduction>
    </actuator>
  </transmission>
  <gazebo reference="front_right_steering_link">
    <material>Gazebo/White</material>
  </gazebo>
  <gazebo reference="front_right_drive_wheel_link">
    <material>Gazebo/Grey</material>
    <mu1 value="1.0"/>
    <mu2 value="1.0"/>
    <kp value="10000000.0"/>
    <kd value="1.0"/>
    <fdir1 value="1.0 0.0 0.0"/>
  </gazebo>
  <!-- ============================================== Include Macros =============================================== -->
  <!-- ================================================ Main Macros ================================================ -->
  <!-- ============================================== Support Macros =============================================== -->
  <!-- ================================================ Main Macros ================================================ -->
  <!-- ============================================== Support Macros =============================================== -->
  <!-- ================================================ Main Macros ================================================ -->
  <!-- ================================================ Main Macros ================================================ -->
  <!-- ============================================== Support Macros =============================================== -->
  <!-- ================================================ Main Macros ================================================ -->
  <!-- ================================================ Main Macros ================================================ -->
  <!-- ================================================ Main Macros ================================================ -->
  <!-- ============================================== Support Macros =============================================== -->
  <link name="rear_right_base_link">
    <inertial>
      <!-- Mass -->
      <mass value="1.0e-5"/>
      <!-- Inertia -->
      <inertia ixx="1.0e-6" ixy="0.0" ixz="0.0" iyy="1.0e-6" iyz="0.0" izz="1.0e-6"/>
    </inertial>
  </link>
  <link name="rear_right_steering_link">
    <visual>
      <!-- Origin -->
      <origin rpy="0.0 0.0 0.0" xyz="0.0 0.0 0.0"/>
      <geometry>
        <mesh filename="package://abb_mp_steerable_wheel_description/meshes/sw_v3/visual/steering_link.stl"/>
      </geometry>
      <material name="light_grey">
        <color rgba="0.6 0.6 0.6 1.0"/>
      </material>
    </visual>
    <collision>
      <!-- Origin -->
      <origin rpy="0.0 0.0 0.0" xyz="0.0 0.0 0.0"/>
      <geometry>
        <mesh filename="package://abb_mp_steerable_wheel_description/meshes/sw_v3/collision/steering_link.stl"/>
      </geometry>
    </collision>
    <inertial>
      <!-- Origin -->
      <origin rpy="0.0 1.0000736613927508 0.0" xyz="0.0 0.0 0.0"/>
      <!-- Mass -->
      <mass value="0.6242"/>
      <inertia ixx="0.0018" ixy="0.0" ixz="0.0" iyy="0.0017" iyz="-0.0004" izz="0.0013"/>
    </inertial>
  </link>
  <link name="rear_right_drive_wheel_link">
    <visual>
      <!-- Origin -->
      <origin rpy="0.0 0.0 0.0" xyz="0.0 0.0 0.0"/>
      <geometry>
        <mesh filename="package://abb_mp_steerable_wheel_description/meshes/sw_v3/visual/drive_wheel_link.stl"/>
      </geometry>
      <material name="dark_grey">
        <color rgba="0.3 0.3 0.3 1.0"/>
      </material>
    </visual>
    <collision>
      <!-- Origin -->
      <origin rpy="1.5707963267948966 0.0 0.0" xyz="0.0 0.0 0.0"/>
      <geometry>
        <cylinder length="0.047" radius="0.0865"/>
      </geometry>
    </collision>
    <inertial>
      <!-- Origin -->
      <origin rpy="0.0 0.0 0.0" xyz="0.0 0.0 0.0"/>
      <!-- Mass -->
      <mass value="0.6242"/>
      <inertia ixx="0.0018" ixy="0.0" ixz="0.0" iyy="0.0017" iyz="0.0" izz="0.0013"/>
    </inertial>
  </link>
  <joint name="rear_right_steering_joint" type="revolute">
    <!-- Parent and child -->
    <parent link="rear_right_base_link"/>
    <child link="rear_right_steering_link"/>
    <!-- Origin -->
    <origin rpy="0.0 0.0 0.0" xyz="0.0 0.0 0.0"/>
    <axis xyz="0.0 0.0 1.0"/>
    <limit effort="1000.0" lower="-62.83185307179586" upper="62.83185307179586" velocity="62.83185307179586"/>
    <dynamics damping="0.7" friction="0.0"/>
  </joint>
  <joint name="rear_right_drive_wheel_joint" type="continuous">
    <!-- Parent and child -->
    <parent link="rear_right_steering_link"/>
    <child link="rear_right_drive_wheel_link"/>
    <!-- Origin -->
    <origin rpy="0.0 0.0 0.0" xyz="0.0 0.0 -0.0925"/>
    <axis xyz="0.0 1.0 0.0"/>
  </joint>
  <transmission name="rear_right_steering_transmission">
    <type>transmission_interface/SimpleTransmission</type>
    <joint name="rear_right_steering_joint">
      <hardwareInterface>hardware_interface/PositionJointInterface</hardwareInterface>
    </joint>
    <actuator name="rear_right_steering_joint_motor">
      <mechanicalReduction>1.0</mechanicalReduction>
    </actuator>
  </transmission>
  <transmission name="rear_right_drive_wheel_transmission">
    <type>transmission_interface/SimpleTransmission</type>
    <joint name="rear_right_drive_wheel_joint">
      <hardwareInterface>hardware_interface/VelocityJointInterface</hardwareInterface>
    </joint>
    <actuator name="rear_right_drive_wheel_joint_motor">
      <mechanicalReduction>1.0</mechanicalReduction>
    </actuator>
  </transmission>
  <gazebo reference="rear_right_steering_link">
    <material>Gazebo/White</material>
  </gazebo>
  <gazebo reference="rear_right_drive_wheel_link">
    <material>Gazebo/Grey</material>
    <mu1 value="1.0"/>
    <mu2 value="1.0"/>
    <kp value="10000000.0"/>
    <kd value="1.0"/>
    <fdir1 value="1.0 0.0 0.0"/>
  </gazebo>
  <!-- ============================================== Include Macros =============================================== -->
  <!-- ================================================ Main Macros ================================================ -->
  <!-- ============================================== Support Macros =============================================== -->
  <!-- ================================================ Main Macros ================================================ -->
  <!-- ============================================== Support Macros =============================================== -->
  <!-- ================================================ Main Macros ================================================ -->
  <!-- ================================================ Main Macros ================================================ -->
  <!-- ============================================== Support Macros =============================================== -->
  <!-- ================================================ Main Macros ================================================ -->
  <!-- ================================================ Main Macros ================================================ -->
  <!-- ================================================ Main Macros ================================================ -->
  <!-- ============================================== Support Macros =============================================== -->
  <link name="rear_left_base_link">
    <inertial>
      <!-- Mass -->
      <mass value="1.0e-5"/>
      <!-- Inertia -->
      <inertia ixx="1.0e-6" ixy="0.0" ixz="0.0" iyy="1.0e-6" iyz="0.0" izz="1.0e-6"/>
    </inertial>
  </link>
  <link name="rear_left_steering_link">
    <visual>
      <!-- Origin -->
      <origin rpy="0.0 0.0 0.0" xyz="0.0 0.0 0.0"/>
      <geometry>
        <mesh filename="package://abb_mp_steerable_wheel_description/meshes/sw_v3/visual/steering_link.stl"/>
      </geometry>
      <material name="light_grey">
        <color rgba="0.6 0.6 0.6 1.0"/>
      </material>
    </visual>
    <collision>
      <!-- Origin -->
      <origin rpy="0.0 0.0 0.0" xyz="0.0 0.0 0.0"/>
      <geometry>
        <mesh filename="package://abb_mp_steerable_wheel_description/meshes/sw_v3/collision/steering_link.stl"/>
      </geometry>
    </collision>
    <inertial>
      <!-- Origin -->
      <origin rpy="0.0 1.0000736613927508 0.0" xyz="0.0 0.0 0.0"/>
      <!-- Mass -->
      <mass value="0.6242"/>
      <inertia ixx="0.0018" ixy="0.0" ixz="0.0" iyy="0.0017" iyz="-0.0004" izz="0.0013"/>
    </inertial>
  </link>
  <link name="rear_left_drive_wheel_link">
    <visual>
      <!-- Origin -->
      <origin rpy="0.0 0.0 0.0" xyz="0.0 0.0 0.0"/>
      <geometry>
        <mesh filename="package://abb_mp_steerable_wheel_description/meshes/sw_v3/visual/drive_wheel_link.stl"/>
      </geometry>
      <material name="dark_grey">
        <color rgba="0.3 0.3 0.3 1.0"/>
      </material>
    </visual>
    <collision>
      <!-- Origin -->
      <origin rpy="1.5707963267948966 0.0 0.0" xyz="0.0 0.0 0.0"/>
      <geometry>
        <cylinder length="0.047" radius="0.0865"/>
      </geometry>
    </collision>
    <inertial>
      <!-- Origin -->
      <origin rpy="0.0 0.0 0.0" xyz="0.0 0.0 0.0"/>
      <!-- Mass -->
      <mass value="0.6242"/>
      <inertia ixx="0.0018" ixy="0.0" ixz="0.0" iyy="0.0017" iyz="0.0" izz="0.0013"/>
    </inertial>
  </link>
  <joint name="rear_left_steering_joint" type="revolute">
    <!-- Parent and child -->
    <parent link="rear_left_base_link"/>
    <child link="rear_left_steering_link"/>
    <!-- Origin -->
    <origin rpy="0.0 0.0 0.0" xyz="0.0 0.0 0.0"/>
    <axis xyz="0.0 0.0 1.0"/>
    <limit effort="1000.0" lower="-62.83185307179586" upper="62.83185307179586" velocity="62.83185307179586"/>
    <dynamics damping="0.7" friction="0.0"/>
  </joint>
  <joint name="rear_left_drive_wheel_joint" type="continuous">
    <!-- Parent and child -->
    <parent link="rear_left_steering_link"/>
    <child link="rear_left_drive_wheel_link"/>
    <!-- Origin -->
    <origin rpy="0.0 0.0 0.0" xyz="0.0 0.0 -0.0925"/>
    <axis xyz="0.0 1.0 0.0"/>
  </joint>
  <transmission name="rear_left_steering_transmission">
    <type>transmission_interface/SimpleTransmission</type>
    <joint name="rear_left_steering_joint">
      <hardwareInterface>hardware_interface/PositionJointInterface</hardwareInterface>
    </joint>
    <actuator name="rear_left_steering_joint_motor">
      <mechanicalReduction>1.0</mechanicalReduction>
    </actuator>
  </transmission>
  <transmission name="rear_left_drive_wheel_transmission">
    <type>transmission_interface/SimpleTransmission</type>
    <joint name="rear_left_drive_wheel_joint">
      <hardwareInterface>hardware_interface/VelocityJointInterface</hardwareInterface>
    </joint>
    <actuator name="rear_left_drive_wheel_joint_motor">
      <mechanicalReduction>1.0</mechanicalReduction>
    </actuator>
  </transmission>
  <gazebo reference="rear_left_steering_link">
    <material>Gazebo/White</material>
  </gazebo>
  <gazebo reference="rear_left_drive_wheel_link">
    <material>Gazebo/Grey</material>
    <mu1 value="1.0"/>
    <mu2 value="1.0"/>
    <kp value="10000000.0"/>
    <kd value="1.0"/>
    <fdir1 value="1.0 0.0 0.0"/>
  </gazebo>
  <joint name="front_left_joint" type="fixed">
    <!-- Parent and child -->
    <parent link="chassis_link"/>
    <child link="front_left_base_link"/>
    <!-- Origin -->
    <origin rpy="0.0 0.0 0.0" xyz="0.285 0.2002 0.1498"/>
  </joint>
  <joint name="front_right_joint" type="fixed">
    <!-- Parent and child -->
    <parent link="chassis_link"/>
    <child link="front_right_base_link"/>
    <!-- Origin -->
    <origin rpy="0.0 0.0 0.0" xyz="0.285 -0.2002 0.1498"/>
  </joint>
  <joint name="rear_right_joint" type="fixed">
    <!-- Parent and child -->
    <parent link="chassis_link"/>
    <child link="rear_right_base_link"/>
    <!-- Origin -->
    <origin rpy="0.0 0.0 0.0" xyz="-0.165 -0.2002 0.1498"/>
  </joint>
  <joint name="rear_left_joint" type="fixed">
    <!-- Parent and child -->
    <parent link="chassis_link"/>
    <child link="rear_left_base_link"/>
    <!-- Origin -->
    <origin rpy="0.0 0.0 0.0" xyz="-0.165 0.2002 0.1498"/>
  </joint>
  <!-- ============================================== Include Macros =============================================== -->
  <!-- ================================================ Main Macros ================================================ -->
  <!-- ============================================== Support Macros =============================================== -->
  <!-- ================================================ Main Macros ================================================ -->
  <!-- ============================================== Support Macros =============================================== -->
  <!-- ================================================ Main Macros ================================================ -->
  <!-- ================================================ Main Macros ================================================ -->
  <!-- ============================================== Support Macros =============================================== -->
  <!-- ================================================ Main Macros ================================================ -->
  <!-- ================================================ Main Macros ================================================ -->
  <!-- ================================================ Main Macros ================================================ -->
  <!-- ============================================== Support Macros =============================================== -->
  <link name="pillar_base_link">
    <visual>
      <!-- Origin -->
      <origin rpy="0.0 0.0 0.0" xyz="0.0 0.0 0.241"/>
      <geometry>
        <mesh filename="package://abb_mp_telescopic_pillar_description/meshes/tp_v2/visual/base_link.stl"/>
      </geometry>
      <material name="dark_grey">
        <color rgba="0.3 0.3 0.3 1.0"/>
      </material>
    </visual>
    <collision>
      <!-- Origin -->
      <origin rpy="0.0 0.0 0.0" xyz="0.0 0.0 0.241"/>
      <geometry>
        <mesh filename="package://abb_mp_telescopic_pillar_description/meshes/tp_v2/collision/base_link.stl"/>
      </geometry>
    </collision>
    <inertial>
      <!-- Origin -->
      <origin rpy="0.0 0.0 0.0" xyz="0.0 0.0 0.241"/>
      <!-- Mass -->
      <mass value="1e-05"/>
      <inertia ixx="1e-06" ixy="0.0" ixz="0.0" iyy="1e-06" iyz="0.0" izz="1e-06"/>
    </inertial>
  </link>
  <link name="pillar_body_link">
    <visual>
      <!-- Origin -->
      <origin rpy="0.0 0.0 0.0" xyz="0.0 0.0 0.0"/>
      <geometry>
        <mesh filename="package://abb_mp_telescopic_pillar_description/meshes/tp_v2/visual/body_link.stl"/>
      </geometry>
      <material name="light_grey">
        <color rgba="0.6 0.6 0.6 1.0"/>
      </material>
    </visual>
    <collision>
      <!-- Origin -->
      <origin rpy="0.0 0.0 0.0" xyz="0.0 0.0 0.0"/>
      <geometry>
        <mesh filename="package://abb_mp_telescopic_pillar_description/meshes/tp_v2/collision/body_link.stl"/>
      </geometry>
    </collision>
    <inertial>
      <!-- Origin -->
      <origin rpy="0.0 0.0 0.0" xyz="0.0 0.0 0.0085"/>
      <!-- Mass -->
      <mass value="1e-05"/>
      <inertia ixx="1e-06" ixy="0.0" ixz="0.0" iyy="1e-06" iyz="0.0" izz="1e-06"/>
    </inertial>
  </link>
  <link name="pillar_top_link">
    <inertial>
      <!-- Mass -->
      <mass value="1.0e-5"/>
      <!-- Inertia -->
      <inertia ixx="1.0e-6" ixy="0.0" ixz="0.0" iyy="1.0e-6" iyz="0.0" izz="1.0e-6"/>
    </inertial>
  </link>
  <joint name="pillar_body_joint" type="prismatic">
    <!-- Parent and child -->
    <parent link="pillar_base_link"/>
    <child link="pillar_body_link"/>
    <!-- Origin -->
    <origin rpy="0.0 0.0 0.0" xyz="0.0 0.0 0.241"/>
    <axis xyz="0.0 0.0 1.0"/>
    <limit effort="0.1" lower="0.0" upper="0.45" velocity="0.1"/>
  </joint>
  <joint name="pillar_top_joint" type="fixed">
    <!-- Parent and child -->
    <parent link="pillar_body_link"/>
    <child link="pillar_top_link"/>
    <!-- Origin -->
    <origin rpy="0.0 0.0 0.0" xyz="0.0 0.0 0.5125"/>
  </joint>
  <transmission name="pillar_body_transmission">
    <type>transmission_interface/SimpleTransmission</type>
    <joint name="pillar_body_joint">
      <hardwareInterface>hardware_interface/PositionJointInterface</hardwareInterface>
    </joint>
    <actuator name="pillar_body_joint_motor">
      <mechanicalReduction>1.0</mechanicalReduction>
    </actuator>
  </transmission>
  <gazebo reference="pillar_base_link">
    <material>Gazebo/Grey</material>
  </gazebo>
  <gazebo reference="pillar_body_link">
    <material>Gazebo/White</material>
  </gazebo>
  <joint name="chassi_pillar_joint" type="fixed">
    <!-- Parent and child -->
    <parent link="chassis_link"/>
    <child link="pillar_base_link"/>
    <!-- Origin -->
    <origin rpy="0.0 0.0 0.0" xyz="0.0 0.0 0.0"/>
  </joint>
  <!-- ============================================== Include Macros =============================================== -->
  <!-- ================================================ Main Macros ================================================ -->
  <!-- ============================================== Support Macros =============================================== -->
  <!-- ================================================ Main Macros ================================================ -->
  <!-- ============================================== Support Macros =============================================== -->
  <!-- ================================================ Main Macros ================================================ -->
  <!-- ================================================ Main Macros ================================================ -->
  <!-- ============================================== Support Macros =============================================== -->
  <!-- ================================================ Main Macros ================================================ -->
  <!-- ================================================ Main Macros ================================================ -->
  <!-- ================================================ Main Macros ================================================ -->
  <!-- ============================================== Support Macros =============================================== -->
  <link name="yumi_base_link">
    <visual>
      <!-- Origin -->
      <origin rpy="0.0 0.0 0.0" xyz="0.0 0.0 0.0"/>
      <geometry>
        <mesh filename="package://abb_mp_irb14000_description/meshes/irb14000_05_50/visual/base_link.stl"/>
      </geometry>
      <material name="light_grey">
        <color rgba="0.6 0.6 0.6 1.0"/>
      </material>
    </visual>
    <collision>
      <!-- Origin -->
      <origin rpy="0.0 0.0 0.0" xyz="0.0 0.0 0.0"/>
      <geometry>
        <mesh filename="package://abb_mp_irb14000_description/meshes/irb14000_05_50/collision/base_link.stl"/>
      </geometry>
    </collision>
    <inertial>
      <!-- Origin -->
      <origin rpy="0.0 0.0 0.0" xyz="0.0 0.0 0.0"/>
      <!-- Mass -->
      <mass value="1e-05"/>
      <inertia ixx="1e-06" ixy="0.0" ixz="0.0" iyy="1e-06" iyz="0.0" izz="1e-06"/>
    </inertial>
  </link>
  <link name="yumi_base">
    <inertial>
      <!-- Mass -->
      <mass value="1.0e-5"/>
      <!-- Inertia -->
      <inertia ixx="1.0e-6" ixy="0.0" ixz="0.0" iyy="1.0e-6" iyz="0.0" izz="1.0e-6"/>
    </inertial>
  </link>
  <link name="yumi_robl_base_link">
    <inertial>
      <!-- Mass -->
      <mass value="1.0e-5"/>
      <!-- Inertia -->
      <inertia ixx="1.0e-6" ixy="0.0" ixz="0.0" iyy="1.0e-6" iyz="0.0" izz="1.0e-6"/>
    </inertial>
  </link>
  <link name="yumi_robl_link_1">
    <visual>
      <!-- Origin -->
      <origin rpy="0.0 0.0 0.0" xyz="0.0 0.0 0.0"/>
      <geometry>
        <mesh filename="package://abb_mp_irb14000_description/meshes/irb14000_05_50/visual/robl_link_1.stl"/>
      </geometry>
      <material name="light_grey">
        <color rgba="0.6 0.6 0.6 1.0"/>
      </material>
    </visual>
    <collision>
      <!-- Origin -->
      <origin rpy="0.0 0.0 0.0" xyz="0.0 0.0 0.0"/>
      <geometry>
        <mesh filename="package://abb_mp_irb14000_description/meshes/irb14000_05_50/collision/robl_link_1.stl"/>
      </geometry>
    </collision>
    <inertial>
      <!-- Origin -->
      <origin rpy="0.0 0.0 0.0" xyz="0.0 0.0 0.0"/>
      <!-- Mass -->
      <mass value="1e-05"/>
      <inertia ixx="1e-06" ixy="0.0" ixz="0.0" iyy="1e-06" iyz="0.0" izz="1e-06"/>
    </inertial>
  </link>
  <link name="yumi_robl_link_2">
    <visual>
      <!-- Origin -->
      <origin rpy="0.0 0.0 0.0" xyz="0.0 0.0 0.0"/>
      <geometry>
        <mesh filename="package://abb_mp_irb14000_description/meshes/irb14000_05_50/visual/robl_link_2.stl"/>
      </geometry>
      <material name="light_grey">
        <color rgba="0.6 0.6 0.6 1.0"/>
      </material>
    </visual>
    <collision>
      <!-- Origin -->
      <origin rpy="0.0 0.0 0.0" xyz="0.0 0.0 0.0"/>
      <geometry>
        <mesh filename="package://abb_mp_irb14000_description/meshes/irb14000_05_50/collision/robl_link_2.stl"/>
      </geometry>
    </collision>
    <inertial>
      <!-- Origin -->
      <origin rpy="0.0 0.0 0.0" xyz="0.0 0.0 0.0"/>
      <!-- Mass -->
      <mass value="1e-05"/>
      <inertia ixx="1e-06" ixy="0.0" ixz="0.0" iyy="1e-06" iyz="0.0" izz="1e-06"/>
    </inertial>
  </link>
  <link name="yumi_robl_link_3">
    <visual>
      <!-- Origin -->
      <origin rpy="0.0 0.0 0.0" xyz="0.0 0.0 0.0"/>
      <geometry>
        <mesh filename="package://abb_mp_irb14000_description/meshes/irb14000_05_50/visual/robl_link_3.stl"/>
      </geometry>
      <material name="light_grey">
        <color rgba="0.6 0.6 0.6 1.0"/>
      </material>
    </visual>
    <collision>
      <!-- Origin -->
      <origin rpy="0.0 0.0 0.0" xyz="0.0 0.0 0.0"/>
      <geometry>
        <mesh filename="package://abb_mp_irb14000_description/meshes/irb14000_05_50/collision/robl_link_3.stl"/>
      </geometry>
    </collision>
    <inertial>
      <!-- Origin -->
      <origin rpy="0.0 0.0 0.0" xyz="0.0 0.0 0.0"/>
      <!-- Mass -->
      <mass value="1e-05"/>
      <inertia ixx="1e-06" ixy="0.0" ixz="0.0" iyy="1e-06" iyz="0.0" izz="1e-06"/>
    </inertial>
  </link>
  <link name="yumi_robl_link_4">
    <visual>
      <!-- Origin -->
      <origin rpy="0.0 0.0 0.0" xyz="0.0 0.0 0.0"/>
      <geometry>
        <mesh filename="package://abb_mp_irb14000_description/meshes/irb14000_05_50/visual/robl_link_4.stl"/>
      </geometry>
      <material name="light_grey">
        <color rgba="0.6 0.6 0.6 1.0"/>
      </material>
    </visual>
    <collision>
      <!-- Origin -->
      <origin rpy="0.0 0.0 0.0" xyz="0.0 0.0 0.0"/>
      <geometry>
        <mesh filename="package://abb_mp_irb14000_description/meshes/irb14000_05_50/collision/robl_link_4.stl"/>
      </geometry>
    </collision>
    <inertial>
      <!-- Origin -->
      <origin rpy="0.0 0.0 0.0" xyz="0.0 0.0 0.0"/>
      <!-- Mass -->
      <mass value="1e-05"/>
      <inertia ixx="1e-06" ixy="0.0" ixz="0.0" iyy="1e-06" iyz="0.0" izz="1e-06"/>
    </inertial>
  </link>
  <link name="yumi_robl_link_5">
    <visual>
      <!-- Origin -->
      <origin rpy="0.0 0.0 0.0" xyz="0.0 0.0 0.0"/>
      <geometry>
        <mesh filename="package://abb_mp_irb14000_description/meshes/irb14000_05_50/visual/robl_link_5.stl"/>
      </geometry>
      <material name="light_grey">
        <color rgba="0.6 0.6 0.6 1.0"/>
      </material>
    </visual>
    <collision>
      <!-- Origin -->
      <origin rpy="0.0 0.0 0.0" xyz="0.0 0.0 0.0"/>
      <geometry>
        <mesh filename="package://abb_mp_irb14000_description/meshes/irb14000_05_50/collision/robl_link_5.stl"/>
      </geometry>
    </collision>
    <inertial>
      <!-- Origin -->
      <origin rpy="0.0 0.0 0.0" xyz="0.0 0.0 0.0"/>
      <!-- Mass -->
      <mass value="1e-05"/>
      <inertia ixx="1e-06" ixy="0.0" ixz="0.0" iyy="1e-06" iyz="0.0" izz="1e-06"/>
    </inertial>
  </link>
  <link name="yumi_robl_link_6">
    <visual>
      <!-- Origin -->
      <origin rpy="0.0 0.0 0.0" xyz="0.0 0.0 0.0"/>
      <geometry>
        <mesh filename="package://abb_mp_irb14000_description/meshes/irb14000_05_50/visual/robl_link_6.stl"/>
      </geometry>
      <material name="light_grey">
        <color rgba="0.6 0.6 0.6 1.0"/>
      </material>
    </visual>
    <collision>
      <!-- Origin -->
      <origin rpy="0.0 0.0 0.0" xyz="0.0 0.0 0.0"/>
      <geometry>
        <mesh filename="package://abb_mp_irb14000_description/meshes/irb14000_05_50/collision/robl_link_6.stl"/>
      </geometry>
    </collision>
    <inertial>
      <!-- Origin -->
      <origin rpy="0.0 0.0 0.0" xyz="0.0 0.0 0.0"/>
      <!-- Mass -->
      <mass value="1e-05"/>
      <inertia ixx="1e-06" ixy="0.0" ixz="0.0" iyy="1e-06" iyz="0.0" izz="1e-06"/>
    </inertial>
  </link>
  <link name="yumi_robl_link_7">
    <visual>
      <!-- Origin -->
      <origin rpy="0.0 0.0 0.0" xyz="0.0 0.0 0.0"/>
      <geometry>
        <mesh filename="package://abb_mp_irb14000_description/meshes/irb14000_05_50/visual/robl_link_7.stl"/>
      </geometry>
      <material name="light_grey">
        <color rgba="0.6 0.6 0.6 1.0"/>
      </material>
    </visual>
    <collision>
      <!-- Origin -->
      <origin rpy="0.0 0.0 0.0" xyz="0.0 0.0 0.0"/>
      <geometry>
        <mesh filename="package://abb_mp_irb14000_description/meshes/irb14000_05_50/collision/robl_link_7.stl"/>
      </geometry>
    </collision>
    <inertial>
      <!-- Origin -->
      <origin rpy="0.0 0.0 0.0" xyz="0.0 0.0 0.0"/>
      <!-- Mass -->
      <mass value="1e-05"/>
      <inertia ixx="1e-06" ixy="0.0" ixz="0.0" iyy="1e-06" iyz="0.0" izz="1e-06"/>
    </inertial>
  </link>
  <link name="yumi_robl_flange">
    <inertial>
      <!-- Mass -->
      <mass value="1.0e-5"/>
      <!-- Inertia -->
      <inertia ixx="1.0e-6" ixy="0.0" ixz="0.0" iyy="1.0e-6" iyz="0.0" izz="1.0e-6"/>
    </inertial>
  </link>
  <link name="yumi_robl_tool0">
    <inertial>
      <!-- Mass -->
      <mass value="1.0e-5"/>
      <!-- Inertia -->
      <inertia ixx="1.0e-6" ixy="0.0" ixz="0.0" iyy="1.0e-6" iyz="0.0" izz="1.0e-6"/>
    </inertial>
  </link>
  <link name="yumi_robr_base_link">
    <inertial>
      <!-- Mass -->
      <mass value="1.0e-5"/>
      <!-- Inertia -->
      <inertia ixx="1.0e-6" ixy="0.0" ixz="0.0" iyy="1.0e-6" iyz="0.0" izz="1.0e-6"/>
    </inertial>
  </link>
  <link name="yumi_robr_link_1">
    <visual>
      <!-- Origin -->
      <origin rpy="0 0 0" xyz="0.0 0.0 0.0"/>
      <geometry>
        <mesh filename="package://abb_mp_irb14000_description/meshes/irb14000_05_50/visual/robr_link_1.stl"/>
      </geometry>
      <material name="light_grey">
        <color rgba="0.6 0.6 0.6 1.0"/>
      </material>
    </visual>
    <collision>
      <!-- Origin -->
      <origin rpy="0 0 0" xyz="0.0 0.0 0.0"/>
      <geometry>
        <mesh filename="package://abb_mp_irb14000_description/meshes/irb14000_05_50/collision/robr_link_1.stl"/>
      </geometry>
    </collision>
    <inertial>
      <!-- Origin -->
      <origin rpy="0.0 0.0 0.0" xyz="0.0 0.0 0.0"/>
      <!-- Mass -->
      <mass value="1e-05"/>
      <inertia ixx="1e-06" ixy="0.0" ixz="0.0" iyy="1e-06" iyz="0.0" izz="1e-06"/>
    </inertial>
  </link>
  <link name="yumi_robr_link_2">
    <visual>
      <!-- Origin -->
      <origin rpy="0.0 0.0 0.0" xyz="0.0 0.0 0.0"/>
      <geometry>
        <mesh filename="package://abb_mp_irb14000_description/meshes/irb14000_05_50/visual/robr_link_2.stl"/>
      </geometry>
      <material name="light_grey">
        <color rgba="0.6 0.6 0.6 1.0"/>
      </material>
    </visual>
    <collision>
      <!-- Origin -->
      <origin rpy="0.0 0.0 0.0" xyz="0.0 0.0 0.0"/>
      <geometry>
        <mesh filename="package://abb_mp_irb14000_description/meshes/irb14000_05_50/collision/robr_link_2.stl"/>
      </geometry>
    </collision>
    <inertial>
      <!-- Origin -->
      <origin rpy="0.0 0.0 0.0" xyz="0.0 0.0 0.0"/>
      <!-- Mass -->
      <mass value="1e-05"/>
      <inertia ixx="1e-06" ixy="0.0" ixz="0.0" iyy="1e-06" iyz="0.0" izz="1e-06"/>
    </inertial>
  </link>
  <link name="yumi_robr_link_3">
    <visual>
      <!-- Origin -->
      <origin rpy="0.0 0.0 0.0" xyz="0.0 0.0 0.0"/>
      <geometry>
        <mesh filename="package://abb_mp_irb14000_description/meshes/irb14000_05_50/visual/robr_link_3.stl"/>
      </geometry>
      <material name="light_grey">
        <color rgba="0.6 0.6 0.6 1.0"/>
      </material>
    </visual>
    <collision>
      <!-- Origin -->
      <origin rpy="0.0 0.0 0.0" xyz="0.0 0.0 0.0"/>
      <geometry>
        <mesh filename="package://abb_mp_irb14000_description/meshes/irb14000_05_50/collision/robr_link_3.stl"/>
      </geometry>
    </collision>
    <inertial>
      <!-- Origin -->
      <origin rpy="0.0 0.0 0.0" xyz="0.0 0.0 0.0"/>
      <!-- Mass -->
      <mass value="1e-05"/>
      <inertia ixx="1e-06" ixy="0.0" ixz="0.0" iyy="1e-06" iyz="0.0" izz="1e-06"/>
    </inertial>
  </link>
  <link name="yumi_robr_link_4">
    <visual>
      <!-- Origin -->
      <origin rpy="0.0 0.0 0.0" xyz="0.0 0.0 0.0"/>
      <geometry>
        <mesh filename="package://abb_mp_irb14000_description/meshes/irb14000_05_50/visual/robr_link_4.stl"/>
      </geometry>
      <material name="light_grey">
        <color rgba="0.6 0.6 0.6 1.0"/>
      </material>
    </visual>
    <collision>
      <!-- Origin -->
      <origin rpy="0.0 0.0 0.0" xyz="0.0 0.0 0.0"/>
      <geometry>
        <mesh filename="package://abb_mp_irb14000_description/meshes/irb14000_05_50/collision/robr_link_4.stl"/>
      </geometry>
    </collision>
    <inertial>
      <!-- Origin -->
      <origin rpy="0.0 0.0 0.0" xyz="0.0 0.0 0.0"/>
      <!-- Mass -->
      <mass value="1e-05"/>
      <inertia ixx="1e-06" ixy="0.0" ixz="0.0" iyy="1e-06" iyz="0.0" izz="1e-06"/>
    </inertial>
  </link>
  <link name="yumi_robr_link_5">
    <visual>
      <!-- Origin -->
      <origin rpy="0.0 0.0 0.0" xyz="0.0 0.0 0.0"/>
      <geometry>
        <mesh filename="package://abb_mp_irb14000_description/meshes/irb14000_05_50/visual/robr_link_5.stl"/>
      </geometry>
      <material name="light_grey">
        <color rgba="0.6 0.6 0.6 1.0"/>
      </material>
    </visual>
    <collision>
      <!-- Origin -->
      <origin rpy="0.0 0.0 0.0" xyz="0.0 0.0 0.0"/>
      <geometry>
        <mesh filename="package://abb_mp_irb14000_description/meshes/irb14000_05_50/collision/robr_link_5.stl"/>
      </geometry>
    </collision>
    <inertial>
      <!-- Origin -->
      <origin rpy="0.0 0.0 0.0" xyz="0.0 0.0 0.0"/>
      <!-- Mass -->
      <mass value="1e-05"/>
      <inertia ixx="1e-06" ixy="0.0" ixz="0.0" iyy="1e-06" iyz="0.0" izz="1e-06"/>
    </inertial>
  </link>
  <link name="yumi_robr_link_6">
    <visual>
      <!-- Origin -->
      <origin rpy="0.0 0.0 0.0" xyz="0.0 0.0 0.0"/>
      <geometry>
        <mesh filename="package://abb_mp_irb14000_description/meshes/irb14000_05_50/visual/robr_link_6.stl"/>
      </geometry>
      <material name="light_grey">
        <color rgba="0.6 0.6 0.6 1.0"/>
      </material>
    </visual>
    <collision>
      <!-- Origin -->
      <origin rpy="0.0 0.0 0.0" xyz="0.0 0.0 0.0"/>
      <geometry>
        <mesh filename="package://abb_mp_irb14000_description/meshes/irb14000_05_50/collision/robr_link_6.stl"/>
      </geometry>
    </collision>
    <inertial>
      <!-- Origin -->
      <origin rpy="0.0 0.0 0.0" xyz="0.0 0.0 0.0"/>
      <!-- Mass -->
      <mass value="1e-05"/>
      <inertia ixx="1e-06" ixy="0.0" ixz="0.0" iyy="1e-06" iyz="0.0" izz="1e-06"/>
    </inertial>
  </link>
  <link name="yumi_robr_link_7">
    <visual>
      <!-- Origin -->
      <origin rpy="0.0 0.0 0.0" xyz="0.0 0.0 0.0"/>
      <geometry>
        <mesh filename="package://abb_mp_irb14000_description/meshes/irb14000_05_50/visual/robr_link_7.stl"/>
      </geometry>
      <material name="light_grey">
        <color rgba="0.6 0.6 0.6 1.0"/>
      </material>
    </visual>
    <collision>
      <!-- Origin -->
      <origin rpy="0.0 0.0 0.0" xyz="0.0 0.0 0.0"/>
      <geometry>
        <mesh filename="package://abb_mp_irb14000_description/meshes/irb14000_05_50/collision/robr_link_7.stl"/>
      </geometry>
    </collision>
    <inertial>
      <!-- Origin -->
      <origin rpy="0.0 0.0 0.0" xyz="0.0 0.0 0.0"/>
      <!-- Mass -->
      <mass value="1e-05"/>
      <inertia ixx="1e-06" ixy="0.0" ixz="0.0" iyy="1e-06" iyz="0.0" izz="1e-06"/>
    </inertial>
  </link>
  <link name="yumi_robr_flange">
    <inertial>
      <!-- Mass -->
      <mass value="1.0e-5"/>
      <!-- Inertia -->
      <inertia ixx="1.0e-6" ixy="0.0" ixz="0.0" iyy="1.0e-6" iyz="0.0" izz="1.0e-6"/>
    </inertial>
  </link>
  <link name="yumi_robr_tool0">
    <inertial>
      <!-- Mass -->
      <mass value="1.0e-5"/>
      <!-- Inertia -->
      <inertia ixx="1.0e-6" ixy="0.0" ixz="0.0" iyy="1.0e-6" iyz="0.0" izz="1.0e-6"/>
    </inertial>
  </link>
  <joint name="yumi_base_joint" type="fixed">
    <!-- Parent and child -->
    <parent link="yumi_base_link"/>
    <child link="yumi_base"/>
    <!-- Origin -->
    <origin rpy="0.0 0.0 0.0" xyz="0.0 0.0 0.0"/>
  </joint>
  <joint name="yumi_robl_base_joint" type="fixed">
    <!-- Parent and child -->
    <parent link="yumi_base_link"/>
    <child link="yumi_robl_base_link"/>
    <!-- Origin -->
    <origin rpy="-0.9790776874284967 0.5692108630372542 -0.82541439274" xyz="0.047607 0.070008 0.411486"/>
  </joint>
  <joint name="yumi_robl_joint_1" type="revolute">
    <!-- Parent and child -->
    <parent link="yumi_robl_base_link"/>
    <child link="yumi_robl_link_1"/>
    <!-- Origin -->
    <origin rpy="0.0 0.0 0.0" xyz="0 0 0"/>
    <axis xyz="0 0 1"/>
    <limit effort="0.0" lower="-2.9408797896104453" upper="2.9408797896104453" velocity="3.141592653589793"/>
    <dynamics damping="0.0" friction="0.0"/>
  </joint>
  <joint name="yumi_robl_joint_2" type="revolute">
    <!-- Parent and child -->
    <parent link="yumi_robl_link_1"/>
    <child link="yumi_robl_link_2"/>
    <!-- Origin -->
    <origin rpy="0.0 0.0 0.0" xyz="-0.03 0.0 0.1075"/>
    <axis xyz="0 1 0"/>
    <limit effort="0.0" lower="-2.504547476611863" upper="0.7592182246175333" velocity="3.141592653589793"/>
    <dynamics damping="0.0" friction="0.0"/>
  </joint>
  <joint name="yumi_robl_joint_3" type="revolute">
    <!-- Parent and child -->
    <parent link="yumi_robl_link_2"/>
    <child link="yumi_robl_link_3"/>
    <!-- Origin -->
    <origin rpy="0.0 0.0 0.0" xyz="0.03 0 0.1603"/>
    <axis xyz="0 0 1"/>
    <limit effort="0.0" lower="-2.9408797896104453" upper="2.9408797896104453" velocity="3.141592653589793"/>
    <dynamics damping="0.0" friction="0.0"/>
  </joint>
  <joint name="yumi_robl_joint_4" type="revolute">
    <!-- Parent and child -->
    <parent link="yumi_robl_link_3"/>
    <child link="yumi_robl_link_4"/>
    <!-- Origin -->
    <origin rpy="0.0 0.0 0.0" xyz="0.0405 0 0.0912"/>
    <axis xyz="0 1 0"/>
    <limit effort="0.0" lower="-2.155481626212997" upper="1.3962634015954636" velocity="3.141592653589793"/>
    <dynamics damping="0.0" friction="0.0"/>
  </joint>
  <joint name="yumi_robl_joint_5" type="revolute">
    <!-- Parent and child -->
    <parent link="yumi_robl_link_4"/>
    <child link="yumi_robl_link_5"/>
    <!-- Origin -->
    <origin rpy="0.0 0.0 0.0" xyz="0.1396 0 0.0405"/>
    <axis xyz="1 0 0"/>
    <limit effort="0.0" lower="-5.061454830783556" upper="5.061454830783556" velocity="6.981317007977318"/>
    <dynamics damping="0.0" friction="0.0"/>
  </joint>
  <joint name="yumi_robl_joint_6" type="revolute">
    <!-- Parent and child -->
    <parent link="yumi_robl_link_5"/>
    <child link="yumi_robl_link_6"/>
    <!-- Origin -->
    <origin rpy="0.0 0.0 0.0" xyz="0.1254 0 -0.027"/>
    <axis xyz="0 1 0"/>
    <limit effort="0.0" lower="-1.53588974175501" upper="2.4085543677521746" velocity="6.981317007977318"/>
    <dynamics damping="0.0" friction="0.0"/>
  </joint>
  <joint name="yumi_robl_joint_7" type="revolute">
    <!-- Parent and child -->
    <parent link="yumi_robl_link_6"/>
    <child link="yumi_robl_link_7"/>
    <!-- Origin -->
    <origin rpy="0.0 0.0 0.0" xyz="0.036 0 0.027"/>
    <axis xyz="1 0 0"/>
    <limit effort="0.0" lower="-3.9968039870670147" upper="3.9968039870670147" velocity="6.981317007977318"/>
    <dynamics damping="0.0" friction="0.0"/>
  </joint>
  <joint name="yumi_robl_joint_7_flange" type="fixed">
    <!-- Parent and ch2.316171656696717 -0.5692108630372542 0.9790776874284967ild -->
    <parent link="yumi_robl_link_7"/>
    <child link="yumi_robl_flange"/>
    <!-- Origin -->
    <origin rpy="0 0 0" xyz="0 0 0"/>
  </joint>
  <joint name="yumi_robl_flange_tool0" type="fixed">
    <!-- Parent and child -->
    <parent link="yumi_robl_flange"/>
    <child link="yumi_robl_tool0"/>
    <!-- Origin -->
    <origin rpy="0.0 1.5707963267948966 0.0" xyz="0.0 0.0 0.0"/>
  </joint>
  <joint name="yumi_robr_base_joint" type="fixed">
    <!-- Parent and child -->
    <parent link="yumi_base_link"/>
    <child link="yumi_robr_base_link"/>
    <!-- Origin -->
    <origin rpy="0.9790776874284967 0.5692108630372542 0.82541439274" xyz="0.047607 -0.070008 0.411486"/>
  </joint>
  <joint name="yumi_robr_joint_1" type="revolute">
    <!-- Parent and child -->
    <parent link="yumi_robr_base_link"/>
    <child link="yumi_robr_link_1"/>
    <!-- Origin -->
    <origin rpy="0.0 0.0 0.0" xyz="0 0 0"/>
    <axis xyz="0 0 1"/>
    <limit effort="0.0" lower="-2.9408797896104453" upper="2.9408797896104453" velocity="3.141592653589793"/>
    <dynamics damping="0.0" friction="0.0"/>
  </joint>
  <joint name="yumi_robr_joint_2" type="revolute">
    <!-- Parent and child -->
    <parent link="yumi_robr_link_1"/>
    <child link="yumi_robr_link_2"/>
    <!-- Origin -->
    <origin rpy="0.0 0.0 0.0" xyz="-0.03 0.0 0.1075"/>
    <axis xyz="0 1 0"/>
    <limit effort="0.0" lower="-2.504547476611863" upper="0.7592182246175333" velocity="3.141592653589793"/>
    <dynamics damping="0.0" friction="0.0"/>
  </joint>

  <joint name="yumi_robr_joint_3" type="revolute">
    <!-- Parent and child -->
    <parent link="yumi_robr_link_2"/>
    <child link="yumi_robr_link_3"/>
    <!-- Origin -->
    <origin rpy="0.0 0.0 0.0" xyz="0.03 0 0.1603"/>
    <axis xyz="0 0 1"/>
    <limit effort="0.0" lower="-2.9408797896104453" upper="2.9408797896104453" velocity="3.141592653589793"/>
    <dynamics damping="0.0" friction="0.0"/>
  </joint>

  <joint name="yumi_robr_joint_4" type="revolute">
    <!-- Parent and child -->
    <parent link="yumi_robr_link_3"/>
    <child link="yumi_robr_link_4"/>
    <!-- Origin -->
    <origin rpy="0.0 0.0 0.0" xyz="0.0405 0 0.0912"/>
    <axis xyz="0 1 0"/>
    <limit effort="0.0" lower="-2.155481626212997" upper="1.3962634015954636" velocity="3.141592653589793"/>
    <dynamics damping="0.0" friction="0.0"/>
  </joint>

  <joint name="yumi_robr_joint_5" type="revolute">
    <!-- Parent and child -->
    <parent link="yumi_robr_link_4"/>
    <child link="yumi_robr_link_5"/>
    <!-- Origin -->
    <origin rpy="0.0 0.0 0.0" xyz="0.1396 0 0.0405"/>
    <axis xyz="1 0 0"/>
    <limit effort="0.0" lower="-5.061454830783556" upper="5.061454830783556" velocity="6.981317007977318"/>
    <dynamics damping="0.0" friction="0.0"/>
  </joint>
  <joint name="yumi_robr_joint_6" type="revolute">
    <!-- Parent and child -->
    <parent link="yumi_robr_link_5"/>
    <child link="yumi_robr_link_6"/>
    <!-- Origin -->
    <origin rpy="0.0 0.0 0.0" xyz="0.1254 0 -0.027"/>
    <axis xyz="0 1 0"/>
    <limit effort="0.0" lower="-1.53588974175501" upper="2.4085543677521746" velocity="6.981317007977318"/>
    <dynamics damping="0.0" friction="0.0"/>
  </joint>
  <joint name="yumi_robr_joint_7" type="revolute">
    <!-- Parent and child -->
    <parent link="yumi_robr_link_6"/>
    <child link="yumi_robr_link_7"/>
    <!-- Origin -->
    <origin rpy="0.0 0.0 0.0" xyz="0.036 0 0.027"/>
    <axis xyz="1 0 0"/>
    <limit effort="0.0" lower="-3.9968039870670147" upper="3.9968039870670147" velocity="6.981317007977318"/>
    <dynamics damping="0.0" friction="0.0"/>
  </joint>
  <joint name="yumi_robr_joint_7_flange" type="fixed">
    <!-- Parent and child -->
    <parent link="yumi_robr_link_7"/>
    <child link="yumi_robr_flange"/>
    <!-- Origin -->
    <origin rpy="0 0 0" xyz="0 0 0"/>
  </joint>
  <joint name="yumi_robr_flange_tool0" type="fixed">
    <!-- Parent and child -->
    <parent link="yumi_robr_flange"/>
    <child link="yumi_robr_tool0"/>
    <!-- Origin -->
    <origin rpy="0.0 1.5707963267948966 0.0" xyz="0.0 0.0 0.0"/>
  </joint>
  <transmission name="yumi_robl_transmission_1">
    <type>transmission_interface/SimpleTransmission</type>
    <joint name="yumi_robl_joint_1">
      <hardwareInterface>hardware_interface/PositionJointInterface</hardwareInterface>
    </joint>
    <actuator name="yumi_robl_joint_1_motor">
      <mechanicalReduction>1.0</mechanicalReduction>
    </actuator>
  </transmission>
  <transmission name="yumi_robl_transmission_2">
    <type>transmission_interface/SimpleTransmission</type>
    <joint name="yumi_robl_joint_2">
      <hardwareInterface>hardware_interface/PositionJointInterface</hardwareInterface>
    </joint>
    <actuator name="yumi_robl_joint_2_motor">
      <mechanicalReduction>1.0</mechanicalReduction>
    </actuator>
  </transmission>
  <transmission name="yumi_robl_transmission_3">
    <type>transmission_interface/SimpleTransmission</type>
    <joint name="yumi_robl_joint_3">
      <hardwareInterface>hardware_interface/PositionJointInterface</hardwareInterface>
    </joint>
    <actuator name="yumi_robl_joint_3_motor">
      <mechanicalReduction>1.0</mechanicalReduction>
    </actuator>
  </transmission>
  <transmission name="yumi_robl_transmission_4">
    <type>transmission_interface/SimpleTransmission</type>
    <joint name="yumi_robl_joint_4">
      <hardwareInterface>hardware_interface/PositionJointInterface</hardwareInterface>
    </joint>
    <actuator name="yumi_robl_joint_4_motor">
      <mechanicalReduction>1.0</mechanicalReduction>
    </actuator>
  </transmission>
  <transmission name="yumi_robl_transmission_5">
    <type>transmission_interface/SimpleTransmission</type>
    <joint name="yumi_robl_joint_5">
      <hardwareInterface>hardware_interface/PositionJointInterface</hardwareInterface>
    </joint>
    <actuator name="yumi_robl_joint_5_motor">
      <mechanicalReduction>1.0</mechanicalReduction>
    </actuator>
  </transmission>
  <transmission name="yumi_robl_transmission_6">
    <type>transmission_interface/SimpleTransmission</type>
    <joint name="yumi_robl_joint_6">
      <hardwareInterface>hardware_interface/PositionJointInterface</hardwareInterface>
    </joint>
    <actuator name="yumi_robl_joint_6_motor">
      <mechanicalReduction>1.0</mechanicalReduction>
    </actuator>
  </transmission>
  <transmission name="yumi_robl_transmission_7">
    <type>transmission_interface/SimpleTransmission</type>
    <joint name="yumi_robl_joint_7">
      <hardwareInterface>hardware_interface/PositionJointInterface</hardwareInterface>
    </joint>
    <actuator name="yumi_robl_joint_7_motor">
      <mechanicalReduction>1.0</mechanicalReduction>
    </actuator>
  </transmission>
  <transmission name="yumi_robr_transmission_1">
    <type>transmission_interface/SimpleTransmission</type>
    <joint name="yumi_robr_joint_1">
      <hardwareInterface>hardware_interface/PositionJointInterface</hardwareInterface>
    </joint>
    <actuator name="yumi_robr_joint_1_motor">
      <mechanicalReduction>1.0</mechanicalReduction>
    </actuator>
  </transmission>
  <transmission name="yumi_robr_transmission_2">
    <type>transmission_interface/SimpleTransmission</type>
    <joint name="yumi_robr_joint_2">
      <hardwareInterface>hardware_interface/PositionJointInterface</hardwareInterface>
    </joint>
    <actuator name="yumi_robr_joint_2_motor">
      <mechanicalReduction>1.0</mechanicalReduction>
    </actuator>
  </transmission>
  <transmission name="yumi_robr_transmission_3">
    <type>transmission_interface/SimpleTransmission</type>
    <joint name="yumi_robr_joint_3">
      <hardwareInterface>hardware_interface/PositionJointInterface</hardwareInterface>
    </joint>
    <actuator name="yumi_robr_joint_3_motor">
      <mechanicalReduction>1.0</mechanicalReduction>
    </actuator>
  </transmission>
  <transmission name="yumi_robr_transmission_4">
    <type>transmission_interface/SimpleTransmission</type>
    <joint name="yumi_robr_joint_4">
      <hardwareInterface>hardware_interface/PositionJointInterface</hardwareInterface>
    </joint>
    <actuator name="yumi_robr_joint_4_motor">
      <mechanicalReduction>1.0</mechanicalReduction>
    </actuator>
  </transmission>
  <transmission name="yumi_robr_transmission_5">
    <type>transmission_interface/SimpleTransmission</type>
    <joint name="yumi_robr_joint_5">
      <hardwareInterface>hardware_interface/PositionJointInterface</hardwareInterface>
    </joint>
    <actuator name="yumi_robr_joint_5_motor">
      <mechanicalReduction>1.0</mechanicalReduction>
    </actuator>
  </transmission>
  <transmission name="yumi_robr_transmission_6">
    <type>transmission_interface/SimpleTransmission</type>
    <joint name="yumi_robr_joint_6">
      <hardwareInterface>hardware_interface/PositionJointInterface</hardwareInterface>
    </joint>
    <actuator name="yumi_robr_joint_6_motor">
      <mechanicalReduction>1.0</mechanicalReduction>
    </actuator>
  </transmission>
  <transmission name="yumi_robr_transmission_7">
    <type>transmission_interface/SimpleTransmission</type>
    <joint name="yumi_robr_joint_7">
      <hardwareInterface>hardware_interface/PositionJointInterface</hardwareInterface>
    </joint>
    <actuator name="yumi_robr_joint_7_motor">
      <mechanicalReduction>1.0</mechanicalReduction>
    </actuator>
  </transmission>
  <gazebo reference="yumi_base_link">
    <material>Gazebo/White</material>
  </gazebo>
  <gazebo reference="yumi_robl_link_1">
    <turnGravityOff>True</turnGravityOff>
  </gazebo>
  <gazebo reference="yumi_robl_link_2">
    <turnGravityOff>True</turnGravityOff>
  </gazebo>
  <gazebo reference="yumi_robl_link_3">
    <turnGravityOff>True</turnGravityOff>
  </gazebo>
  <gazebo reference="yumi_robl_link_4">
    <turnGravityOff>True</turnGravityOff>
  </gazebo>
  <gazebo reference="yumi_robl_link_5">
    <turnGravityOff>True</turnGravityOff>
  </gazebo>
  <gazebo reference="yumi_robl_link_6">
    <turnGravityOff>True</turnGravityOff>
  </gazebo>
  <gazebo reference="yumi_robl_link_7">
    <turnGravityOff>True</turnGravityOff>
  </gazebo>
  <gazebo reference="yumi_robr_link_1">
    <turnGravityOff>True</turnGravityOff>
  </gazebo>
  <gazebo reference="yumi_robr_link_2">
    <turnGravityOff>True</turnGravityOff>
  </gazebo>
  <gazebo reference="yumi_robr_link_3">
    <turnGravityOff>True</turnGravityOff>
  </gazebo>
  <gazebo reference="yumi_robr_link_4">
    <turnGravityOff>True</turnGravityOff>
  </gazebo>
  <gazebo reference="yumi_robr_link_5">
    <turnGravityOff>True</turnGravityOff>
  </gazebo>
  <gazebo reference="yumi_robr_link_6">
    <turnGravityOff>True</turnGravityOff>
  </gazebo>
  <gazebo reference="yumi_robr_link_7">
    <turnGravityOff>True</turnGravityOff>
  </gazebo>
  <joint name="pillar_yumi_joint" type="fixed">
    <!-- Parent and child -->
    <parent link="pillar_top_link"/>
    <child link="yumi_base_link"/>
    <!-- Origin -->
    <origin rpy="0.0 0.0 0.0" xyz="0.234995 0.0 -0.108"/>
  </joint>
  <!-- ============================================== Include Macros =============================================== -->
  <!-- ================================================ Main Macros ================================================ -->
  <!-- ============================================== Support Macros =============================================== -->
  <!-- ================================================ Main Macros ================================================ -->
  <!-- ============================================== Support Macros =============================================== -->
  <!-- ================================================ Main Macros ================================================ -->
  <!-- ================================================ Main Macros ================================================ -->
  <!-- ============================================== Support Macros =============================================== -->
  <!-- ================================================ Main Macros ================================================ -->
  <!-- ================================================ Main Macros ================================================ -->
  <!-- ================================================ Main Macros ================================================ -->
  <!-- ============================================== Support Macros =============================================== -->
  <link name="yumi_robl_sg_base_link">
    <visual>
      <!-- Origin -->
      <origin rpy="0.0 0.0 0.0" xyz="0.0 0.0 0.0"/>
      <geometry>
        <mesh filename="package://abb_mp_smart_gripper_description/meshes/sg/visual/base_link.dae"/>
      </geometry>
      <material name="light_grey">
        <color rgba="0.6 0.6 0.6 1.0"/>
      </material>
    </visual>
    <collision>
      <!-- Origin -->
      <origin rpy="0.0 0.0 0.0" xyz="0.0 0.0 0.0"/>
      <geometry>
        <mesh filename="package://abb_mp_smart_gripper_description/meshes/sg/collision/base_link.stl"/>
      </geometry>
    </collision>
    <inertial>
      <!-- Origin -->
      <origin rpy="0.0 0.0 0.0" xyz="0.0 0.0 0.0"/>
      <!-- Mass -->
      <mass value="1e-05"/>
      <inertia ixx="1e-06" ixy="0.0" ixz="0.0" iyy="1e-06" iyz="0.0" izz="1e-06"/>
    </inertial>
  </link>
  <link name="yumi_robl_sg_servo_frame_link">
    <inertial>
      <!-- Mass -->
      <mass value="1.0e-5"/>
      <!-- Inertia -->
      <inertia ixx="1.0e-6" ixy="0.0" ixz="0.0" iyy="1.0e-6" iyz="0.0" izz="1.0e-6"/>
    </inertial>
  </link>
  <link name="yumi_robl_sg_fingers_frame_link">
    <inertial>
      <!-- Mass -->
      <mass value="1.0e-5"/>
      <!-- Inertia -->
      <inertia ixx="1.0e-6" ixy="0.0" ixz="0.0" iyy="1.0e-6" iyz="0.0" izz="1.0e-6"/>
    </inertial>
  </link>
  <link name="yumi_robl_sg_vacuum_1_frame_link">
    <inertial>
      <!-- Mass -->
      <mass value="1.0e-5"/>
      <!-- Inertia -->
      <inertia ixx="1.0e-6" ixy="0.0" ixz="0.0" iyy="1.0e-6" iyz="0.0" izz="1.0e-6"/>
    </inertial>
  </link>
  <link name="yumi_robl_sg_vacuum_2_frame_link">
    <inertial>
      <!-- Mass -->
      <mass value="1.0e-5"/>
      <!-- Inertia -->
      <inertia ixx="1.0e-6" ixy="0.0" ixz="0.0" iyy="1.0e-6" iyz="0.0" izz="1.0e-6"/>
    </inertial>
  </link>
  <link name="yumi_robl_sg_camera_frame_link">
    <inertial>
      <!-- Mass -->
      <mass value="1.0e-5"/>
      <!-- Inertia -->
      <inertia ixx="1.0e-6" ixy="0.0" ixz="0.0" iyy="1.0e-6" iyz="0.0" izz="1.0e-6"/>
    </inertial>
  </link>
  <link name="yumi_robl_sg_finger_1_base_link">
    <visual>
      <!-- Origin -->
      <origin rpy="0.0 0.0 0.0" xyz="0.0 0.0 0.0"/>
      <geometry>
        <mesh filename="package://abb_mp_smart_gripper_description/meshes/sg/visual/finger_1_base_link.dae"/>
      </geometry>
      <material name="light_grey">
        <color rgba="0.6 0.6 0.6 1.0"/>
      </material>
    </visual>
    <collision>
      <!-- Origin -->
      <origin rpy="0.0 0.0 0.0" xyz="0.0 0.0 0.0"/>
      <geometry>
        <mesh filename="package://abb_mp_smart_gripper_description/meshes/sg/collision/finger_1_base_link.stl"/>
      </geometry>
    </collision>
    <inertial>
      <!-- Origin -->
      <origin rpy="0.0 0.0 0.0" xyz="0.0 0.0 0.0"/>
      <!-- Mass -->
      <mass value="1e-05"/>
      <inertia ixx="1e-06" ixy="0.0" ixz="0.0" iyy="1e-06" iyz="0.0" izz="1e-06"/>
    </inertial>
  </link>
  <link name="yumi_robl_sg_finger_2_base_link">
    <visual>
      <!-- Origin -->
      <origin rpy="0.0 0.0 0.0" xyz="0.0 0.0 0.0"/>
      <geometry>
        <mesh filename="package://abb_mp_smart_gripper_description/meshes/sg/visual/finger_2_base_link.dae"/>
      </geometry>
      <material name="light_grey">
        <color rgba="0.6 0.6 0.6 1.0"/>
      </material>
    </visual>
    <collision>
      <!-- Origin -->
      <origin rpy="0.0 0.0 0.0" xyz="0.0 0.0 0.0"/>
      <geometry>
        <mesh filename="package://abb_mp_smart_gripper_description/meshes/sg/collision/finger_2_base_link.stl"/>
      </geometry>
    </collision>
    <inertial>
      <!-- Origin -->
      <origin rpy="0.0 0.0 0.0" xyz="0.0 0.0 0.0"/>
      <!-- Mass -->
      <mass value="1e-05"/>
      <inertia ixx="1e-06" ixy="0.0" ixz="0.0" iyy="1e-06" iyz="0.0" izz="1e-06"/>
    </inertial>
  </link>
  <link name="yumi_robl_sg_finger_1_link">
    <visual>
      <!-- Origin -->
      <origin rpy="0.0 0.0 0.0" xyz="0.0125 -0.0065 -0.0837"/>
      <geometry>
        <mesh filename="package://abb_mp_smart_gripper_description/meshes/sg/visual/finger_1_link.dae"/>
      </geometry>
      <material name="light_grey">
        <color rgba="0.6 0.6 0.6 1.0"/>
      </material>
    </visual>
    <collision>
      <!-- Origin -->
      <origin rpy="0.0 0.0 0.0" xyz="0.0125 -0.0065 -0.0837"/>
      <geometry>
        <mesh filename="package://abb_mp_smart_gripper_description/meshes/sg/collision/finger_1_link.stl"/>
      </geometry>
    </collision>
    <inertial>
      <!-- Origin -->
      <origin rpy="0.0 0.0 0.0" xyz="0.0 0.0 0.0"/>
      <!-- Mass -->
      <mass value="1e-05"/>
      <inertia ixx="1e-06" ixy="0.0" ixz="0.0" iyy="1e-06" iyz="0.0" izz="1e-06"/>
    </inertial>
  </link>
  <link name="yumi_robl_sg_finger_2_link">
    <visual>
      <!-- Origin -->
      <origin rpy="0.0 0.0 0.0" xyz="-0.0125 0.0065 -0.0837"/>
      <geometry>
        <mesh filename="package://abb_mp_smart_gripper_description/meshes/sg/visual/finger_2_link.dae"/>
      </geometry>
      <material name="light_grey">
        <color rgba="0.6 0.6 0.6 1.0"/>
      </material>
    </visual>
    <collision>
      <!-- Origin -->
      <origin rpy="0.0 0.0 0.0" xyz="-0.0125 0.0065 -0.0837"/>
      <geometry>
        <mesh filename="package://abb_mp_smart_gripper_description/meshes/sg/collision/finger_2_link.stl"/>
      </geometry>
    </collision>
    <inertial>
      <!-- Origin -->
      <origin rpy="0.0 0.0 0.0" xyz="0.0 0.0 0.0"/>
      <!-- Mass -->
      <mass value="1e-05"/>
      <inertia ixx="1e-06" ixy="0.0" ixz="0.0" iyy="1e-06" iyz="0.0" izz="1e-06"/>
    </inertial>
  </link>
  <joint name="yumi_robl_sg_servo_frame_joint" type="fixed">
    <!-- Parent and child -->
    <parent link="yumi_robl_sg_base_link"/>
    <child link="yumi_robl_sg_servo_frame_link"/>
    <!-- Origin -->
    <origin rpy="0.0 0.0 0.0" xyz="0.0 0.0 0.084"/>
  </joint>
  <joint name="yumi_robl_sg_fingers_frame_joint" type="fixed">
    <!-- Parent and child -->
    <parent link="yumi_robl_sg_base_link"/>
    <child link="yumi_robl_sg_fingers_frame_link"/>
    <!-- Origin -->
    <origin rpy="0.0 0.0 0.0" xyz="0.0 0.0 0.1142"/>
  </joint>
  <joint name="yumi_robl_sg_vacuum_1_frame_joint" type="fixed">
    <!-- Parent and child -->
    <parent link="yumi_robl_sg_base_link"/>
    <child link="yumi_robl_sg_vacuum_1_frame_link"/>
    <!-- Origin -->
    <origin rpy="0.0 1.5707963267948966 0.0" xyz="0.0274 0.0185 0.0375"/>
  </joint>
  <joint name="yumi_robl_sg_vacuum_2_frame_joint" type="fixed">
    <!-- Parent and child -->
    <parent link="yumi_robl_sg_base_link"/>
    <child link="yumi_robl_sg_vacuum_2_frame_link"/>
    <!-- Origin -->
    <origin rpy="-3.141592653589793 1.5707963267948966 0.0" xyz="-0.0274 0.0185 0.0375"/>
  </joint>
  <joint name="yumi_robl_sg_camera_frame_joint" type="fixed">
    <!-- Parent and child -->
    <parent link="yumi_robl_sg_base_link"/>
    <child link="yumi_robl_sg_camera_frame_link"/>
    <!-- Origin -->
    <origin rpy="-1.5707963267948966 1.5707963267948966 0.0" xyz="-0.0073 0.0283 0.0351"/>
  </joint>
  <joint name="yumi_robl_sg_finger_1_base_joint" type="fixed">
    <!-- Parent and child -->
    <parent link="yumi_robl_sg_base_link"/>
    <child link="yumi_robl_sg_finger_1_base_link"/>
    <!-- Origin -->
    <origin rpy="0.0 0.0 0.0" xyz="-0.0125 0.0065 0.084"/>
    <axis xyz="1.0 0.0 0.0"/>
  </joint>
  <joint name="yumi_robl_sg_finger_2_base_joint" type="fixed">
    <!-- Parent and child -->
    <parent link="yumi_robl_sg_base_link"/>
    <child link="yumi_robl_sg_finger_2_base_link"/>
    <!-- Origin -->
    <origin rpy="0.0 0.0 0.0" xyz="0.0125 -0.0065 0.084"/>
    <axis xyz="1.0 0.0 0.0"/>
    <mimic joint="yumi_robl_sg_finger_1_base_joint" multiplier="-1.0" offset="0.0"/>
  </joint>
  <joint name="yumi_robl_sg_finger_1_joint" type="fixed">
    <!-- Parent and child -->
    <parent link="yumi_robl_sg_finger_1_base_link"/>
    <child link="yumi_robl_sg_finger_1_link"/>
    <!-- Origin -->
    <origin rpy="0.0 0.0 0.0" xyz="0.0 0.0 0.0"/>
  </joint>
  <joint name="yumi_robl_sg_finger_2_joint" type="fixed">
    <!-- Parent and child -->
    <parent link="yumi_robl_sg_finger_2_base_link"/>
    <child link="yumi_robl_sg_finger_2_link"/>
    <!-- Origin -->
    <origin rpy="0.0 0.0 0.0" xyz="0.0 0.0 0.0"/>
  </joint>
  <gazebo reference="yumi_robl_sg_base_link">
    <material>Gazebo/White</material>
    <turnGravityOff>True</turnGravityOff>
  </gazebo>
  <gazebo reference="yumi_robl_sg_finger_1_base_link">
    <material>Gazebo/White</material>
    <turnGravityOff>True</turnGravityOff>
  </gazebo>
  <gazebo reference="yumi_robl_sg_finger_2_base_link">
    <material>Gazebo/White</material>
    <turnGravityOff>True</turnGravityOff>
  </gazebo>
  <gazebo reference="yumi_robl_sg_finger_1_link">
    <material>Gazebo/Grey</material>
    <turnGravityOff>True</turnGravityOff>
  </gazebo>
  <gazebo reference="yumi_robl_sg_finger_2_link">
    <material>Gazebo/Grey</material>
    <turnGravityOff>True</turnGravityOff>
  </gazebo>
  <!-- ============================================== Include Macros =============================================== -->
  <!-- ================================================ Main Macros ================================================ -->
  <!-- ============================================== Support Macros =============================================== -->
  <!-- ================================================ Main Macros ================================================ -->
  <!-- ============================================== Support Macros =============================================== -->
  <!-- ================================================ Main Macros ================================================ -->
  <!-- ================================================ Main Macros ================================================ -->
  <!-- ============================================== Support Macros =============================================== -->
  <!-- ================================================ Main Macros ================================================ -->
  <!-- ================================================ Main Macros ================================================ -->
  <!-- ================================================ Main Macros ================================================ -->
  <!-- ============================================== Support Macros =============================================== -->
  <link name="yumi_robr_sg_base_link">
    <visual>
      <!-- Origin -->
      <origin rpy="0.0 0.0 0.0" xyz="0.0 0.0 0.0"/>
      <geometry>
        <mesh filename="package://abb_mp_smart_gripper_description/meshes/sg/visual/base_link.dae"/>
      </geometry>
      <material name="light_grey">
        <color rgba="0.6 0.6 0.6 1.0"/>
      </material>
    </visual>
    <collision>
      <!-- Origin -->
      <origin rpy="0.0 0.0 0.0" xyz="0.0 0.0 0.0"/>
      <geometry>
        <mesh filename="package://abb_mp_smart_gripper_description/meshes/sg/collision/base_link.stl"/>
      </geometry>
    </collision>
    <inertial>
      <!-- Origin -->
      <origin rpy="0.0 0.0 0.0" xyz="0.0 0.0 0.0"/>
      <!-- Mass -->
      <mass value="1e-05"/>
      <inertia ixx="1e-06" ixy="0.0" ixz="0.0" iyy="1e-06" iyz="0.0" izz="1e-06"/>
    </inertial>
  </link>
  <link name="yumi_robr_sg_servo_frame_link">
    <inertial>
      <!-- Mass -->
      <mass value="1.0e-5"/>
      <!-- Inertia -->
      <inertia ixx="1.0e-6" ixy="0.0" ixz="0.0" iyy="1.0e-6" iyz="0.0" izz="1.0e-6"/>
    </inertial>
  </link>
  <link name="yumi_robr_sg_fingers_frame_link">
    <inertial>
      <!-- Mass -->
      <mass value="1.0e-5"/>
      <!-- Inertia -->
      <inertia ixx="1.0e-6" ixy="0.0" ixz="0.0" iyy="1.0e-6" iyz="0.0" izz="1.0e-6"/>
    </inertial>
  </link>
  <link name="yumi_robr_sg_vacuum_1_frame_link">
    <inertial>
      <!-- Mass -->
      <mass value="1.0e-5"/>
      <!-- Inertia -->
      <inertia ixx="1.0e-6" ixy="0.0" ixz="0.0" iyy="1.0e-6" iyz="0.0" izz="1.0e-6"/>
    </inertial>
  </link>
  <link name="yumi_robr_sg_vacuum_2_frame_link">
    <inertial>
      <!-- Mass -->
      <mass value="1.0e-5"/>
      <!-- Inertia -->
      <inertia ixx="1.0e-6" ixy="0.0" ixz="0.0" iyy="1.0e-6" iyz="0.0" izz="1.0e-6"/>
    </inertial>
  </link>
  <link name="yumi_robr_sg_camera_frame_link">
    <inertial>
      <!-- Mass -->
      <mass value="1.0e-5"/>
      <!-- Inertia -->
      <inertia ixx="1.0e-6" ixy="0.0" ixz="0.0" iyy="1.0e-6" iyz="0.0" izz="1.0e-6"/>
    </inertial>
  </link>
  <link name="yumi_robr_sg_finger_1_base_link">
    <visual>
      <!-- Origin -->
      <origin rpy="0.0 0.0 0.0" xyz="0.0 0.0 0.0"/>
      <geometry>
        <mesh filename="package://abb_mp_smart_gripper_description/meshes/sg/visual/finger_1_base_link.dae"/>
      </geometry>
      <material name="light_grey">
        <color rgba="0.6 0.6 0.6 1.0"/>
      </material>
    </visual>
    <collision>
      <!-- Origin -->
      <origin rpy="0.0 0.0 0.0" xyz="0.0 0.0 0.0"/>
      <geometry>
        <mesh filename="package://abb_mp_smart_gripper_description/meshes/sg/collision/finger_1_base_link.stl"/>
      </geometry>
    </collision>
    <inertial>
      <!-- Origin -->
      <origin rpy="0.0 0.0 0.0" xyz="0.0 0.0 0.0"/>
      <!-- Mass -->
      <mass value="1e-05"/>
      <inertia ixx="1e-06" ixy="0.0" ixz="0.0" iyy="1e-06" iyz="0.0" izz="1e-06"/>
    </inertial>
  </link>
  <link name="yumi_robr_sg_finger_2_base_link">
    <visual>
      <!-- Origin -->
      <origin rpy="0.0 0.0 0.0" xyz="0.0 0.0 0.0"/>
      <geometry>
        <mesh filename="package://abb_mp_smart_gripper_description/meshes/sg/visual/finger_2_base_link.dae"/>
      </geometry>
      <material name="light_grey">
        <color rgba="0.6 0.6 0.6 1.0"/>
      </material>
    </visual>
    <collision>
      <!-- Origin -->
      <origin rpy="0.0 0.0 0.0" xyz="0.0 0.0 0.0"/>
      <geometry>
        <mesh filename="package://abb_mp_smart_gripper_description/meshes/sg/collision/finger_2_base_link.stl"/>
      </geometry>
    </collision>
    <inertial>
      <!-- Origin -->
      <origin rpy="0.0 0.0 0.0" xyz="0.0 0.0 0.0"/>
      <!-- Mass -->
      <mass value="1e-05"/>
      <inertia ixx="1e-06" ixy="0.0" ixz="0.0" iyy="1e-06" iyz="0.0" izz="1e-06"/>
    </inertial>
  </link>
  <link name="yumi_robr_sg_finger_1_link">
    <visual>
      <!-- Origin -->
      <origin rpy="0.0 0.0 0.0" xyz="0.0125 -0.0065 -0.0837"/>
      <geometry>
        <mesh filename="package://abb_mp_smart_gripper_description/meshes/sg/visual/finger_1_link.dae"/>
      </geometry>
      <material name="light_grey">
        <color rgba="0.6 0.6 0.6 1.0"/>
      </material>
    </visual>
    <collision>
      <!-- Origin -->
      <origin rpy="0.0 0.0 0.0" xyz="0.0125 -0.0065 -0.0837"/>
      <geometry>
        <mesh filename="package://abb_mp_smart_gripper_description/meshes/sg/collision/finger_1_link.stl"/>
      </geometry>
    </collision>
    <inertial>
      <!-- Origin -->
      <origin rpy="0.0 0.0 0.0" xyz="0.0 0.0 0.0"/>
      <!-- Mass -->
      <mass value="1e-05"/>
      <inertia ixx="1e-06" ixy="0.0" ixz="0.0" iyy="1e-06" iyz="0.0" izz="1e-06"/>
    </inertial>
  </link>
  <link name="yumi_robr_sg_finger_2_link">
    <visual>
      <!-- Origin -->
      <origin rpy="0.0 0.0 0.0" xyz="-0.0125 0.0065 -0.0837"/>
      <geometry>
        <mesh filename="package://abb_mp_smart_gripper_description/meshes/sg/visual/finger_2_link.dae"/>
      </geometry>
      <material name="light_grey">
        <color rgba="0.6 0.6 0.6 1.0"/>
      </material>
    </visual>
    <collision>
      <!-- Origin -->
      <origin rpy="0.0 0.0 0.0" xyz="-0.0125 0.0065 -0.0837"/>
      <geometry>
        <mesh filename="package://abb_mp_smart_gripper_description/meshes/sg/collision/finger_2_link.stl"/>
      </geometry>
    </collision>
    <inertial>
      <!-- Origin -->
      <origin rpy="0.0 0.0 0.0" xyz="0.0 0.0 0.0"/>
      <!-- Mass -->
      <mass value="1e-05"/>
      <inertia ixx="1e-06" ixy="0.0" ixz="0.0" iyy="1e-06" iyz="0.0" izz="1e-06"/>
    </inertial>
  </link>
  <joint name="yumi_robr_sg_servo_frame_joint" type="fixed">
    <!-- Parent and child -->
    <parent link="yumi_robr_sg_base_link"/>
    <child link="yumi_robr_sg_servo_frame_link"/>
    <!-- Origin -->
    <origin rpy="0.0 0.0 0.0" xyz="0.0 0.0 0.084"/>
  </joint>
  <joint name="yumi_robr_sg_fingers_frame_joint" type="fixed">
    <!-- Parent and child -->
    <parent link="yumi_robr_sg_base_link"/>
    <child link="yumi_robr_sg_fingers_frame_link"/>
    <!-- Origin -->
    <origin rpy="0.0 0.0 0.0" xyz="0.0 0.0 0.1142"/>
  </joint>
  <joint name="yumi_robr_sg_vacuum_1_frame_joint" type="fixed">
    <!-- Parent and child -->
    <parent link="yumi_robr_sg_base_link"/>
    <child link="yumi_robr_sg_vacuum_1_frame_link"/>
    <!-- Origin -->
    <origin rpy="0.0 1.5707963267948966 0.0" xyz="0.0274 0.0185 0.0375"/>
  </joint>
  <joint name="yumi_robr_sg_vacuum_2_frame_joint" type="fixed">
    <!-- Parent and child -->
    <parent link="yumi_robr_sg_base_link"/>
    <child link="yumi_robr_sg_vacuum_2_frame_link"/>
    <!-- Origin -->
    <origin rpy="-3.141592653589793 1.5707963267948966 0.0" xyz="-0.0274 0.0185 0.0375"/>
  </joint>
  <joint name="yumi_robr_sg_camera_frame_joint" type="fixed">
    <!-- Parent and child -->
    <parent link="yumi_robr_sg_base_link"/>
    <child link="yumi_robr_sg_camera_frame_link"/>
    <!-- Origin -->
    <origin rpy="-1.5707963267948966 1.5707963267948966 0.0" xyz="-0.0073 0.0283 0.0351"/>
  </joint>
  <joint name="yumi_robr_sg_finger_1_base_joint" type="fixed">
    <!-- Parent and child -->
    <parent link="yumi_robr_sg_base_link"/>
    <child link="yumi_robr_sg_finger_1_base_link"/>
    <!-- Origin -->
    <origin rpy="0.0 0.0 0.0" xyz="-0.0125 0.0065 0.084"/>
    <axis xyz="1.0 0.0 0.0"/>
  </joint>
  <joint name="yumi_robr_sg_finger_2_base_joint" type="fixed">
    <!-- Parent and child -->
    <parent link="yumi_robr_sg_base_link"/>
    <child link="yumi_robr_sg_finger_2_base_link"/>
    <!-- Origin -->
    <origin rpy="0.0 0.0 0.0" xyz="0.0125 -0.0065 0.084"/>
    <axis xyz="1.0 0.0 0.0"/>
    <mimic joint="yumi_robr_sg_finger_1_base_joint" multiplier="-1.0" offset="0.0"/>
  </joint>
  <joint name="yumi_robr_sg_finger_1_joint" type="fixed">
    <!-- Parent and child -->
    <parent link="yumi_robr_sg_finger_1_base_link"/>
    <child link="yumi_robr_sg_finger_1_link"/>
    <!-- Origin -->
    <origin rpy="0.0 0.0 0.0" xyz="0.0 0.0 0.0"/>
  </joint>
  <joint name="yumi_robr_sg_finger_2_joint" type="fixed">
    <!-- Parent and child -->
    <parent link="yumi_robr_sg_finger_2_base_link"/>
    <child link="yumi_robr_sg_finger_2_link"/>
    <!-- Origin -->
    <origin rpy="0.0 0.0 0.0" xyz="0.0 0.0 0.0"/>
  </joint>
  <gazebo reference="yumi_robr_sg_base_link">
    <material>Gazebo/White</material>
    <turnGravityOff>True</turnGravityOff>
  </gazebo>
  <gazebo reference="yumi_robr_sg_finger_1_base_link">
    <material>Gazebo/White</material>
    <turnGravityOff>True</turnGravityOff>
  </gazebo>
  <gazebo reference="yumi_robr_sg_finger_2_base_link">
    <material>Gazebo/White</material>
    <turnGravityOff>True</turnGravityOff>
  </gazebo>
  <gazebo reference="yumi_robr_sg_finger_1_link">
    <material>Gazebo/Grey</material>
    <turnGravityOff>True</turnGravityOff>
  </gazebo>
  <gazebo reference="yumi_robr_sg_finger_2_link">
    <material>Gazebo/Grey</material>
    <turnGravityOff>True</turnGravityOff>
  </gazebo>
  <joint name="yumi_robl_sg_joint" type="fixed">
    <!-- Parent and child -->
    <parent link="yumi_robl_tool0"/>
    <child link="yumi_robl_sg_base_link"/>
    <!-- Origin -->
    <origin rpy="0.0 0.0 0.0" xyz="0.0 0.0 0.0"/>
  </joint>
  <joint name="yumi_robr_sg_joint" type="fixed">
    <!-- Parent and child -->
    <parent link="yumi_robr_tool0"/>
    <child link="yumi_robr_sg_base_link"/>
    <!-- Origin -->
    <origin rpy="0.0 0.0 0.0" xyz="0.0 0.0 0.0"/>
  </joint>
  <!-- ============================================== Include Macros =============================================== -->
  <!-- ================================================ Main Macros ================================================ -->
  <!-- ============================================== Support Macros =============================================== -->
  <!-- ================================================ Main Macros ================================================ -->
  <!-- ============================================== Support Macros =============================================== -->
  <!-- ================================================ Main Macros ================================================ -->
  <!-- ================================================ Main Macros ================================================ -->
  <!-- ============================================== Support Macros =============================================== -->
  <!-- ================================================ Main Macros ================================================ -->
  <!-- ================================================ Main Macros ================================================ -->
  <!-- ================================================ Main Macros ================================================ -->
  <!-- ============================================== Support Macros =============================================== -->
  <link name="yumi_cs_base_link">
    <visual>
      <!-- Origin -->
      <origin rpy="0.0 0.0 0.0" xyz="0.0 0.0 0.0"/>
      <geometry>
        <mesh filename="package://abb_mp_camera_stand_description/meshes/cs_v2/visual/base_link.stl"/>
      </geometry>
      <material name="light_grey">
        <color rgba="0.6 0.6 0.6 1.0"/>
      </material>
    </visual>
    <collision>
      <!-- Origin -->
      <origin rpy="0.0 0.0 0.0" xyz="0.0 0.0 0.0"/>
      <geometry>
        <mesh filename="package://abb_mp_camera_stand_description/meshes/cs_v2/collision/base_link.stl"/>
      </geometry>
    </collision>
    <inertial>
      <!-- Origin -->
      <origin rpy="0.0 0.0 0.0" xyz="0.0 0.0 0.0"/>
      <!-- Mass -->
      <mass value="1e-05"/>
      <inertia ixx="1e-06" ixy="0.0" ixz="0.0" iyy="1e-06" iyz="0.0" izz="1e-06"/>
    </inertial>
  </link>
  <link name="yumi_cs_plate_link">
    <visual>
      <!-- Origin -->
      <origin rpy="0.0 0.0 0.0" xyz="0.0 0.0 0.0"/>
      <geometry>
        <mesh filename="package://abb_mp_camera_stand_description/meshes/cs_v2/visual/plate_link.stl"/>
      </geometry>
      <material name="dark_grey">
        <color rgba="0.3 0.3 0.3 1.0"/>
      </material>
    </visual>
    <collision>
      <!-- Origin -->
      <origin rpy="0.0 0.0 0.0" xyz="0.0 0.0 0.0"/>
      <geometry>
        <mesh filename="package://abb_mp_camera_stand_description/meshes/cs_v2/collision/plate_link.stl"/>
      </geometry>
    </collision>
    <inertial>
      <!-- Origin -->
      <origin rpy="0.0 0.0 0.0" xyz="0.0 0.0 0.0"/>
      <!-- Mass -->
      <mass value="1e-05"/>
      <inertia ixx="1e-06" ixy="0.0" ixz="0.0" iyy="1e-06" iyz="0.0" izz="1e-06"/>
    </inertial>
  </link>
  <link name="yumi_cs_attachment_link">
    <inertial>
      <!-- Mass -->
      <mass value="1.0e-5"/>
      <!-- Inertia -->
      <inertia ixx="1.0e-6" ixy="0.0" ixz="0.0" iyy="1.0e-6" iyz="0.0" izz="1.0e-6"/>
    </inertial>
  </link>
  <joint name="yumi_cs_plate_joint" type="revolute">
    <!-- Parent and child -->
    <parent link="yumi_cs_base_link"/>
    <child link="yumi_cs_plate_link"/>
    <!-- Origin -->
    <origin rpy="0.0 0.0 0.0" xyz="0.14935 0.0 0.17194"/>
    <axis xyz="0.0 1.0 0.0"/>
    <limit effort="1.0" lower="-0.7853981633974483" upper="0.7853981633974483" velocity="0.017453292519943295"/>
  </joint>
  <joint name="yumi_cs_attachment_joint" type="fixed">
    <!-- Parent and child -->
    <parent link="yumi_cs_plate_link"/>
    <child link="yumi_cs_attachment_link"/>
    <!-- Origin -->
    <origin rpy="0.0 0.0 0.0" xyz="0.015 0.0 -0.0125"/>
  </joint>
  <transmission name="yumi_cs_plate_transmission">
    <type>transmission_interface/SimpleTransmission</type>
    <joint name="yumi_cs_plate_joint">
      <hardwareInterface>hardware_interface/PositionJointInterface</hardwareInterface>
    </joint>
    <actuator name="yumi_cs_plate_joint_motor">
      <mechanicalReduction>1.0</mechanicalReduction>
    </actuator>
  </transmission>
  <gazebo reference="yumi_cs_base_link">
    <material>Gazebo/White</material>
  </gazebo>
  <gazebo reference="yumi_cs_plate_link">
    <material>Gazebo/Grey</material>
  </gazebo>
  <joint name="yumi_cs_joint" type="revolute">
    <!-- Parent and child -->
    <parent link="yumi_base_link"/>
    <child link="yumi_cs_base_link"/>
    <!-- Origin -->
    <origin rpy="0.0 0.0 0.0" xyz="-0.09 0.0 0.469"/>
    <axis xyz="0.0 0.0 1.0"/>
    <limit effort="1.0" lower="-0.7853981633974483" upper="0.7853981633974483" velocity="0.017453292519943295"/>
  </joint>
  <transmission name="yumi_cs_transmission">
    <type>transmission_interface/SimpleTransmission</type>
    <joint name="yumi_cs_joint">
      <hardwareInterface>hardware_interface/PositionJointInterface</hardwareInterface>
    </joint>
    <actuator name="yumi_cs_joint_motor">
      <mechanicalReduction>1.0</mechanicalReduction>
    </actuator>
  </transmission>
  <link name="camera_body">
    <visual>
      <origin xyz="0. 0. 0."/>
      <geometry>
        <box size="0.0994 0.0996 0.023"/>
      </geometry>
      <material name="white">
        <color rgba="0.9 0.9 0.9 1"/>
      </material>
    </visual>
    <collision>
      <origin xyz="0. 0. 0."/>
      <geometry>
        <box size="0.0994 0.0996 0.023"/>
      </geometry>
    </collision>
  </link>
  <link name="camera_base">
    <visual>
      <origin xyz="-0.013 0. 0."/>
      <geometry>
        <box size="0.026 0.103 0.039"/>
      </geometry>
      <material name="grey">
        <color rgba="0.6 0.6 0.6 1"/>
      </material>
    </visual>
    <collision>
      <origin xyz="-0.013 0. 0."/>
      <geometry>
        <box size="0.026 0.103 0.039"/>
      </geometry>
    </collision>
  </link>
  <link name="camera_visor">
    <visual>
      <origin xyz="-0.0128 0. 0."/>
      <geometry>
        <box size="0.026 0.101 0.037"/>
      </geometry>
      <material name="black">
        <color rgba="0. 0. 0. 1"/>
      </material>
    </visual>
    <collision>
      <origin xyz="-0.0128 0. 0."/>
      <geometry>
        <box size="0.026 0.101 0.037"/>
      </geometry>
    </collision>
  </link>
  <joint name="camera_base_to_body" type="fixed">
    <parent link="camera_base"/>
    <child link="camera_body"/>
    <origin rpy="0. 0. 0." xyz="-0.0757 0. 0.008"/>
  </joint>
  <joint name="camera_base_to_visor" type="fixed">
    <parent link="camera_base"/>
    <child link="camera_visor"/>
    <origin rpy="0. 0. 0." xyz="0. 0. 0."/>
  </joint>
  <gazebo reference="camera_visor">
    <material>Gazebo/Black</material>
  </gazebo>
  <joint name="cs_camera_joint" type="fixed">
    <!-- Parent and child -->
    <parent link="yumi_cs_attachment_link"/>
    <child link="camera_base"/>
    <!-- Origin -->
    <origin rpy="0.0 0.0 0.0" xyz="0.03 0.0 0.03"/>
  </joint>
</robot>
